{
    "registryname": "deep_void_excavator",
    "localizedname": "§9深度虚空采掘机",
    "color": "4FA0C6",
    "requires-blueprint": false,
    "has-factory": true,
    "factory-only": true,
    "modifiers": [
        {
            "x": 0,
            "y": 2,
            "z": 2,
            "elements": "contenttweaker:innerved_sky_stone",
            "description": "配方速度x5",
            "modifier": {
                "io": "input",
                "target": "modularmachinery:duration",
                "operation": 1,
                "multiplier": 0.2
            }
        },
        {
            "x": 0,
            "y": 1,
            "z": 0,
            "elements": "contenttweaker:ordered_eigenstate_condenser",
            "description": "配方速度x10",
            "modifier": {
                "io": "input",
                "target": "modularmachinery:duration",
                "operation": 1,
                "multiplier": 0.1
            }
        },
        {
            "x": 0,
            "y": 1,
            "z": 0,
            "elements": "contenttweaker:everburner",
            "description": "配方速度x20",
            "modifier": {
                "io": "input",
                "target": "modularmachinery:duration",
                "operation": 1,
                "multiplier": 0.05
            }
        }
    ],
    "parts": [
        {
            "x": -1,
            "y": 2,
            "z": 0,
            "elements": [
                "extrabotany:blockshadowium@0"
            ]
        },
        {
            "x": -7,
            "y": -5,
            "z": -7,
            "elements": [
                "environmentaltech:structure_frame_6@0"
            ]
        },
        {
            "x": 0,
            "y": -2,
            "z": 0,
            "elements": [
                "extrabotany:blockshadowium@0"
            ]
        },
        {
            "x": 5,
            "y": -9,
            "z": -5,
            "elements": [
                "environmentaltech:structure_frame_6@0"
            ]
        },
        {
            "x": -9,
            "y": -5,
            "z": 9,
            "elements": [
                "environmentaltech:structure_frame_6@0"
            ]
        },
        {
            "x": -3,
            "y": 9,
            "z": -5,
            "elements": [
                "environmentaltech:ionite@0"
            ]
        },
        {
            "x": -4,
            "y": -7,
            "z": 11,
            "elements": [
                "environmentaltech:structure_frame_6@0"
            ]
        },
        {
            "x": 3,
            "y": 10,
            "z": 7,
            "elements": [
                "environmentaltech:ionite@0"
            ]
        },
        {
            "x": 1,
            "y": 0,
            "z": 0,
            "elements": [
                "extrabotany:blockshadowium@0"
            ]
        },
        {
            "x": -7,
            "y": 6,
            "z": 10,
            "elements": [
                "environmentaltech:structure_frame_6@0"
            ]
        },
        {
            "x": 1,
            "y": -2,
            "z": 0,
            "elements": [
                "extrabotany:blockshadowium@0"
            ]
        },
        {
            "x": -2,
            "y": 2,
            "z": 0,
            "elements": [
                "extrabotany:blockshadowium@0"
            ]
        },
        {
            "x": -9,
            "y": 6,
            "z": -1,
            "elements": [
                "environmentaltech:ionite@0"
            ]
        },
        {
            "x": 9,
            "y": 4,
            "z": -4,
            "elements": [
                "environmentaltech:structure_frame_6@0"
            ]
        },
        {
            "x": 8,
            "y": -8,
            "z": -1,
            "elements": [
                "environmentaltech:ionite@0"
            ]
        },
        {
            "x": -7,
            "y": -3,
            "z": -7,
            "elements": [
                "environmentaltech:ionite@0"
            ]
        },
        {
            "x": 5,
            "y": 9,
            "z": -3,
            "elements": [
                "environmentaltech:structure_frame_6@0"
            ]
        },
        {
            "x": -7,
            "y": -4,
            "z": -7,
            "elements": [
                "environmentaltech:structure_frame_6@0"
            ]
        },
        {
            "x": -9,
            "y": 7,
            "z": -1,
            "elements": [
                "environmentaltech:ionite@0"
            ]
        },
        {
            "x": -8,
            "y": -8,
            "z": -2,
            "elements": [
                "environmentaltech:structure_frame_6@0"
            ]
        },
        {
            "x": -10,
            "y": -4,
            "z": -2,
            "elements": [
                "environmentaltech:structure_frame_6@0"
            ]
        },
        {
            "x": -7,
            "y": -3,
            "z": 11,
            "elements": [
                "environmentaltech:ionite@0"
            ]
        },
        {
            "x": -4,
            "y": -7,
            "z": -7,
            "elements": [
                "environmentaltech:structure_frame_6@0"
            ]
        },
        {
            "x": 2,
            "y": 0,
            "z": 0,
            "elements": [
                "extrabotany:blockshadowium@0"
            ]
        },
        {
            "x": 3,
            "y": -9,
            "z": -5,
            "elements": [
                "environmentaltech:ionite@0"
            ]
        },
        {
            "x": 6,
            "y": 9,
            "z": 7,
            "elements": [
                "environmentaltech:structure_frame_6@0"
            ]
        },
        {
            "x": 1,
            "y": 2,
            "z": 0,
            "elements": [
                "extrabotany:blockshadowium@0"
            ]
        },
        {
            "x": -2,
            "y": -2,
            "z": 0,
            "elements": [
                "extrabotany:blockshadowium@0"
            ]
        },
        {
            "x": 3,
            "y": 10,
            "z": 6,
            "elements": [
                "environmentaltech:ionite@0"
            ]
        },
        {
            "x": -7,
            "y": 2,
            "z": 10,
            "elements": [
                "thermalfoundation:glass@6"
            ]
        },
        {
            "x": -5,
            "y": 7,
            "z": 11,
            "elements": [
                "environmentaltech:structure_frame_6@0"
            ]
        },
        {
            "x": -3,
            "y": 10,
            "z": 7,
            "elements": [
                "environmentaltech:ionite@0"
            ]
        },
        {
            "x": -7,
            "y": -5,
            "z": 11,
            "elements": [
                "environmentaltech:structure_frame_6@0"
            ]
        },
        {
            "x": -4,
            "y": -8,
            "z": 10,
            "elements": [
                "environmentaltech:structure_frame_6@0"
            ]
        },
        {
            "x": -5,
            "y": -9,
            "z": 9,
            "elements": [
                "environmentaltech:structure_frame_6@0"
            ]
        },
        {
            "x": -1,
            "y": 0,
            "z": 0,
            "elements": [
                "extrabotany:blockshadowium@0"
            ]
        },
        {
            "x": -10,
            "y": -3,
            "z": -3,
            "elements": [
                "environmentaltech:ionite@0"
            ]
        },
        {
            "x": -7,
            "y": 0,
            "z": 10,
            "elements": [
                "thermalfoundation:glass@6"
            ]
        },
        {
            "x": -9,
            "y": -3,
            "z": 9,
            "elements": [
                "environmentaltech:ionite@0"
            ]
        },
        {
            "x": 9,
            "y": 5,
            "z": 7,
            "elements": [
                "environmentaltech:structure_frame_6@0"
            ]
        },
        {
            "x": -7,
            "y": -2,
            "z": 10,
            "elements": [
                "thermalfoundation:glass@6"
            ]
        },
        {
            "x": 3,
            "y": 0,
            "z": 3,
            "elements": [
                "extendedcrafting:trimmed@4"
            ]
        },
        {
            "x": -9,
            "y": 4,
            "z": -4,
            "elements": [
                "environmentaltech:structure_frame_6@0"
            ]
        },
        {
            "x": -4,
            "y": 9,
            "z": -5,
            "elements": [
                "environmentaltech:structure_frame_6@0"
            ]
        },
        {
            "x": 3,
            "y": -10,
            "z": 5,
            "elements": [
                "environmentaltech:ionite@0"
            ]
        },
        {
            "x": -5,
            "y": -10,
            "z": -2,
            "elements": [
                "environmentaltech:structure_frame_6@0"
            ]
        },
        {
            "x": -7,
            "y": -9,
            "z": -3,
            "elements": [
                "environmentaltech:structure_frame_6@0"
            ]
        },
        {
            "x": -5,
            "y": 5,
            "z": 11,
            "elements": [
                "environmentaltech:structure_frame_6@0"
            ]
        },
        {
            "x": 3,
            "y": 10,
            "z": -1,
            "elements": [
                "environmentaltech:ionite@0"
            ]
        },
        {
            "x": -4,
            "y": -8,
            "z": -6,
            "elements": [
                "environmentaltech:structure_frame_6@0"
            ]
        },
        {
            "x": -6,
            "y": -3,
            "z": 11,
            "elements": [
                "environmentaltech:ionite@0"
            ]
        },
        {
            "x": -7,
            "y": -3,
            "z": -6,
            "elements": [
                "extrabotany:blockphotonium@0"
            ]
        },
        {
            "x": 3,
            "y": 9,
            "z": 8,
            "elements": [
                "environmentaltech:ionite@0"
            ]
        },
        {
            "x": 2,
            "y": -1,
            "z": 4,
            "elements": [
                "extrabotany:blockshadowium@0"
            ]
        },
        {
            "x": -8,
            "y": -2,
            "z": 10,
            "elements": [
                "environmentaltech:mica@0"
            ]
        },
        {
            "x": 4,
            "y": -4,
            "z": 12,
            "elements": [
                "environmentaltech:structure_frame_6@0"
            ]
        },
        {
            "x": 9,
            "y": 4,
            "z": 8,
            "elements": [
                "environmentaltech:structure_frame_6@0"
            ]
        },
        {
            "x": 0,
            "y": 1,
            "z": 4,
            "elements": [
                "extrabotany:blockshadowium@0"
            ]
        },
        {
            "x": -3,
            "y": 10,
            "z": 6,
            "elements": [
                "environmentaltech:ionite@0"
            ]
        },
        {
            "x": 9,
            "y": 3,
            "z": 8,
            "elements": [
                "environmentaltech:ionite@0"
            ]
        },
        {
            "x": -6,
            "y": 5,
            "z": 11,
            "elements": [
                "environmentaltech:structure_frame_6@0"
            ]
        },
        {
            "x": -9,
            "y": 2,
            "z": 10,
            "elements": [
                "thermalfoundation:glass@6"
            ]
        },
        {
            "x": 8,
            "y": -8,
            "z": 7,
            "elements": [
                "environmentaltech:structure_frame_6@0"
            ]
        },
        {
            "x": -1,
            "y": -1,
            "z": 4,
            "elements": [
                "extrabotany:blockshadowium@0"
            ]
        },
        {
            "x": 10,
            "y": -3,
            "z": -3,
            "elements": [
                "environmentaltech:ionite@0"
            ]
        },
        {
            "x": -5,
            "y": -5,
            "z": 11,
            "elements": [
                "environmentaltech:structure_frame_6@0"
            ]
        },
        {
            "x": -9,
            "y": 5,
            "z": -3,
            "elements": [
                "environmentaltech:structure_frame_6@0"
            ]
        },
        {
            "x": -4,
            "y": 10,
            "z": 5,
            "elements": [
                "environmentaltech:ionite@0"
            ]
        },
        {
            "x": -9,
            "y": 6,
            "z": -4,
            "elements": [
                "environmentaltech:structure_frame_6@0"
            ]
        },
        {
            "x": -8,
            "y": -4,
            "z": 10,
            "elements": [
                "environmentaltech:structure_frame_6@0"
            ]
        },
        {
            "x": -9,
            "y": 7,
            "z": -3,
            "elements": [
                "environmentaltech:structure_frame_6@0"
            ]
        },
        {
            "x": -8,
            "y": 1,
            "z": 11,
            "elements": [
                "thermalfoundation:glass@6"
            ]
        },
        {
            "x": 2,
            "y": 2,
            "z": 0,
            "elements": [
                "extrabotany:blockshadowium@0"
            ]
        },
        {
            "x": -9,
            "y": 0,
            "z": 10,
            "elements": [
                "thermalfoundation:glass@6"
            ]
        },
        {
            "x": -3,
            "y": -10,
            "z": 5,
            "elements": [
                "environmentaltech:ionite@0"
            ]
        },
        {
            "x": -4,
            "y": -6,
            "z": -7,
            "elements": [
                "environmentaltech:structure_frame_6@0"
            ]
        },
        {
            "x": -5,
            "y": -7,
            "z": 11,
            "elements": [
                "environmentaltech:structure_frame_6@0"
            ]
        },
        {
            "x": -3,
            "y": 10,
            "z": -1,
            "elements": [
                "environmentaltech:ionite@0"
            ]
        },
        {
            "x": 9,
            "y": -5,
            "z": 9,
            "elements": [
                "environmentaltech:structure_frame_6@0"
            ]
        },
        {
            "x": -3,
            "y": 10,
            "z": 5,
            "elements": [
                "environmentaltech:ionite@0"
            ]
        },
        {
            "x": -5,
            "y": -8,
            "z": 10,
            "elements": [
                "environmentaltech:structure_frame_6@0"
            ]
        },
        {
            "x": -2,
            "y": 0,
            "z": 0,
            "elements": [
                "extrabotany:blockshadowium@0"
            ]
        },
        {
            "x": -6,
            "y": 4,
            "z": -7,
            "elements": [
                "environmentaltech:structure_frame_6@0"
            ]
        },
        {
            "x": -1,
            "y": 0,
            "z": 5,
            "elements": [
                "extendedcrafting:trimmed@4"
            ]
        },
        {
            "x": -10,
            "y": -5,
            "z": -2,
            "elements": [
                "environmentaltech:structure_frame_6@0"
            ]
        },
        {
            "x": 9,
            "y": -5,
            "z": -5,
            "elements": [
                "environmentaltech:structure_frame_6@0"
            ]
        },
        {
            "x": -10,
            "y": 4,
            "z": 5,
            "elements": [
                "environmentaltech:ionite@0"
            ]
        },
        {
            "x": 4,
            "y": -10,
            "z": 5,
            "elements": [
                "environmentaltech:ionite@0"
            ]
        },
        {
            "x": -5,
            "y": 9,
            "z": -5,
            "elements": [
                "environmentaltech:structure_frame_6@0"
            ]
        },
        {
            "x": 9,
            "y": -3,
            "z": 9,
            "elements": [
                "environmentaltech:ionite@0"
            ]
        },
        {
            "x": -5,
            "y": 9,
            "z": 9,
            "elements": [
                "environmentaltech:structure_frame_6@0"
            ]
        },
        {
            "x": -6,
            "y": 5,
            "z": -7,
            "elements": [
                "environmentaltech:structure_frame_6@0"
            ]
        },
        {
            "x": 9,
            "y": 7,
            "z": -1,
            "elements": [
                "environmentaltech:ionite@0"
            ]
        },
        {
            "x": -7,
            "y": -1,
            "z": -6,
            "elements": [
                "thermalfoundation:glass@6"
            ]
        },
        {
            "x": 4,
            "y": -3,
            "z": 12,
            "elements": [
                "environmentaltech:ionite@0"
            ]
        },
        {
            "x": 6,
            "y": 9,
            "z": 8,
            "elements": [
                "environmentaltech:structure_frame_6@0"
            ]
        },
        {
            "x": 9,
            "y": 6,
            "z": 8,
            "elements": [
                "environmentaltech:structure_frame_6@0"
            ]
        },
        {
            "x": 6,
            "y": 9,
            "z": -1,
            "elements": [
                "environmentaltech:ionite@0"
            ]
        },
        {
            "x": -7,
            "y": -2,
            "z": -6,
            "elements": [
                "thermalfoundation:glass@6"
            ]
        },
        {
            "x": 9,
            "y": 6,
            "z": -1,
            "elements": [
                "environmentaltech:ionite@0"
            ]
        },
        {
            "x": -3,
            "y": 8,
            "z": 10,
            "elements": [
                "environmentaltech:ionite@0"
            ]
        },
        {
            "x": -3,
            "y": -7,
            "z": 11,
            "elements": [
                "environmentaltech:ionite@0"
            ]
        },
        {
            "x": -6,
            "y": 3,
            "z": 11,
            "elements": [
                "environmentaltech:ionite@0"
            ]
        },
        {
            "x": -6,
            "y": 3,
            "z": -7,
            "elements": [
                "environmentaltech:ionite@0"
            ]
        },
        {
            "x": 4,
            "y": -5,
            "z": 12,
            "elements": [
                "environmentaltech:structure_frame_6@0"
            ]
        },
        {
            "x": 9,
            "y": 5,
            "z": 8,
            "elements": [
                "environmentaltech:structure_frame_6@0"
            ]
        },
        {
            "x": 9,
            "y": 6,
            "z": -2,
            "elements": [
                "environmentaltech:structure_frame_6@0"
            ]
        },
        {
            "x": -7,
            "y": 7,
            "z": 9,
            "elements": [
                "environmentaltech:structure_frame_6@0"
            ]
        },
        {
            "x": 6,
            "y": 5,
            "z": 11,
            "elements": [
                "environmentaltech:structure_frame_6@0"
            ]
        },
        {
            "x": 5,
            "y": 3,
            "z": 12,
            "elements": [
                "environmentaltech:ionite@0"
            ]
        },
        {
            "x": -9,
            "y": 2,
            "z": -6,
            "elements": [
                "thermalfoundation:glass@6"
            ]
        },
        {
            "x": 8,
            "y": -7,
            "z": 8,
            "elements": [
                "environmentaltech:structure_frame_6@0"
            ]
        },
        {
            "x": 6,
            "y": 9,
            "z": -2,
            "elements": [
                "environmentaltech:structure_frame_6@0"
            ]
        },
        {
            "x": 9,
            "y": 7,
            "z": -2,
            "elements": [
                "environmentaltech:structure_frame_6@0"
            ]
        },
        {
            "x": -8,
            "y": -8,
            "z": 6,
            "elements": [
                "environmentaltech:structure_frame_6@0"
            ]
        },
        {
            "x": -8,
            "y": 3,
            "z": -5,
            "elements": [
                "extrabotany:blockphotonium@0"
            ]
        },
        {
            "x": 7,
            "y": -9,
            "z": -3,
            "elements": [
                "environmentaltech:structure_frame_6@0"
            ]
        },
        {
            "x": -1,
            "y": 1,
            "z": 4,
            "elements": [
                "extrabotany:blockshadowium@0"
            ]
        },
        {
            "x": -6,
            "y": 9,
            "z": -3,
            "elements": [
                "environmentaltech:structure_frame_6@0"
            ]
        },
        {
            "x": 7,
            "y": -8,
            "z": -4,
            "elements": [
                "environmentaltech:structure_frame_6@0"
            ]
        },
        {
            "x": -9,
            "y": 5,
            "z": 8,
            "elements": [
                "environmentaltech:structure_frame_6@0"
            ]
        },
        {
            "x": 1,
            "y": 0,
            "z": 3,
            "elements": [
                "extrabotany:blockshadowium@0"
            ]
        },
        {
            "x": -9,
            "y": 6,
            "z": 8,
            "elements": [
                "environmentaltech:structure_frame_6@0"
            ]
        },
        {
            "x": 7,
            "y": 6,
            "z": -6,
            "elements": [
                "environmentaltech:structure_frame_6@0"
            ]
        },
        {
            "x": -9,
            "y": 3,
            "z": 8,
            "elements": [
                "environmentaltech:ionite@0"
            ]
        },
        {
            "x": 3,
            "y": -9,
            "z": 9,
            "elements": [
                "environmentaltech:ionite@0"
            ]
        },
        {
            "x": -2,
            "y": 1,
            "z": 4,
            "elements": [
                "extrabotany:blockshadowium@0"
            ]
        },
        {
            "x": -3,
            "y": 5,
            "z": -8,
            "elements": [
                "environmentaltech:ionite@0"
            ]
        },
        {
            "x": 3,
            "y": 7,
            "z": 11,
            "elements": [
                "environmentaltech:ionite@0"
            ]
        },
        {
            "x": -9,
            "y": 3,
            "z": -5,
            "elements": [
                "environmentaltech:ionite@0"
            ]
        },
        {
            "x": -7,
            "y": -6,
            "z": -6,
            "elements": [
                "environmentaltech:structure_frame_6@0"
            ]
        },
        {
            "x": -8,
            "y": 1,
            "z": -5,
            "elements": [
                "thermalfoundation:glass@6"
            ]
        },
        {
            "x": -9,
            "y": 4,
            "z": 8,
            "elements": [
                "environmentaltech:structure_frame_6@0"
            ]
        },
        {
            "x": 5,
            "y": -9,
            "z": 8,
            "elements": [
                "environmentaltech:structure_frame_6@0"
            ]
        },
        {
            "x": -8,
            "y": 1,
            "z": 9,
            "elements": [
                "thermalfoundation:glass@6"
            ]
        },
        {
            "x": -6,
            "y": 9,
            "z": 8,
            "elements": [
                "environmentaltech:structure_frame_6@0"
            ]
        },
        {
            "x": 5,
            "y": 4,
            "z": 12,
            "elements": [
                "environmentaltech:structure_frame_6@0"
            ]
        },
        {
            "x": -9,
            "y": 5,
            "z": -5,
            "elements": [
                "environmentaltech:structure_frame_6@0"
            ]
        },
        {
            "x": -9,
            "y": -3,
            "z": -5,
            "elements": [
                "environmentaltech:ionite@0"
            ]
        },
        {
            "x": -3,
            "y": 3,
            "z": -8,
            "elements": [
                "environmentaltech:ionite@0"
            ]
        },
        {
            "x": -9,
            "y": 5,
            "z": 9,
            "elements": [
                "environmentaltech:structure_frame_6@0"
            ]
        },
        {
            "x": 1,
            "y": 2,
            "z": 3,
            "elements": [
                "extrabotany:blockshadowium@0"
            ]
        },
        {
            "x": -9,
            "y": 1,
            "z": -6,
            "elements": [
                "thermalfoundation:glass@6"
            ]
        },
        {
            "x": 6,
            "y": 3,
            "z": 11,
            "elements": [
                "environmentaltech:ionite@0"
            ]
        },
        {
            "x": -9,
            "y": 0,
            "z": -6,
            "elements": [
                "thermalfoundation:glass@6"
            ]
        },
        {
            "x": -3,
            "y": 4,
            "z": -8,
            "elements": [
                "environmentaltech:ionite@0"
            ]
        },
        {
            "x": -2,
            "y": -1,
            "z": 4,
            "elements": [
                "extrabotany:blockshadowium@0"
            ]
        },
        {
            "x": -8,
            "y": 3,
            "z": 9,
            "elements": [
                "extrabotany:blockphotonium@0"
            ]
        },
        {
            "x": -6,
            "y": -5,
            "z": 11,
            "elements": [
                "environmentaltech:structure_frame_6@0"
            ]
        },
        {
            "x": 8,
            "y": -8,
            "z": 5,
            "elements": [
                "environmentaltech:ionite@0"
            ]
        },
        {
            "x": -3,
            "y": -9,
            "z": -5,
            "elements": [
                "environmentaltech:ionite@0"
            ]
        },
        {
            "x": -3,
            "y": -9,
            "z": 9,
            "elements": [
                "environmentaltech:ionite@0"
            ]
        },
        {
            "x": -9,
            "y": -5,
            "z": -5,
            "elements": [
                "environmentaltech:structure_frame_6@0"
            ]
        },
        {
            "x": 9,
            "y": 7,
            "z": 7,
            "elements": [
                "environmentaltech:structure_frame_6@0"
            ]
        },
        {
            "x": -8,
            "y": -3,
            "z": 9,
            "elements": [
                "extrabotany:blockphotonium@0"
            ]
        },
        {
            "x": -7,
            "y": 9,
            "z": -3,
            "elements": [
                "environmentaltech:structure_frame_6@0"
            ]
        },
        {
            "x": -9,
            "y": 6,
            "z": 5,
            "elements": [
                "environmentaltech:ionite@0"
            ]
        },
        {
            "x": -3,
            "y": 7,
            "z": 11,
            "elements": [
                "environmentaltech:ionite@0"
            ]
        },
        {
            "x": 0,
            "y": 0,
            "z": 3,
            "elements": [
                "extrabotany:blockshadowium@0"
            ]
        },
        {
            "x": -8,
            "y": -1,
            "z": 9,
            "elements": [
                "thermalfoundation:glass@6"
            ]
        },
        {
            "x": 6,
            "y": 9,
            "z": 6,
            "elements": [
                "environmentaltech:structure_frame_6@0"
            ]
        },
        {
            "x": 9,
            "y": 6,
            "z": 7,
            "elements": [
                "environmentaltech:structure_frame_6@0"
            ]
        },
        {
            "x": 2,
            "y": -2,
            "z": 3,
            "elements": [
                "extrabotany:blockshadowium@0"
            ]
        },
        {
            "x": -9,
            "y": -2,
            "z": 10,
            "elements": [
                "thermalfoundation:glass@6"
            ]
        },
        {
            "x": 4,
            "y": -9,
            "z": 9,
            "elements": [
                "environmentaltech:structure_frame_6@0"
            ]
        },
        {
            "x": 3,
            "y": 10,
            "z": -2,
            "elements": [
                "environmentaltech:ionite@0"
            ]
        },
        {
            "x": -10,
            "y": -4,
            "z": -1,
            "elements": [
                "environmentaltech:ionite@0"
            ]
        },
        {
            "x": 0,
            "y": 2,
            "z": 3,
            "elements": [
                "extrabotany:blockshadowium@0"
            ]
        },
        {
            "x": -10,
            "y": -3,
            "z": -1,
            "elements": [
                "environmentaltech:ionite@0"
            ]
        },
        {
            "x": 5,
            "y": 10,
            "z": 5,
            "elements": [
                "environmentaltech:ionite@0"
            ]
        },
        {
            "x": 5,
            "y": -10,
            "z": 5,
            "elements": [
                "environmentaltech:ionite@0"
            ]
        },
        {
            "x": -4,
            "y": -10,
            "z": -1,
            "elements": [
                "environmentaltech:ionite@0"
            ]
        },
        {
            "x": -3,
            "y": 0,
            "z": 3,
            "elements": [
                "extendedcrafting:trimmed@4"
            ]
        },
        {
            "x": -5,
            "y": 8,
            "z": 10,
            "elements": [
                "environmentaltech:structure_frame_6@0"
            ]
        },
        {
            "x": 0,
            "y": -1,
            "z": 4,
            "elements": [
                "extrabotany:blockshadowium@0"
            ]
        },
        {
            "x": 3,
            "y": -7,
            "z": 11,
            "elements": [
                "environmentaltech:ionite@0"
            ]
        },
        {
            "x": -3,
            "y": 9,
            "z": 8,
            "elements": [
                "environmentaltech:ionite@0"
            ]
        },
        {
            "x": 3,
            "y": 9,
            "z": -5,
            "elements": [
                "environmentaltech:ionite@0"
            ]
        },
        {
            "x": 5,
            "y": -5,
            "z": 11,
            "elements": [
                "environmentaltech:structure_frame_6@0"
            ]
        },
        {
            "x": 8,
            "y": -1,
            "z": -5,
            "elements": [
                "thermalfoundation:glass@6"
            ]
        },
        {
            "x": 3,
            "y": -8,
            "z": 10,
            "elements": [
                "environmentaltech:ionite@0"
            ]
        },
        {
            "x": 9,
            "y": 7,
            "z": 6,
            "elements": [
                "environmentaltech:structure_frame_6@0"
            ]
        },
        {
            "x": -7,
            "y": -9,
            "z": -1,
            "elements": [
                "environmentaltech:ionite@0"
            ]
        },
        {
            "x": -4,
            "y": -4,
            "z": -8,
            "elements": [
                "environmentaltech:structure_frame_6@0"
            ]
        },
        {
            "x": 6,
            "y": -9,
            "z": -3,
            "elements": [
                "environmentaltech:structure_frame_6@0"
            ]
        },
        {
            "x": -4,
            "y": -10,
            "z": 5,
            "elements": [
                "environmentaltech:ionite@0"
            ]
        },
        {
            "x": -8,
            "y": 0,
            "z": 10,
            "elements": [
                "environmentaltech:mica@0"
            ]
        },
        {
            "x": -5,
            "y": 9,
            "z": -3,
            "elements": [
                "environmentaltech:structure_frame_6@0"
            ]
        },
        {
            "x": -4,
            "y": -5,
            "z": -8,
            "elements": [
                "environmentaltech:structure_frame_6@0"
            ]
        },
        {
            "x": 2,
            "y": 1,
            "z": 4,
            "elements": [
                "extrabotany:blockshadowium@0"
            ]
        },
        {
            "x": 9,
            "y": 5,
            "z": -5,
            "elements": [
                "environmentaltech:structure_frame_6@0"
            ]
        },
        {
            "x": -1,
            "y": 2,
            "z": 3,
            "elements": [
                "extrabotany:blockshadowium@0"
            ]
        },
        {
            "x": -7,
            "y": -8,
            "z": 8,
            "elements": [
                "environmentaltech:structure_frame_6@0"
            ]
        },
        {
            "x": 9,
            "y": 6,
            "z": 6,
            "elements": [
                "environmentaltech:structure_frame_6@0"
            ]
        },
        {
            "x": -10,
            "y": -5,
            "z": -1,
            "elements": [
                "environmentaltech:ionite@0"
            ]
        },
        {
            "x": -2,
            "y": 0,
            "z": 3,
            "elements": [
                "extrabotany:blockshadowium@0"
            ]
        },
        {
            "x": 8,
            "y": -3,
            "z": -5,
            "elements": [
                "extrabotany:blockphotonium@0"
            ]
        },
        {
            "x": 0,
            "y": -2,
            "z": 3,
            "elements": [
                "extrabotany:blockshadowium@0"
            ]
        },
        {
            "x": -8,
            "y": 4,
            "z": 10,
            "elements": [
                "environmentaltech:structure_frame_6@0"
            ]
        },
        {
            "x": 6,
            "y": -5,
            "z": 11,
            "elements": [
                "environmentaltech:structure_frame_6@0"
            ]
        },
        {
            "x": 5,
            "y": -9,
            "z": -3,
            "elements": [
                "environmentaltech:structure_frame_6@0"
            ]
        },
        {
            "x": -7,
            "y": 8,
            "z": -4,
            "elements": [
                "environmentaltech:structure_frame_6@0"
            ]
        },
        {
            "x": 1,
            "y": -1,
            "z": 4,
            "elements": [
                "extrabotany:blockshadowium@0"
            ]
        },
        {
            "x": 1,
            "y": 1,
            "z": 4,
            "elements": [
                "extrabotany:blockshadowium@0"
            ]
        },
        {
            "x": -2,
            "y": 2,
            "z": 3,
            "elements": [
                "extrabotany:blockshadowium@0"
            ]
        },
        {
            "x": -1,
            "y": 0,
            "z": 3,
            "elements": [
                "extrabotany:blockshadowium@0"
            ]
        },
        {
            "x": -4,
            "y": -3,
            "z": -8,
            "elements": [
                "environmentaltech:ionite@0"
            ]
        },
        {
            "x": 9,
            "y": 3,
            "z": -5,
            "elements": [
                "environmentaltech:ionite@0"
            ]
        },
        {
            "x": -10,
            "y": -4,
            "z": 5,
            "elements": [
                "environmentaltech:ionite@0"
            ]
        },
        {
            "x": -8,
            "y": 2,
            "z": 10,
            "elements": [
                "environmentaltech:mica@0"
            ]
        },
        {
            "x": -1,
            "y": -2,
            "z": 3,
            "elements": [
                "extrabotany:blockshadowium@0"
            ]
        },
        {
            "x": -3,
            "y": -8,
            "z": 10,
            "elements": [
                "environmentaltech:ionite@0"
            ]
        },
        {
            "x": 5,
            "y": -7,
            "z": 11,
            "elements": [
                "environmentaltech:structure_frame_6@0"
            ]
        },
        {
            "x": 10,
            "y": -3,
            "z": 7,
            "elements": [
                "environmentaltech:ionite@0"
            ]
        },
        {
            "x": -3,
            "y": 3,
            "z": 12,
            "elements": [
                "environmentaltech:ionite@0"
            ]
        },
        {
            "x": -8,
            "y": 1,
            "z": -6,
            "elements": [
                "environmentaltech:mica@0"
            ]
        },
        {
            "x": 10,
            "y": 5,
            "z": 5,
            "elements": [
                "environmentaltech:ionite@0"
            ]
        },
        {
            "x": 6,
            "y": -3,
            "z": 11,
            "elements": [
                "environmentaltech:ionite@0"
            ]
        },
        {
            "x": 7,
            "y": 3,
            "z": 11,
            "elements": [
                "environmentaltech:ionite@0"
            ]
        },
        {
            "x": 9,
            "y": 1,
            "z": 10,
            "elements": [
                "thermalfoundation:glass@6"
            ]
        },
        {
            "x": -5,
            "y": 6,
            "z": -7,
            "elements": [
                "environmentaltech:structure_frame_6@0"
            ]
        },
        {
            "x": 7,
            "y": 6,
            "z": 10,
            "elements": [
                "environmentaltech:structure_frame_6@0"
            ]
        },
        {
            "x": -3,
            "y": 9,
            "z": 9,
            "elements": [
                "environmentaltech:ionite@0"
            ]
        },
        {
            "x": 6,
            "y": -4,
            "z": 11,
            "elements": [
                "environmentaltech:structure_frame_6@0"
            ]
        },
        {
            "x": -9,
            "y": -1,
            "z": -6,
            "elements": [
                "thermalfoundation:glass@6"
            ]
        },
        {
            "x": 9,
            "y": 2,
            "z": 10,
            "elements": [
                "thermalfoundation:glass@6"
            ]
        },
        {
            "x": 10,
            "y": -3,
            "z": -1,
            "elements": [
                "environmentaltech:ionite@0"
            ]
        },
        {
            "x": 3,
            "y": 1,
            "z": 2,
            "elements": [
                "extendedcrafting:trimmed@4"
            ]
        },
        {
            "x": 3,
            "y": 5,
            "z": 12,
            "elements": [
                "environmentaltech:ionite@0"
            ]
        },
        {
            "x": -4,
            "y": 10,
            "z": 6,
            "elements": [
                "environmentaltech:structure_frame_6@0"
            ]
        },
        {
            "x": -8,
            "y": 0,
            "z": -7,
            "elements": [
                "thermalfoundation:glass@6"
            ]
        },
        {
            "x": 10,
            "y": -4,
            "z": 6,
            "elements": [
                "environmentaltech:structure_frame_6@0"
            ]
        },
        {
            "x": 5,
            "y": -3,
            "z": 12,
            "elements": [
                "environmentaltech:ionite@0"
            ]
        },
        {
            "x": 10,
            "y": 4,
            "z": 5,
            "elements": [
                "environmentaltech:ionite@0"
            ]
        },
        {
            "x": -4,
            "y": 3,
            "z": -8,
            "elements": [
                "environmentaltech:ionite@0"
            ]
        },
        {
            "x": -10,
            "y": 3,
            "z": 7,
            "elements": [
                "environmentaltech:ionite@0"
            ]
        },
        {
            "x": 8,
            "y": -8,
            "z": -2,
            "elements": [
                "environmentaltech:structure_frame_6@0"
            ]
        },
        {
            "x": 6,
            "y": 7,
            "z": 10,
            "elements": [
                "environmentaltech:structure_frame_6@0"
            ]
        },
        {
            "x": -10,
            "y": 5,
            "z": -1,
            "elements": [
                "environmentaltech:ionite@0"
            ]
        },
        {
            "x": 2,
            "y": -1,
            "z": 2,
            "elements": [
                "extrabotany:blockshadowium@0"
            ]
        },
        {
            "x": 10,
            "y": -5,
            "z": -1,
            "elements": [
                "environmentaltech:ionite@0"
            ]
        },
        {
            "x": 0,
            "y": 1,
            "z": 2,
            "elements": [
                "extrabotany:blockshadowium@0"
            ]
        },
        {
            "x": -6,
            "y": -7,
            "z": -6,
            "elements": [
                "environmentaltech:structure_frame_6@0"
            ]
        },
        {
            "x": 10,
            "y": 3,
            "z": 5,
            "elements": [
                "environmentaltech:ionite@0"
            ]
        },
        {
            "x": 3,
            "y": 3,
            "z": 12,
            "elements": [
                "environmentaltech:ionite@0"
            ]
        },
        {
            "x": 3,
            "y": -6,
            "z": -7,
            "elements": [
                "environmentaltech:ionite@0"
            ]
        },
        {
            "x": 7,
            "y": 9,
            "z": 5,
            "elements": [
                "environmentaltech:ionite@0"
            ]
        },
        {
            "x": 8,
            "y": -6,
            "z": 9,
            "elements": [
                "environmentaltech:structure_frame_6@0"
            ]
        },
        {
            "x": 7,
            "y": 2,
            "z": 10,
            "elements": [
                "thermalfoundation:glass@6"
            ]
        },
        {
            "x": 6,
            "y": -4,
            "z": -7,
            "elements": [
                "environmentaltech:structure_frame_6@0"
            ]
        },
        {
            "x": 9,
            "y": -1,
            "z": 10,
            "elements": [
                "thermalfoundation:glass@6"
            ]
        },
        {
            "x": -4,
            "y": 5,
            "z": -8,
            "elements": [
                "environmentaltech:structure_frame_6@0"
            ]
        },
        {
            "x": 5,
            "y": 3,
            "z": -8,
            "elements": [
                "environmentaltech:ionite@0"
            ]
        },
        {
            "x": 4,
            "y": 7,
            "z": 11,
            "elements": [
                "environmentaltech:structure_frame_6@0"
            ]
        },
        {
            "x": 7,
            "y": -9,
            "z": 7,
            "elements": [
                "environmentaltech:structure_frame_6@0"
            ]
        },
        {
            "x": -3,
            "y": 1,
            "z": 2,
            "elements": [
                "extendedcrafting:trimmed@4"
            ]
        },
        {
            "x": 7,
            "y": 3,
            "z": 10,
            "elements": [
                "extrabotany:blockphotonium@0"
            ]
        },
        {
            "x": -3,
            "y": 5,
            "z": 12,
            "elements": [
                "environmentaltech:ionite@0"
            ]
        },
        {
            "x": 6,
            "y": -6,
            "z": -7,
            "elements": [
                "environmentaltech:structure_frame_6@0"
            ]
        },
        {
            "x": 9,
            "y": 0,
            "z": 10,
            "elements": [
                "thermalfoundation:glass@6"
            ]
        },
        {
            "x": -9,
            "y": 6,
            "z": -2,
            "elements": [
                "environmentaltech:structure_frame_6@0"
            ]
        },
        {
            "x": 4,
            "y": 6,
            "z": 11,
            "elements": [
                "environmentaltech:structure_frame_6@0"
            ]
        },
        {
            "x": 9,
            "y": -2,
            "z": 10,
            "elements": [
                "thermalfoundation:glass@6"
            ]
        },
        {
            "x": 8,
            "y": -2,
            "z": 11,
            "elements": [
                "thermalfoundation:glass@6"
            ]
        },
        {
            "x": -1,
            "y": 3,
            "z": 2,
            "elements": [
                "extendedcrafting:trimmed@1"
            ]
        },
        {
            "x": -4,
            "y": -10,
            "z": 6,
            "elements": [
                "environmentaltech:structure_frame_6@0"
            ]
        },
        {
            "x": 5,
            "y": -9,
            "z": 9,
            "elements": [
                "environmentaltech:structure_frame_6@0"
            ]
        },
        {
            "x": -9,
            "y": 4,
            "z": 9,
            "elements": [
                "environmentaltech:structure_frame_6@0"
            ]
        },
        {
            "x": 8,
            "y": -1,
            "z": -6,
            "elements": [
                "environmentaltech:mica@0"
            ]
        },
        {
            "x": -2,
            "y": 1,
            "z": 2,
            "elements": [
                "extrabotany:blockshadowium@0"
            ]
        },
        {
            "x": 3,
            "y": 5,
            "z": -8,
            "elements": [
                "environmentaltech:ionite@0"
            ]
        },
        {
            "x": 1,
            "y": 0,
            "z": 1,
            "elements": [
                "extrabotany:blockshadowium@0"
            ]
        },
        {
            "x": 8,
            "y": -1,
            "z": 10,
            "elements": [
                "environmentaltech:mica@0"
            ]
        },
        {
            "x": -1,
            "y": -3,
            "z": 2,
            "elements": [
                "extendedcrafting:trimmed@1"
            ]
        },
        {
            "x": -10,
            "y": -3,
            "z": 7,
            "elements": [
                "environmentaltech:ionite@0"
            ]
        },
        {
            "x": 0,
            "y": -1,
            "z": 2,
            "elements": [
                "extrabotany:blockshadowium@0"
            ]
        },
        {
            "x": -3,
            "y": -6,
            "z": -7,
            "elements": [
                "environmentaltech:ionite@0"
            ]
        },
        {
            "x": 4,
            "y": 8,
            "z": 10,
            "elements": [
                "environmentaltech:structure_frame_6@0"
            ]
        },
        {
            "x": -9,
            "y": 3,
            "z": 9,
            "elements": [
                "environmentaltech:ionite@0"
            ]
        },
        {
            "x": -7,
            "y": -9,
            "z": 7,
            "elements": [
                "environmentaltech:structure_frame_6@0"
            ]
        },
        {
            "x": 8,
            "y": -2,
            "z": 10,
            "elements": [
                "environmentaltech:mica@0"
            ]
        },
        {
            "x": 3,
            "y": -3,
            "z": -8,
            "elements": [
                "environmentaltech:ionite@0"
            ]
        },
        {
            "x": 8,
            "y": -1,
            "z": 11,
            "elements": [
                "thermalfoundation:glass@6"
            ]
        },
        {
            "x": -8,
            "y": 2,
            "z": -7,
            "elements": [
                "thermalfoundation:glass@6"
            ]
        },
        {
            "x": -10,
            "y": 3,
            "z": -1,
            "elements": [
                "environmentaltech:ionite@0"
            ]
        },
        {
            "x": -4,
            "y": -9,
            "z": 9,
            "elements": [
                "environmentaltech:structure_frame_6@0"
            ]
        },
        {
            "x": 8,
            "y": -3,
            "z": 10,
            "elements": [
                "environmentaltech:ionite@0"
            ]
        },
        {
            "x": -10,
            "y": -4,
            "z": 6,
            "elements": [
                "environmentaltech:structure_frame_6@0"
            ]
        },
        {
            "x": 3,
            "y": 3,
            "z": -8,
            "elements": [
                "environmentaltech:ionite@0"
            ]
        },
        {
            "x": 1,
            "y": 2,
            "z": 1,
            "elements": [
                "extrabotany:blockshadowium@0"
            ]
        },
        {
            "x": 7,
            "y": 1,
            "z": 10,
            "elements": [
                "thermalfoundation:glass@6"
            ]
        },
        {
            "x": -10,
            "y": 4,
            "z": 6,
            "elements": [
                "environmentaltech:structure_frame_6@0"
            ]
        },
        {
            "x": -5,
            "y": -9,
            "z": -4,
            "elements": [
                "environmentaltech:structure_frame_6@0"
            ]
        },
        {
            "x": -1,
            "y": 1,
            "z": 2,
            "elements": [
                "extrabotany:blockshadowium@0"
            ]
        },
        {
            "x": 8,
            "y": -4,
            "z": 10,
            "elements": [
                "environmentaltech:structure_frame_6@0"
            ]
        },
        {
            "x": -1,
            "y": -1,
            "z": 2,
            "elements": [
                "extrabotany:blockshadowium@0"
            ]
        },
        {
            "x": 3,
            "y": -5,
            "z": -8,
            "elements": [
                "environmentaltech:ionite@0"
            ]
        },
        {
            "x": 7,
            "y": -9,
            "z": -1,
            "elements": [
                "environmentaltech:ionite@0"
            ]
        },
        {
            "x": -5,
            "y": 10,
            "z": -2,
            "elements": [
                "environmentaltech:structure_frame_6@0"
            ]
        },
        {
            "x": 3,
            "y": 8,
            "z": 10,
            "elements": [
                "environmentaltech:ionite@0"
            ]
        },
        {
            "x": 7,
            "y": 0,
            "z": 10,
            "elements": [
                "thermalfoundation:glass@6"
            ]
        },
        {
            "x": -5,
            "y": -9,
            "z": -3,
            "elements": [
                "environmentaltech:structure_frame_6@0"
            ]
        },
        {
            "x": 6,
            "y": 6,
            "z": -7,
            "elements": [
                "environmentaltech:structure_frame_6@0"
            ]
        },
        {
            "x": 5,
            "y": -10,
            "z": -2,
            "elements": [
                "environmentaltech:structure_frame_6@0"
            ]
        },
        {
            "x": 9,
            "y": 1,
            "z": -6,
            "elements": [
                "thermalfoundation:glass@6"
            ]
        },
        {
            "x": -7,
            "y": 8,
            "z": 8,
            "elements": [
                "environmentaltech:structure_frame_6@0"
            ]
        },
        {
            "x": -8,
            "y": 8,
            "z": -2,
            "elements": [
                "environmentaltech:structure_frame_6@0"
            ]
        },
        {
            "x": 6,
            "y": 7,
            "z": -6,
            "elements": [
                "environmentaltech:structure_frame_6@0"
            ]
        },
        {
            "x": 1,
            "y": 3,
            "z": 2,
            "elements": [
                "extendedcrafting:trimmed@1"
            ]
        },
        {
            "x": 7,
            "y": 9,
            "z": -1,
            "elements": [
                "environmentaltech:ionite@0"
            ]
        },
        {
            "x": -2,
            "y": -1,
            "z": 2,
            "elements": [
                "extrabotany:blockshadowium@0"
            ]
        },
        {
            "x": -6,
            "y": -4,
            "z": -7,
            "elements": [
                "environmentaltech:structure_frame_6@0"
            ]
        },
        {
            "x": 4,
            "y": -5,
            "z": -8,
            "elements": [
                "environmentaltech:structure_frame_6@0"
            ]
        },
        {
            "x": 8,
            "y": -8,
            "z": 6,
            "elements": [
                "environmentaltech:structure_frame_6@0"
            ]
        },
        {
            "x": 1,
            "y": -3,
            "z": 2,
            "elements": [
                "extendedcrafting:trimmed@1"
            ]
        },
        {
            "x": 8,
            "y": -5,
            "z": 10,
            "elements": [
                "environmentaltech:structure_frame_6@0"
            ]
        },
        {
            "x": -5,
            "y": -9,
            "z": 7,
            "elements": [
                "environmentaltech:structure_frame_6@0"
            ]
        },
        {
            "x": 5,
            "y": -3,
            "z": -8,
            "elements": [
                "environmentaltech:ionite@0"
            ]
        },
        {
            "x": -8,
            "y": 5,
            "z": -6,
            "elements": [
                "environmentaltech:structure_frame_6@0"
            ]
        },
        {
            "x": 4,
            "y": -10,
            "z": -2,
            "elements": [
                "environmentaltech:structure_frame_6@0"
            ]
        },
        {
            "x": -9,
            "y": -7,
            "z": 5,
            "elements": [
                "environmentaltech:ionite@0"
            ]
        },
        {
            "x": 8,
            "y": 6,
            "z": -5,
            "elements": [
                "environmentaltech:structure_frame_6@0"
            ]
        },
        {
            "x": 7,
            "y": 4,
            "z": 11,
            "elements": [
                "environmentaltech:structure_frame_6@0"
            ]
        },
        {
            "x": -7,
            "y": -7,
            "z": 9,
            "elements": [
                "environmentaltech:structure_frame_6@0"
            ]
        },
        {
            "x": -8,
            "y": -7,
            "z": -4,
            "elements": [
                "environmentaltech:structure_frame_6@0"
            ]
        },
        {
            "x": 1,
            "y": 1,
            "z": 2,
            "elements": [
                "extrabotany:blockshadowium@0"
            ]
        },
        {
            "x": 1,
            "y": -1,
            "z": 2,
            "elements": [
                "extrabotany:blockshadowium@0"
            ]
        },
        {
            "x": 7,
            "y": 5,
            "z": 11,
            "elements": [
                "environmentaltech:structure_frame_6@0"
            ]
        },
        {
            "x": 3,
            "y": 10,
            "z": -3,
            "elements": [
                "environmentaltech:ionite@0"
            ]
        },
        {
            "x": -6,
            "y": -6,
            "z": -7,
            "elements": [
                "environmentaltech:structure_frame_6@0"
            ]
        },
        {
            "x": 9,
            "y": -1,
            "z": -6,
            "elements": [
                "thermalfoundation:glass@6"
            ]
        },
        {
            "x": -3,
            "y": 10,
            "z": -2,
            "elements": [
                "environmentaltech:ionite@0"
            ]
        },
        {
            "x": 4,
            "y": 6,
            "z": -7,
            "elements": [
                "environmentaltech:structure_frame_6@0"
            ]
        },
        {
            "x": -8,
            "y": 3,
            "z": -6,
            "elements": [
                "environmentaltech:ionite@0"
            ]
        },
        {
            "x": 4,
            "y": -3,
            "z": -8,
            "elements": [
                "environmentaltech:ionite@0"
            ]
        },
        {
            "x": 7,
            "y": 4,
            "z": -7,
            "elements": [
                "environmentaltech:structure_frame_6@0"
            ]
        },
        {
            "x": 5,
            "y": -8,
            "z": 10,
            "elements": [
                "environmentaltech:structure_frame_6@0"
            ]
        },
        {
            "x": -3,
            "y": 0,
            "z": 1,
            "elements": [
                "extendedcrafting:trimmed@4"
            ]
        },
        {
            "x": 7,
            "y": -4,
            "z": -7,
            "elements": [
                "environmentaltech:structure_frame_6@0"
            ]
        },
        {
            "x": 8,
            "y": 2,
            "z": -5,
            "elements": [
                "thermalfoundation:glass@6"
            ]
        },
        {
            "x": 5,
            "y": 9,
            "z": -5,
            "elements": [
                "environmentaltech:structure_frame_6@0"
            ]
        },
        {
            "x": 0,
            "y": 2,
            "z": 1,
            "elements": [
                "extrabotany:blockshadowium@0"
            ]
        },
        {
            "x": -10,
            "y": 4,
            "z": -3,
            "elements": [
                "environmentaltech:structure_frame_6@0"
            ]
        },
        {
            "x": -10,
            "y": 3,
            "z": -3,
            "elements": [
                "environmentaltech:ionite@0"
            ]
        },
        {
            "x": -4,
            "y": 5,
            "z": 12,
            "elements": [
                "environmentaltech:structure_frame_6@0"
            ]
        },
        {
            "x": 7,
            "y": 3,
            "z": -6,
            "elements": [
                "extrabotany:blockphotonium@0"
            ]
        },
        {
            "x": 8,
            "y": 3,
            "z": -5,
            "elements": [
                "extrabotany:blockphotonium@0"
            ]
        },
        {
            "x": 6,
            "y": -9,
            "z": -1,
            "elements": [
                "environmentaltech:ionite@0"
            ]
        },
        {
            "x": -7,
            "y": 9,
            "z": -1,
            "elements": [
                "environmentaltech:ionite@0"
            ]
        },
        {
            "x": -6,
            "y": -9,
            "z": 5,
            "elements": [
                "environmentaltech:ionite@0"
            ]
        },
        {
            "x": 3,
            "y": 6,
            "z": -7,
            "elements": [
                "environmentaltech:ionite@0"
            ]
        },
        {
            "x": -9,
            "y": 6,
            "z": 6,
            "elements": [
                "environmentaltech:structure_frame_6@0"
            ]
        },
        {
            "x": 2,
            "y": -2,
            "z": 1,
            "elements": [
                "extrabotany:blockshadowium@0"
            ]
        },
        {
            "x": 9,
            "y": 4,
            "z": 9,
            "elements": [
                "environmentaltech:structure_frame_6@0"
            ]
        },
        {
            "x": -5,
            "y": -10,
            "z": 6,
            "elements": [
                "environmentaltech:structure_frame_6@0"
            ]
        },
        {
            "x": 0,
            "y": 0,
            "z": 1,
            "elements": [
                "extrabotany:blockshadowium@0"
            ]
        },
        {
            "x": 5,
            "y": -9,
            "z": 7,
            "elements": [
                "environmentaltech:structure_frame_6@0"
            ]
        },
        {
            "x": 3,
            "y": -1,
            "z": 2,
            "elements": [
                "extendedcrafting:trimmed@4"
            ]
        },
        {
            "x": -1,
            "y": -1,
            "z": -1,
            "elements": [
                "extrabotany:blockshadowium@0"
            ]
        },
        {
            "x": 9,
            "y": -7,
            "z": 5,
            "elements": [
                "environmentaltech:ionite@0"
            ]
        },
        {
            "x": -9,
            "y": -6,
            "z": 5,
            "elements": [
                "environmentaltech:ionite@0"
            ]
        },
        {
            "x": 7,
            "y": 7,
            "z": 9,
            "elements": [
                "environmentaltech:structure_frame_6@0"
            ]
        },
        {
            "x": -6,
            "y": 6,
            "z": -7,
            "elements": [
                "environmentaltech:structure_frame_6@0"
            ]
        },
        {
            "x": -9,
            "y": 5,
            "z": 7,
            "elements": [
                "environmentaltech:structure_frame_6@0"
            ]
        },
        {
            "x": 0,
            "y": -1,
            "z": -1,
            "elements": [
                "extendedcrafting:trimmed@4"
            ]
        },
        {
            "x": -1,
            "y": 0,
            "z": 1,
            "elements": [
                "extrabotany:blockshadowium@0"
            ]
        },
        {
            "x": 0,
            "y": 1,
            "z": -1,
            "elements": [
                "extendedcrafting:trimmed@4"
            ]
        },
        {
            "x": -1,
            "y": -2,
            "z": 1,
            "elements": [
                "extrabotany:blockshadowium@0"
            ]
        },
        {
            "x": 4,
            "y": 3,
            "z": -8,
            "elements": [
                "environmentaltech:ionite@0"
            ]
        },
        {
            "x": -2,
            "y": 2,
            "z": 1,
            "elements": [
                "extrabotany:blockshadowium@0"
            ]
        },
        {
            "x": -5,
            "y": 3,
            "z": 12,
            "elements": [
                "environmentaltech:ionite@0"
            ]
        },
        {
            "x": 8,
            "y": -5,
            "z": -6,
            "elements": [
                "environmentaltech:structure_frame_6@0"
            ]
        },
        {
            "x": 8,
            "y": -2,
            "z": -7,
            "elements": [
                "thermalfoundation:glass@6"
            ]
        },
        {
            "x": 10,
            "y": -4,
            "z": -2,
            "elements": [
                "environmentaltech:structure_frame_6@0"
            ]
        },
        {
            "x": -3,
            "y": 6,
            "z": -7,
            "elements": [
                "environmentaltech:ionite@0"
            ]
        },
        {
            "x": 9,
            "y": 7,
            "z": -3,
            "elements": [
                "environmentaltech:structure_frame_6@0"
            ]
        },
        {
            "x": -5,
            "y": 10,
            "z": 6,
            "elements": [
                "environmentaltech:structure_frame_6@0"
            ]
        },
        {
            "x": -4,
            "y": 10,
            "z": -2,
            "elements": [
                "environmentaltech:structure_frame_6@0"
            ]
        },
        {
            "x": -7,
            "y": -6,
            "z": 10,
            "elements": [
                "environmentaltech:structure_frame_6@0"
            ]
        },
        {
            "x": 6,
            "y": 4,
            "z": -7,
            "elements": [
                "environmentaltech:structure_frame_6@0"
            ]
        },
        {
            "x": 3,
            "y": -5,
            "z": 12,
            "elements": [
                "environmentaltech:ionite@0"
            ]
        },
        {
            "x": 6,
            "y": 9,
            "z": -3,
            "elements": [
                "environmentaltech:structure_frame_6@0"
            ]
        },
        {
            "x": -2,
            "y": 0,
            "z": 1,
            "elements": [
                "extrabotany:blockshadowium@0"
            ]
        },
        {
            "x": 1,
            "y": -1,
            "z": -1,
            "elements": [
                "extrabotany:blockshadowium@0"
            ]
        },
        {
            "x": 0,
            "y": -2,
            "z": 1,
            "elements": [
                "extrabotany:blockshadowium@0"
            ]
        },
        {
            "x": -1,
            "y": 1,
            "z": -1,
            "elements": [
                "extrabotany:blockshadowium@0"
            ]
        },
        {
            "x": 9,
            "y": 6,
            "z": -3,
            "elements": [
                "environmentaltech:structure_frame_6@0"
            ]
        },
        {
            "x": -1,
            "y": 2,
            "z": 1,
            "elements": [
                "extrabotany:blockshadowium@0"
            ]
        },
        {
            "x": 5,
            "y": -10,
            "z": 6,
            "elements": [
                "environmentaltech:structure_frame_6@0"
            ]
        },
        {
            "x": 8,
            "y": -3,
            "z": -6,
            "elements": [
                "environmentaltech:ionite@0"
            ]
        },
        {
            "x": 8,
            "y": 0,
            "z": -5,
            "elements": [
                "thermalfoundation:glass@6"
            ]
        },
        {
            "x": 4,
            "y": 5,
            "z": -8,
            "elements": [
                "environmentaltech:structure_frame_6@0"
            ]
        },
        {
            "x": -5,
            "y": 9,
            "z": 7,
            "elements": [
                "environmentaltech:structure_frame_6@0"
            ]
        },
        {
            "x": -3,
            "y": -1,
            "z": 2,
            "elements": [
                "extendedcrafting:trimmed@4"
            ]
        },
        {
            "x": 4,
            "y": 9,
            "z": 9,
            "elements": [
                "environmentaltech:structure_frame_6@0"
            ]
        },
        {
            "x": 9,
            "y": 5,
            "z": -3,
            "elements": [
                "environmentaltech:structure_frame_6@0"
            ]
        },
        {
            "x": -6,
            "y": 7,
            "z": -6,
            "elements": [
                "environmentaltech:structure_frame_6@0"
            ]
        },
        {
            "x": -3,
            "y": -3,
            "z": 12,
            "elements": [
                "environmentaltech:ionite@0"
            ]
        },
        {
            "x": -6,
            "y": 9,
            "z": -1,
            "elements": [
                "environmentaltech:ionite@0"
            ]
        },
        {
            "x": 7,
            "y": 1,
            "z": -6,
            "elements": [
                "thermalfoundation:glass@6"
            ]
        },
        {
            "x": 8,
            "y": 1,
            "z": -5,
            "elements": [
                "thermalfoundation:glass@6"
            ]
        },
        {
            "x": 1,
            "y": -2,
            "z": 1,
            "elements": [
                "extrabotany:blockshadowium@0"
            ]
        },
        {
            "x": 8,
            "y": -1,
            "z": 9,
            "elements": [
                "thermalfoundation:glass@6"
            ]
        },
        {
            "x": 6,
            "y": -9,
            "z": 5,
            "elements": [
                "environmentaltech:ionite@0"
            ]
        },
        {
            "x": 7,
            "y": -8,
            "z": 8,
            "elements": [
                "environmentaltech:structure_frame_6@0"
            ]
        },
        {
            "x": 1,
            "y": 0,
            "z": 5,
            "elements": [
                "extendedcrafting:trimmed@4"
            ]
        },
        {
            "x": 9,
            "y": -7,
            "z": -1,
            "elements": [
                "environmentaltech:ionite@0"
            ]
        },
        {
            "x": -8,
            "y": -8,
            "z": -3,
            "elements": [
                "environmentaltech:structure_frame_6@0"
            ]
        },
        {
            "x": 4,
            "y": -10,
            "z": 6,
            "elements": [
                "environmentaltech:structure_frame_6@0"
            ]
        },
        {
            "x": -8,
            "y": -6,
            "z": -5,
            "elements": [
                "environmentaltech:structure_frame_6@0"
            ]
        },
        {
            "x": -5,
            "y": -3,
            "z": -8,
            "elements": [
                "environmentaltech:ionite@0"
            ]
        },
        {
            "x": 4,
            "y": 10,
            "z": 5,
            "elements": [
                "environmentaltech:ionite@0"
            ]
        },
        {
            "x": -3,
            "y": -5,
            "z": 12,
            "elements": [
                "environmentaltech:ionite@0"
            ]
        },
        {
            "x": -4,
            "y": -3,
            "z": 12,
            "elements": [
                "environmentaltech:ionite@0"
            ]
        },
        {
            "x": 1,
            "y": 1,
            "z": 5,
            "elements": [
                "extrabotany:blockshadowium@0"
            ]
        },
        {
            "x": 5,
            "y": -6,
            "z": -7,
            "elements": [
                "environmentaltech:structure_frame_6@0"
            ]
        },
        {
            "x": -5,
            "y": 3,
            "z": -8,
            "elements": [
                "environmentaltech:ionite@0"
            ]
        },
        {
            "x": -2,
            "y": -2,
            "z": 1,
            "elements": [
                "extrabotany:blockshadowium@0"
            ]
        },
        {
            "x": 1,
            "y": 1,
            "z": -1,
            "elements": [
                "extrabotany:blockshadowium@0"
            ]
        },
        {
            "x": 8,
            "y": -2,
            "z": 9,
            "elements": [
                "thermalfoundation:glass@6"
            ]
        },
        {
            "x": 9,
            "y": -6,
            "z": 8,
            "elements": [
                "environmentaltech:structure_frame_6@0"
            ]
        },
        {
            "x": 7,
            "y": -7,
            "z": -5,
            "elements": [
                "environmentaltech:structure_frame_6@0"
            ]
        },
        {
            "x": -10,
            "y": 4,
            "z": -2,
            "elements": [
                "environmentaltech:structure_frame_6@0"
            ]
        },
        {
            "x": -7,
            "y": 9,
            "z": 7,
            "elements": [
                "environmentaltech:structure_frame_6@0"
            ]
        },
        {
            "x": -5,
            "y": -9,
            "z": -5,
            "elements": [
                "environmentaltech:structure_frame_6@0"
            ]
        },
        {
            "x": -7,
            "y": 7,
            "z": -5,
            "elements": [
                "environmentaltech:structure_frame_6@0"
            ]
        },
        {
            "x": -5,
            "y": -3,
            "z": 12,
            "elements": [
                "environmentaltech:ionite@0"
            ]
        },
        {
            "x": 0,
            "y": -1,
            "z": 5,
            "elements": [
                "extendedcrafting:trimmed@4"
            ]
        },
        {
            "x": 8,
            "y": -3,
            "z": 9,
            "elements": [
                "extrabotany:blockphotonium@0"
            ]
        },
        {
            "x": 4,
            "y": -6,
            "z": -7,
            "elements": [
                "environmentaltech:structure_frame_6@0"
            ]
        },
        {
            "x": 6,
            "y": 8,
            "z": 9,
            "elements": [
                "environmentaltech:structure_frame_6@0"
            ]
        },
        {
            "x": 9,
            "y": -6,
            "z": 5,
            "elements": [
                "environmentaltech:ionite@0"
            ]
        },
        {
            "x": -8,
            "y": 8,
            "z": 5,
            "elements": [
                "environmentaltech:ionite@0"
            ]
        },
        {
            "x": -8,
            "y": -2,
            "z": -5,
            "elements": [
                "thermalfoundation:glass@6"
            ]
        },
        {
            "x": 6,
            "y": 9,
            "z": -4,
            "elements": [
                "environmentaltech:structure_frame_6@0"
            ]
        },
        {
            "x": -8,
            "y": -3,
            "z": -5,
            "elements": [
                "extrabotany:blockphotonium@0"
            ]
        },
        {
            "x": 9,
            "y": 3,
            "z": 9,
            "elements": [
                "environmentaltech:ionite@0"
            ]
        },
        {
            "x": 9,
            "y": 6,
            "z": -4,
            "elements": [
                "environmentaltech:structure_frame_6@0"
            ]
        },
        {
            "x": 3,
            "y": 0,
            "z": 1,
            "elements": [
                "extendedcrafting:trimmed@4"
            ]
        },
        {
            "x": -6,
            "y": 9,
            "z": 7,
            "elements": [
                "environmentaltech:structure_frame_6@0"
            ]
        },
        {
            "x": -8,
            "y": -1,
            "z": -5,
            "elements": [
                "thermalfoundation:glass@6"
            ]
        },
        {
            "x": 3,
            "y": 9,
            "z": 9,
            "elements": [
                "environmentaltech:ionite@0"
            ]
        },
        {
            "x": -3,
            "y": -3,
            "z": -8,
            "elements": [
                "environmentaltech:ionite@0"
            ]
        },
        {
            "x": -4,
            "y": -10,
            "z": -2,
            "elements": [
                "environmentaltech:structure_frame_6@0"
            ]
        },
        {
            "x": 2,
            "y": 2,
            "z": 1,
            "elements": [
                "extrabotany:blockshadowium@0"
            ]
        },
        {
            "x": 9,
            "y": 5,
            "z": -4,
            "elements": [
                "environmentaltech:structure_frame_6@0"
            ]
        },
        {
            "x": 9,
            "y": 5,
            "z": 9,
            "elements": [
                "environmentaltech:structure_frame_6@0"
            ]
        },
        {
            "x": -9,
            "y": 7,
            "z": 7,
            "elements": [
                "environmentaltech:structure_frame_6@0"
            ]
        },
        {
            "x": -8,
            "y": 8,
            "z": 6,
            "elements": [
                "environmentaltech:structure_frame_6@0"
            ]
        },
        {
            "x": 4,
            "y": -9,
            "z": -5,
            "elements": [
                "environmentaltech:structure_frame_6@0"
            ]
        },
        {
            "x": 6,
            "y": -7,
            "z": -6,
            "elements": [
                "environmentaltech:structure_frame_6@0"
            ]
        },
        {
            "x": -3,
            "y": -5,
            "z": -8,
            "elements": [
                "environmentaltech:ionite@0"
            ]
        },
        {
            "x": -4,
            "y": 3,
            "z": 12,
            "elements": [
                "environmentaltech:ionite@0"
            ]
        },
        {
            "x": 2,
            "y": 0,
            "z": 1,
            "elements": [
                "extrabotany:blockshadowium@0"
            ]
        },
        {
            "x": 5,
            "y": 10,
            "z": -2,
            "elements": [
                "environmentaltech:structure_frame_6@0"
            ]
        },
        {
            "x": -4,
            "y": 6,
            "z": -7,
            "elements": [
                "environmentaltech:structure_frame_6@0"
            ]
        },
        {
            "x": -4,
            "y": -5,
            "z": 12,
            "elements": [
                "environmentaltech:structure_frame_6@0"
            ]
        },
        {
            "x": -5,
            "y": 10,
            "z": 5,
            "elements": [
                "environmentaltech:ionite@0"
            ]
        },
        {
            "x": -7,
            "y": 6,
            "z": -6,
            "elements": [
                "environmentaltech:structure_frame_6@0"
            ]
        },
        {
            "x": 8,
            "y": 0,
            "z": -6,
            "elements": [
                "environmentaltech:mica@0"
            ]
        },
        {
            "x": 4,
            "y": 4,
            "z": 12,
            "elements": [
                "environmentaltech:structure_frame_6@0"
            ]
        },
        {
            "x": -4,
            "y": -9,
            "z": -4,
            "elements": [
                "environmentaltech:structure_frame_6@0"
            ]
        },
        {
            "x": -1,
            "y": 1,
            "z": 0,
            "elements": [
                "extrabotany:blockshadowium@0"
            ]
        },
        {
            "x": -8,
            "y": 5,
            "z": 10,
            "elements": [
                "environmentaltech:structure_frame_6@0"
            ]
        },
        {
            "x": 0,
            "y": -1,
            "z": 0,
            "elements": [
                "extrabotany:blockshadowium@0"
            ]
        },
        {
            "x": -7,
            "y": 9,
            "z": 5,
            "elements": [
                "environmentaltech:ionite@0"
            ]
        },
        {
            "x": -10,
            "y": -4,
            "z": -3,
            "elements": [
                "environmentaltech:structure_frame_6@0"
            ]
        },
        {
            "x": 5,
            "y": 9,
            "z": -4,
            "elements": [
                "environmentaltech:structure_frame_6@0"
            ]
        },
        {
            "x": 8,
            "y": 7,
            "z": -4,
            "elements": [
                "environmentaltech:structure_frame_6@0"
            ]
        },
        {
            "x": 4,
            "y": 5,
            "z": 12,
            "elements": [
                "environmentaltech:structure_frame_6@0"
            ]
        },
        {
            "x": -9,
            "y": -4,
            "z": 9,
            "elements": [
                "environmentaltech:structure_frame_6@0"
            ]
        },
        {
            "x": 8,
            "y": 1,
            "z": -6,
            "elements": [
                "environmentaltech:mica@0"
            ]
        },
        {
            "x": 7,
            "y": -2,
            "z": -6,
            "elements": [
                "thermalfoundation:glass@6"
            ]
        },
        {
            "x": 6,
            "y": -9,
            "z": 6,
            "elements": [
                "environmentaltech:structure_frame_6@0"
            ]
        },
        {
            "x": -4,
            "y": -10,
            "z": -3,
            "elements": [
                "environmentaltech:structure_frame_6@0"
            ]
        },
        {
            "x": -3,
            "y": -10,
            "z": 7,
            "elements": [
                "environmentaltech:ionite@0"
            ]
        },
        {
            "x": 1,
            "y": -1,
            "z": 0,
            "elements": [
                "extrabotany:blockshadowium@0"
            ]
        },
        {
            "x": -4,
            "y": -6,
            "z": 11,
            "elements": [
                "environmentaltech:structure_frame_6@0"
            ]
        },
        {
            "x": 3,
            "y": -10,
            "z": 6,
            "elements": [
                "environmentaltech:ionite@0"
            ]
        },
        {
            "x": 5,
            "y": 5,
            "z": -7,
            "elements": [
                "environmentaltech:structure_frame_6@0"
            ]
        },
        {
            "x": 7,
            "y": -1,
            "z": -6,
            "elements": [
                "thermalfoundation:glass@6"
            ]
        },
        {
            "x": -7,
            "y": -4,
            "z": 11,
            "elements": [
                "environmentaltech:structure_frame_6@0"
            ]
        },
        {
            "x": -2,
            "y": 1,
            "z": 0,
            "elements": [
                "extrabotany:blockshadowium@0"
            ]
        },
        {
            "x": -6,
            "y": 9,
            "z": 5,
            "elements": [
                "environmentaltech:ionite@0"
            ]
        },
        {
            "x": 9,
            "y": 3,
            "z": -4,
            "elements": [
                "environmentaltech:ionite@0"
            ]
        },
        {
            "x": 10,
            "y": 3,
            "z": -2,
            "elements": [
                "environmentaltech:ionite@0"
            ]
        },
        {
            "x": -4,
            "y": 8,
            "z": -6,
            "elements": [
                "environmentaltech:structure_frame_6@0"
            ]
        },
        {
            "x": 6,
            "y": -8,
            "z": -5,
            "elements": [
                "environmentaltech:structure_frame_6@0"
            ]
        },
        {
            "x": 7,
            "y": 9,
            "z": -2,
            "elements": [
                "environmentaltech:structure_frame_6@0"
            ]
        },
        {
            "x": -7,
            "y": 3,
            "z": 10,
            "elements": [
                "extrabotany:blockphotonium@0"
            ]
        },
        {
            "x": 3,
            "y": 1,
            "z": 3,
            "elements": [
                "extrabotany:blockshadowium@0"
            ]
        },
        {
            "x": 10,
            "y": 4,
            "z": -2,
            "elements": [
                "environmentaltech:structure_frame_6@0"
            ]
        },
        {
            "x": -9,
            "y": -7,
            "z": 7,
            "elements": [
                "environmentaltech:structure_frame_6@0"
            ]
        },
        {
            "x": -5,
            "y": 6,
            "z": 11,
            "elements": [
                "environmentaltech:structure_frame_6@0"
            ]
        },
        {
            "x": 7,
            "y": -3,
            "z": -6,
            "elements": [
                "extrabotany:blockphotonium@0"
            ]
        },
        {
            "x": 4,
            "y": 10,
            "z": -2,
            "elements": [
                "environmentaltech:structure_frame_6@0"
            ]
        },
        {
            "x": 1,
            "y": 1,
            "z": 0,
            "elements": [
                "extrabotany:blockshadowium@0"
            ]
        },
        {
            "x": -7,
            "y": -3,
            "z": 10,
            "elements": [
                "extrabotany:blockphotonium@0"
            ]
        },
        {
            "x": -2,
            "y": -1,
            "z": 0,
            "elements": [
                "extrabotany:blockshadowium@0"
            ]
        },
        {
            "x": 5,
            "y": 7,
            "z": -7,
            "elements": [
                "environmentaltech:structure_frame_6@0"
            ]
        },
        {
            "x": -8,
            "y": -6,
            "z": 9,
            "elements": [
                "environmentaltech:structure_frame_6@0"
            ]
        },
        {
            "x": -1,
            "y": -1,
            "z": 5,
            "elements": [
                "extrabotany:blockshadowium@0"
            ]
        },
        {
            "x": -3,
            "y": -10,
            "z": -1,
            "elements": [
                "environmentaltech:ionite@0"
            ]
        },
        {
            "x": 10,
            "y": 5,
            "z": -2,
            "elements": [
                "environmentaltech:structure_frame_6@0"
            ]
        },
        {
            "x": 5,
            "y": 6,
            "z": -7,
            "elements": [
                "environmentaltech:structure_frame_6@0"
            ]
        },
        {
            "x": 3,
            "y": 9,
            "z": -4,
            "elements": [
                "environmentaltech:ionite@0"
            ]
        },
        {
            "x": -3,
            "y": -10,
            "z": 6,
            "elements": [
                "environmentaltech:ionite@0"
            ]
        },
        {
            "x": 8,
            "y": 8,
            "z": -3,
            "elements": [
                "environmentaltech:structure_frame_6@0"
            ]
        },
        {
            "x": -9,
            "y": 3,
            "z": -4,
            "elements": [
                "environmentaltech:ionite@0"
            ]
        },
        {
            "x": -7,
            "y": 1,
            "z": 10,
            "elements": [
                "thermalfoundation:glass@6"
            ]
        },
        {
            "x": 2,
            "y": -1,
            "z": 3,
            "elements": [
                "extrabotany:blockshadowium@0"
            ]
        },
        {
            "x": -3,
            "y": -9,
            "z": -4,
            "elements": [
                "environmentaltech:ionite@0"
            ]
        },
        {
            "x": 7,
            "y": -6,
            "z": -6,
            "elements": [
                "environmentaltech:structure_frame_6@0"
            ]
        },
        {
            "x": 9,
            "y": -4,
            "z": 8,
            "elements": [
                "environmentaltech:structure_frame_6@0"
            ]
        },
        {
            "x": -7,
            "y": -1,
            "z": 10,
            "elements": [
                "thermalfoundation:glass@6"
            ]
        },
        {
            "x": -9,
            "y": 7,
            "z": 5,
            "elements": [
                "environmentaltech:ionite@0"
            ]
        },
        {
            "x": 6,
            "y": -8,
            "z": 9,
            "elements": [
                "environmentaltech:structure_frame_6@0"
            ]
        },
        {
            "x": 0,
            "y": 3,
            "z": 3,
            "elements": [
                "extendedcrafting:trimmed@1"
            ]
        },
        {
            "x": 0,
            "y": 1,
            "z": 5,
            "elements": [
                "extendedcrafting:trimmed@4"
            ]
        },
        {
            "x": 3,
            "y": -3,
            "z": 12,
            "elements": [
                "environmentaltech:ionite@0"
            ]
        },
        {
            "x": -8,
            "y": -1,
            "z": -6,
            "elements": [
                "environmentaltech:mica@0"
            ]
        },
        {
            "x": 9,
            "y": -3,
            "z": 8,
            "elements": [
                "environmentaltech:ionite@0"
            ]
        },
        {
            "x": -9,
            "y": 5,
            "z": -4,
            "elements": [
                "environmentaltech:structure_frame_6@0"
            ]
        },
        {
            "x": 2,
            "y": -2,
            "z": 4,
            "elements": [
                "extrabotany:blockshadowium@0"
            ]
        },
        {
            "x": -9,
            "y": -6,
            "z": 7,
            "elements": [
                "environmentaltech:structure_frame_6@0"
            ]
        },
        {
            "x": -5,
            "y": -6,
            "z": 11,
            "elements": [
                "environmentaltech:structure_frame_6@0"
            ]
        },
        {
            "x": -6,
            "y": -4,
            "z": 11,
            "elements": [
                "environmentaltech:structure_frame_6@0"
            ]
        },
        {
            "x": -6,
            "y": 4,
            "z": 11,
            "elements": [
                "environmentaltech:structure_frame_6@0"
            ]
        },
        {
            "x": -9,
            "y": -7,
            "z": 6,
            "elements": [
                "environmentaltech:structure_frame_6@0"
            ]
        },
        {
            "x": -8,
            "y": -2,
            "z": -6,
            "elements": [
                "environmentaltech:mica@0"
            ]
        },
        {
            "x": -9,
            "y": 6,
            "z": -3,
            "elements": [
                "environmentaltech:structure_frame_6@0"
            ]
        },
        {
            "x": -8,
            "y": 2,
            "z": 11,
            "elements": [
                "thermalfoundation:glass@6"
            ]
        },
        {
            "x": 1,
            "y": -1,
            "z": 5,
            "elements": [
                "extrabotany:blockshadowium@0"
            ]
        },
        {
            "x": 0,
            "y": 2,
            "z": 4,
            "elements": [
                "extrabotany:blockshadowium@0"
            ]
        },
        {
            "x": 9,
            "y": -6,
            "z": 6,
            "elements": [
                "environmentaltech:structure_frame_6@0"
            ]
        },
        {
            "x": -7,
            "y": 3,
            "z": -7,
            "elements": [
                "environmentaltech:ionite@0"
            ]
        },
        {
            "x": -8,
            "y": -1,
            "z": 10,
            "elements": [
                "environmentaltech:mica@0"
            ]
        },
        {
            "x": -9,
            "y": -5,
            "z": 7,
            "elements": [
                "environmentaltech:structure_frame_6@0"
            ]
        },
        {
            "x": -6,
            "y": 6,
            "z": 11,
            "elements": [
                "environmentaltech:structure_frame_6@0"
            ]
        },
        {
            "x": 9,
            "y": -7,
            "z": 7,
            "elements": [
                "environmentaltech:structure_frame_6@0"
            ]
        },
        {
            "x": 9,
            "y": -4,
            "z": 9,
            "elements": [
                "environmentaltech:structure_frame_6@0"
            ]
        },
        {
            "x": -7,
            "y": 1,
            "z": -6,
            "elements": [
                "thermalfoundation:glass@6"
            ]
        },
        {
            "x": -7,
            "y": 4,
            "z": -7,
            "elements": [
                "environmentaltech:structure_frame_6@0"
            ]
        },
        {
            "x": 3,
            "y": -4,
            "z": 12,
            "elements": [
                "environmentaltech:ionite@0"
            ]
        },
        {
            "x": 8,
            "y": 2,
            "z": -7,
            "elements": [
                "thermalfoundation:glass@6"
            ]
        },
        {
            "x": -8,
            "y": -3,
            "z": 10,
            "elements": [
                "environmentaltech:ionite@0"
            ]
        },
        {
            "x": 2,
            "y": 1,
            "z": 0,
            "elements": [
                "extrabotany:blockshadowium@0"
            ]
        },
        {
            "x": -7,
            "y": 5,
            "z": -7,
            "elements": [
                "environmentaltech:structure_frame_6@0"
            ]
        },
        {
            "x": 0,
            "y": 0,
            "z": 4,
            "elements": [
                "modularmachinery:blockoutputbus@6"
            ]
        },
        {
            "x": -6,
            "y": -9,
            "z": 7,
            "elements": [
                "environmentaltech:structure_frame_6@0"
            ]
        },
        {
            "x": -8,
            "y": 0,
            "z": 11,
            "elements": [
                "thermalfoundation:glass@6"
            ]
        },
        {
            "x": -9,
            "y": 1,
            "z": 10,
            "elements": [
                "thermalfoundation:glass@6"
            ]
        },
        {
            "x": -7,
            "y": 0,
            "z": -6,
            "elements": [
                "thermalfoundation:glass@6"
            ]
        },
        {
            "x": 8,
            "y": 1,
            "z": -7,
            "elements": [
                "thermalfoundation:glass@6"
            ]
        },
        {
            "x": -10,
            "y": 3,
            "z": 5,
            "elements": [
                "environmentaltech:ionite@0"
            ]
        },
        {
            "x": 9,
            "y": -4,
            "z": -5,
            "elements": [
                "environmentaltech:structure_frame_6@0"
            ]
        },
        {
            "x": -3,
            "y": -6,
            "z": 11,
            "elements": [
                "environmentaltech:ionite@0"
            ]
        },
        {
            "x": 5,
            "y": 9,
            "z": 8,
            "elements": [
                "environmentaltech:structure_frame_6@0"
            ]
        },
        {
            "x": -6,
            "y": 7,
            "z": 10,
            "elements": [
                "environmentaltech:structure_frame_6@0"
            ]
        },
        {
            "x": 8,
            "y": 0,
            "z": -7,
            "elements": [
                "thermalfoundation:glass@6"
            ]
        },
        {
            "x": 8,
            "y": 3,
            "z": -6,
            "elements": [
                "environmentaltech:ionite@0"
            ]
        },
        {
            "x": 6,
            "y": -9,
            "z": 7,
            "elements": [
                "environmentaltech:structure_frame_6@0"
            ]
        },
        {
            "x": -8,
            "y": 6,
            "z": -5,
            "elements": [
                "environmentaltech:structure_frame_6@0"
            ]
        },
        {
            "x": 5,
            "y": 8,
            "z": -6,
            "elements": [
                "environmentaltech:structure_frame_6@0"
            ]
        },
        {
            "x": -6,
            "y": -9,
            "z": 6,
            "elements": [
                "environmentaltech:structure_frame_6@0"
            ]
        },
        {
            "x": 8,
            "y": 8,
            "z": -2,
            "elements": [
                "environmentaltech:structure_frame_6@0"
            ]
        },
        {
            "x": -7,
            "y": 2,
            "z": -6,
            "elements": [
                "thermalfoundation:glass@6"
            ]
        },
        {
            "x": -8,
            "y": -5,
            "z": 10,
            "elements": [
                "environmentaltech:structure_frame_6@0"
            ]
        },
        {
            "x": -7,
            "y": 3,
            "z": -6,
            "elements": [
                "extrabotany:blockphotonium@0"
            ]
        },
        {
            "x": -1,
            "y": 1,
            "z": 5,
            "elements": [
                "extrabotany:blockshadowium@0"
            ]
        },
        {
            "x": -10,
            "y": 5,
            "z": 5,
            "elements": [
                "environmentaltech:ionite@0"
            ]
        },
        {
            "x": -9,
            "y": -7,
            "z": -1,
            "elements": [
