{
    "registryname": "large_scale_hypergrowth_insolator",
    "localizedname": "§5超速生长催生器",
    "requires-blueprint": false,
    "color": "790091",
    "has-factory": true,
    "factory-only": true,
    "modifiers": [
        {
            "elements": "contenttweaker:hypergrowth_actualizer",
            "x": 0,
            "y": 2,
            "z": 0,
            "description": "产出x4",
            "modifier": {
                "io": "output",
                "target": "modularmachinery:item",
                "operation": 1,
                "multiplier": 4
            }
        },
        {
            "elements": "contenttweaker:trinity_hypergrowth_component",
            "x": 0,
            "y": 2,
            "z": 0,
            "description": "产出x16",
            "modifier": {
                "io": "output",
                "target": "modularmachinery:item",
                "operation": 1,
                "multiplier": 16
            }
        },
        {
            "elements": "contenttweaker:cosmic_hypergrowth_component",
            "x": 0,
            "y": 2,
            "z": 0,
            "description": "产出x64",
            "modifier": {
                "io": "output",
                "target": "modularmachinery:item",
                "operation": 1,
                "multiplier": 64
            }
        }
    ],
    "parts": [
        {
            "x": -4,
            "y": -2,
            "z": 2,
            "elements": [
                "mysticalagradditions:storage@1"
            ]
        },
        {
            "x": 0,
            "y": -2,
            "z": 0,
            "elements": [
                "mysticalagradditions:storage@1"
            ]
        },
        {
            "x": -1,
            "y": 2,
            "z": 0,
            "elements": [
                "environmentaltech:ionite_tile_stairs@4"
            ]
        },
        {
            "x": 2,
            "y": 7,
            "z": -1,
            "elements": [
                "advancedrocketry:crystal@0"
            ]
        },
        {
            "x": 2,
            "y": 7,
            "z": 1,
            "elements": [
                "advancedrocketry:crystal@0"
            ]
        },
        {
            "x": 5,
            "y": -2,
            "z": 1,
            "elements": [
                "contenttweaker:innerved_sky_stone@0"
            ]
        },
        {
            "x": -3,
            "y": 6,
            "z": 0,
            "elements": [
                "advancedrocketry:crystal@0"
            ]
        },
        {
            "x": 5,
            "y": -2,
            "z": -2,
            "elements": [
                "contenttweaker:innerved_sky_stone@0"
            ]
        },
        {
            "x": 0,
            "y": -1,
            "z": 0,
            "elements": [
                "generalized_input_fluid"
            ]
        },
        {
            "x": 1,
            "y": 7,
            "z": -2,
            "elements": [
                "advancedrocketry:crystal@0"
            ]
        },
        {
            "x": -2,
            "y": 3,
            "z": 0,
            "elements": [
                "advancedrocketry:crystal@0"
            ]
        },
        {
            "x": 1,
            "y": 8,
            "z": -1,
            "elements": [
                "advancedrocketry:crystal@0"
            ]
        },
        {
            "x": 2,
            "y": -2,
            "z": -5,
            "elements": [
                "contenttweaker:innerved_sky_stone@0"
            ]
        },
        {
            "x": -2,
            "y": -2,
            "z": 3,
            "elements": [
                "mysticalagradditions:storage@1"
            ]
        },
        {
            "x": -3,
            "y": 5,
            "z": 0,
            "elements": [
                "advancedrocketry:crystal@0"
            ]
        },
        {
            "x": 0,
            "y": 7,
            "z": 2,
            "elements": [
                "advancedrocketry:crystal@0"
            ]
        },
        {
            "x": 1,
            "y": -2,
            "z": 0,
            "elements": [
                "actuallyadditions:block_crystal_empowered@1"
            ]
        },
        {
            "x": 3,
            "y": -2,
            "z": -3,
            "elements": [
                "mysticalagradditions:storage@1"
            ]
        },
        {
            "x": -4,
            "y": -2,
            "z": -2,
            "elements": [
                "mysticalagradditions:storage@1"
            ]
        },
        {
            "x": -5,
            "y": -2,
            "z": 2,
            "elements": [
                "contenttweaker:innerved_sky_stone@0"
            ]
        },
        {
            "x": 3,
            "y": -1,
            "z": 4,
            "elements": [
                "botania:pylon@1"
            ]
        },
        {
            "x": 1,
            "y": 4,
            "z": -3,
            "elements": [
                "advancedrocketry:crystal@0"
            ]
        },
        {
            "x": 0,
            "y": 7,
            "z": -2,
            "elements": [
                "advancedrocketry:crystal@0"
            ]
        },
        {
            "x": 1,
            "y": -2,
            "z": -5,
            "elements": [
                "contenttweaker:innerved_sky_stone@0"
            ]
        },
        {
            "x": 1,
            "y": -2,
            "z": 3,
            "elements": [
                "mysticalagradditions:storage@1"
            ]
        },
        {
            "x": 2,
            "y": -2,
            "z": 2,
            "elements": [
                "mysticalagradditions:storage@1"
            ]
        },
        {
            "x": -4,
            "y": -2,
            "z": -3,
            "elements": [
                "contenttweaker:innerved_sky_stone@0"
            ]
        },
        {
            "x": -2,
            "y": 7,
            "z": 0,
            "elements": [
                "advancedrocketry:crystal@0"
            ]
        },
        {
            "x": 0,
            "y": 6,
            "z": 3,
            "elements": [
                "advancedrocketry:crystal@0"
            ]
        },
        {
            "x": -2,
            "y": -2,
            "z": 0,
            "elements": [
                "actuallyadditions:block_crystal_empowered@1"
            ]
        },
        {
            "x": 1,
            "y": 2,
            "z": 0,
            "elements": [
                "environmentaltech:ionite_tile_stairs@5"
            ]
        },
        {
            "x": -1,
            "y": -2,
            "z": 5,
            "elements": [
                "contenttweaker:innerved_sky_stone@0"
            ]
        },
        {
            "x": 1,
            "y": 5,
            "z": -3,
            "elements": [
                "advancedrocketry:crystal@0"
            ]
        },
        {
            "x": -1,
            "y": -2,
            "z": -2,
            "elements": [
                "mysticalagradditions:storage@1"
            ]
        },
        {
            "x": -1,
            "y": 4,
            "z": 3,
            "elements": [
                "advancedrocketry:crystal@0"
            ]
        },
        {
            "x": 4,
            "y": -2,
            "z": 3,
            "elements": [
                "contenttweaker:innerved_sky_stone@0"
            ]
        },
        {
            "x": 0,
            "y": 5,
            "z": 3,
            "elements": [
                "advancedrocketry:crystal@0"
            ]
        },
        {
            "x": 1,
            "y": 6,
            "z": -3,
            "elements": [
                "advancedrocketry:crystal@0"
            ]
        },
        {
            "x": 2,
            "y": 3,
            "z": -5,
            "elements": [
                "chisel:glasspanedyedpurple@0"
            ]
        },
        {
            "x": 3,
            "y": -2,
            "z": 0,
            "elements": [
                "actuallyadditions:block_crystal_empowered@1"
            ]
        },
        {
            "x": 1,
            "y": 8,
            "z": 1,
            "elements": [
                "advancedrocketry:crystal@0"
            ]
        },
        {
            "x": -3,
            "y": -2,
            "z": -3,
            "elements": [
                "mysticalagradditions:storage@1"
            ]
        },
        {
            "x": 0,
            "y": 3,
            "z": 2,
            "elements": [
                "advancedrocketry:crystal@0"
            ]
        },
        {
            "x": -1,
            "y": 6,
            "z": 3,
            "elements": [
                "advancedrocketry:crystal@0"
            ]
        },
        {
            "x": 0,
            "y": 4,
            "z": 3,
            "elements": [
                "advancedrocketry:crystal@0"
            ]
        },
        {
            "x": 2,
            "y": 4,
            "z": -5,
            "elements": [
                "chisel:glasspanedyedmagenta@0"
            ]
        },
        {
            "x": 2,
            "y": -2,
            "z": -2,
            "elements": [
                "mysticalagradditions:storage@1"
            ]
        },
        {
            "x": -4,
            "y": -1,
            "z": -3,
            "elements": [
                "botania:pylon@1"
            ]
        },
        {
            "x": 2,
            "y": 5,
            "z": -5,
            "elements": [
                "chisel:glasspanedyedpink@0"
            ]
        },
        {
            "x": -1,
            "y": 5,
            "z": 3,
            "elements": [
                "advancedrocketry:crystal@0"
            ]
        },
        {
            "x": 5,
            "y": -2,
            "z": 2,
            "elements": [
                "contenttweaker:innerved_sky_stone@0"
            ]
        },
        {
            "x": -1,
            "y": -2,
            "z": -5,
            "elements": [
                "contenttweaker:innerved_sky_stone@0"
            ]
        },
        {
            "x": 0,
            "y": -2,
            "z": 2,
            "elements": [
                "actuallyadditions:block_crystal_empowered@1"
            ]
        },
        {
            "x": 4,
            "y": -2,
            "z": 0,
            "elements": [
                "actuallyadditions:block_crystal_empowered@1"
            ]
        },
        {
            "x": 1,
            "y": -2,
            "z": 5,
            "elements": [
                "contenttweaker:innerved_sky_stone@0"
            ]
        },
        {
            "x": -1,
            "y": 3,
            "z": 2,
            "elements": [
                "advancedrocketry:crystal@0"
            ]
        },
        {
            "x": 2,
            "y": 6,
            "z": -5,
            "elements": [
                "chisel:glasspanedyedred@0"
            ]
        },
        {
            "x": 2,
            "y": -2,
            "z": 4,
            "elements": [
                "mysticalagradditions:storage@1"
            ]
        },
        {
            "x": -1,
            "y": -2,
            "z": -4,
            "elements": [
                "mysticalagradditions:storage@1"
            ]
        },
        {
            "x": 0,
            "y": 3,
            "z": -2,
            "elements": [
                "advancedrocketry:crystal@0"
            ]
        },
        {
            "x": 3,
            "y": 4,
            "z": -1,
            "elements": [
                "advancedrocketry:crystal@0"
            ]
        },
        {
            "x": -2,
            "y": 7,
            "z": 1,
            "elements": [
                "advancedrocketry:crystal@0"
            ]
        },
        {
            "x": 1,
            "y": -2,
            "z": -2,
            "elements": [
                "mysticalagradditions:storage@1"
            ]
        },
        {
            "x": -1,
            "y": -1,
            "z": 4,
            "elements": [
                "chisel:glasspanedyedpurple@0"
            ]
        },
        {
            "x": 2,
            "y": 3,
            "z": 0,
            "elements": [
                "advancedrocketry:crystal@0"
            ]
        },
        {
            "x": -2,
            "y": -2,
            "z": -1,
            "elements": [
                "mysticalagradditions:storage@1"
            ]
        },
        {
            "x": 3,
            "y": 5,
            "z": -1,
            "elements": [
                "advancedrocketry:crystal@0"
            ]
        },
        {
            "x": -3,
            "y": -2,
            "z": 0,
            "elements": [
                "actuallyadditions:block_crystal_empowered@1"
            ]
        },
        {
            "x": -1,
            "y": 3,
            "z": -2,
            "elements": [
                "advancedrocketry:crystal@0"
            ]
        },
        {
            "x": -1,
            "y": -2,
            "z": 2,
            "elements": [
                "mysticalagradditions:storage@1"
            ]
        },
        {
            "x": 4,
            "y": -1,
            "z": 3,
            "elements": [
                "botania:pylon@1"
            ]
        },
        {
            "x": 3,
            "y": 6,
            "z": -1,
            "elements": [
                "advancedrocketry:crystal@0"
            ]
        },
        {
            "x": -2,
            "y": 3,
            "z": 2,
            "elements": [
                "advancedrocketry:crystal@0"
            ]
        },
        {
            "x": 1,
            "y": 2,
            "z": 1,
            "elements": [
                "generalized_output_item"
            ]
        },
        {
            "x": 0,
            "y": -2,
            "z": -2,
            "elements": [
                "actuallyadditions:block_crystal_empowered@1"
            ]
        },
        {
            "x": -2,
            "y": 5,
            "z": -2,
            "elements": [
                "advancedrocketry:crystal@0"
            ]
        },
        {
            "x": 0,
            "y": 8,
            "z": -1,
            "elements": [
                "advancedrocketry:crystal@0"
            ]
        },
        {
            "x": -5,
            "y": -2,
            "z": -1,
            "elements": [
                "contenttweaker:innerved_sky_stone@0"
            ]
        },
        {
            "x": -2,
            "y": 4,
            "z": -2,
            "elements": [
                "advancedrocketry:crystal@0"
            ]
        },
        {
            "x": -4,
            "y": 1,
            "z": -1,
            "elements": [
                "chisel:glasspanedyedmagenta@0"
            ]
        },
        {
            "x": 3,
            "y": -2,
            "z": 1,
            "elements": [
                "mysticalagradditions:storage@1"
            ]
        },
        {
            "x": -2,
            "y": 5,
            "z": 2,
            "elements": [
                "advancedrocketry:crystal@0"
            ]
        },
        {
            "x": 2,
            "y": 7,
            "z": 0,
            "elements": [
                "advancedrocketry:crystal@0"
            ]
        },
        {
            "x": -2,
            "y": -2,
            "z": 2,
            "elements": [
                "mysticalagradditions:storage@1"
            ]
        },
        {
            "x": 1,
            "y": 3,
            "z": 2,
            "elements": [
                "advancedrocketry:crystal@0"
            ]
        },
        {
            "x": 0,
            "y": -1,
            "z": -5,
            "elements": [
                "botania:pylon@2"
            ]
        },
        {
            "x": -2,
            "y": 6,
            "z": 2,
            "elements": [
                "advancedrocketry:crystal@0"
            ]
        },
        {
            "x": -2,
            "y": 3,
            "z": -2,
            "elements": [
                "advancedrocketry:crystal@0"
            ]
        },
        {
            "x": 4,
            "y": -2,
            "z": -1,
            "elements": [
                "mysticalagradditions:storage@1"
            ]
        },
        {
            "x": -2,
            "y": 4,
            "z": 2,
            "elements": [
                "advancedrocketry:crystal@0"
            ]
        },
        {
            "x": 3,
            "y": -2,
            "z": -2,
            "elements": [
                "mysticalagradditions:storage@1"
            ]
        },
        {
            "x": -4,
            "y": -2,
            "z": 1,
            "elements": [
                "mysticalagradditions:storage@1"
            ]
        },
        {
            "x": -2,
            "y": 7,
            "z": 2,
            "elements": [
                "advancedrocketry:crystal@0"
            ]
        },
        {
            "x": -1,
            "y": 8,
            "z": 1,
            "elements": [
                "advancedrocketry:crystal@0"
            ]
        },
        {
            "x": 2,
            "y": 3,
            "z": -1,
            "elements": [
                "advancedrocketry:crystal@0"
            ]
        },
        {
            "x": -4,
            "y": 0,
            "z": -1,
            "elements": [
                "chisel:glasspanedyedpurple@0"
            ]
        },
        {
            "x": 0,
            "y": -2,
            "z": -5,
            "elements": [
                "contenttweaker:innerved_sky_stone@0"
            ]
        },
        {
            "x": -2,
            "y": -2,
            "z": 5,
            "elements": [
                "contenttweaker:innerved_sky_stone@0"
            ]
        },
        {
            "x": 1,
            "y": -2,
            "z": 2,
            "elements": [
                "mysticalagradditions:storage@1"
            ]
        },
        {
            "x": -2,
            "y": 6,
            "z": -2,
            "elements": [
                "advancedrocketry:crystal@0"
            ]
        },
        {
            "x": -4,
            "y": 3,
            "z": -1,
            "elements": [
                "chisel:glasspanedyedred@0"
            ]
        },
        {
            "x": 1,
            "y": 3,
            "z": -2,
            "elements": [
                "advancedrocketry:crystal@0"
            ]
        },
        {
            "x": -2,
            "y": -2,
            "z": -2,
            "elements": [
                "mysticalagradditions:storage@1"
            ]
        },
        {
            "x": -2,
            "y": 7,
            "z": -2,
            "elements": [
                "advancedrocketry:crystal@0"
            ]
        },
        {
            "x": 5,
            "y": -2,
            "z": -1,
            "elements": [
                "contenttweaker:innerved_sky_stone@0"
            ]
        },
        {
            "x": -4,
            "y": 2,
            "z": -1,
            "elements": [
                "chisel:glasspanedyedpink@0"
            ]
        },
        {
            "x": -1,
            "y": 8,
            "z": 0,
            "elements": [
                "advancedrocketry:crystal@0"
            ]
        },
        {
            "x": -2,
            "y": -2,
            "z": -3,
            "elements": [
                "mysticalagradditions:storage@1"
            ]
        },
        {
            "x": 3,
            "y": -1,
            "z": -4,
            "elements": [
                "botania:pylon@1"
            ]
        },
        {
            "x": -2,
            "y": -2,
            "z": 4,
            "elements": [
                "mysticalagradditions:storage@1"
            ]
        },
        {
            "x": -3,
            "y": -2,
            "z": 1,
            "elements": [
                "mysticalagradditions:storage@1"
            ]
        },
        {
            "x": 1,
            "y": 4,
            "z": 3,
            "elements": [
                "advancedrocketry:crystal@0"
            ]
        },
        {
            "x": 0,
            "y": 2,
            "z": 1,
            "elements": [
                "environmentaltech:ionite_tile_stairs@7"
            ]
        },
        {
            "x": -3,
            "y": -2,
            "z": -2,
            "elements": [
                "mysticalagradditions:storage@1"
            ]
        },
        {
            "x": 3,
            "y": -2,
            "z": -4,
            "elements": [
                "contenttweaker:innerved_sky_stone@0"
            ]
        },
        {
            "x": -1,
            "y": 0,
            "z": 4,
            "elements": [
                "chisel:glasspanedyedmagenta@0"
            ]
        },
        {
            "x": 4,
            "y": -2,
            "z": 2,
            "elements": [
                "mysticalagradditions:storage@1"
            ]
        },
        {
            "x": 2,
            "y": -2,
            "z": -1,
            "elements": [
                "mysticalagradditions:storage@1"
            ]
        },
        {
            "x": 3,
            "y": -2,
            "z": 2,
            "elements": [
                "mysticalagradditions:storage@1"
            ]
        },
        {
            "x": 2,
            "y": -2,
            "z": 1,
            "elements": [
                "mysticalagradditions:storage@1"
            ]
        },
        {
            "x": 0,
            "y": 5,
            "z": -3,
            "elements": [
                "advancedrocketry:crystal@0"
            ]
        },
        {
            "x": 1,
            "y": -2,
            "z": 4,
            "elements": [
                "mysticalagradditions:storage@1"
            ]
        },
        {
            "x": 1,
            "y": 6,
            "z": 3,
            "elements": [
                "advancedrocketry:crystal@0"
            ]
        },
        {
            "x": 2,
            "y": 3,
            "z": 2,
            "elements": [
                "advancedrocketry:crystal@0"
            ]
        },
        {
            "x": -1,
            "y": 1,
            "z": 4,
            "elements": [
                "chisel:glasspanedyedpink@0"
            ]
        },
        {
            "x": 0,
            "y": -2,
            "z": -4,
            "elements": [
                "actuallyadditions:block_crystal_empowered@1"
            ]
        },
        {
            "x": 4,
            "y": -2,
            "z": -2,
            "elements": [
                "mysticalagradditions:storage@1"
            ]
        },
        {
            "x": 1,
            "y": 5,
            "z": 3,
            "elements": [
                "advancedrocketry:crystal@0"
            ]
        },
        {
            "x": -1,
            "y": 7,
            "z": 2,
            "elements": [
                "advancedrocketry:crystal@0"
            ]
        },
        {
            "x": 2,
            "y": 4,
            "z": -2,
            "elements": [
                "advancedrocketry:crystal@0"
            ]
        },
        {
            "x": -1,
            "y": -2,
            "z": -1,
            "elements": [
                "mysticalagradditions:storage@1"
            ]
        },
        {
            "x": -1,
            "y": 2,
            "z": 4,
            "elements": [
                "chisel:glasspanedyedred@0"
            ]
        },
        {
            "x": 0,
            "y": 6,
            "z": -3,
            "elements": [
                "advancedrocketry:crystal@0"
            ]
        },
        {
            "x": 3,
            "y": 5,
            "z": 0,
            "elements": [
                "advancedrocketry:crystal@0"
            ]
        },
        {
            "x": 5,
            "y": 3,
            "z": 2,
            "elements": [
                "chisel:glasspanedyedpink@0"
            ]
        },
        {
            "x": -3,
            "y": 4,
            "z": -1,
            "elements": [
                "advancedrocketry:crystal@0"
            ]
        },
        {
            "x": -1,
            "y": -2,
            "z": 1,
            "elements": [
                "mysticalagradditions:storage@1"
            ]
        },
        {
            "x": 0,
            "y": -2,
            "z": 4,
            "elements": [
                "actuallyadditions:block_crystal_empowered@1"
            ]
        },
        {
            "x": -4,
            "y": 5,
            "z": 4,
            "elements": [
                "chisel:glasspanedyedmagenta@0"
            ]
        },
        {
            "x": -3,
            "y": 5,
            "z": 1,
            "elements": [
                "advancedrocketry:crystal@0"
            ]
        },
        {
            "x": -3,
            "y": 4,
            "z": 1,
            "elements": [
                "advancedrocketry:crystal@0"
            ]
        },
        {
            "x": 1,
            "y": -2,
            "z": -4,
            "elements": [
                "mysticalagradditions:storage@1"
            ]
        },
        {
            "x": 4,
            "y": -2,
            "z": -3,
            "elements": [
                "contenttweaker:innerved_sky_stone@0"
            ]
        },
        {
            "x": 5,
            "y": 4,
            "z": 2,
            "elements": [
                "chisel:glasspanedyedred@0"
            ]
        },
        {
            "x": -4,
            "y": 6,
            "z": 4,
            "elements": [
                "chisel:glasspanedyedpink@0"
            ]
        },
        {
            "x": 5,
            "y": 2,
            "z": 2,
            "elements": [
                "chisel:glasspanedyedmagenta@0"
            ]
        },
        {
            "x": 2,
            "y": 6,
            "z": 2,
            "elements": [
                "advancedrocketry:crystal@0"
            ]
        },
        {
            "x": 2,
            "y": 3,
            "z": -2,
            "elements": [
                "advancedrocketry:crystal@0"
            ]
        },
        {
            "x": -3,
            "y": -1,
            "z": 4,
            "elements": [
                "botania:pylon@1"
            ]
        },
        {
            "x": 3,
            "y": 6,
            "z": 0,
            "elements": [
                "advancedrocketry:crystal@0"
            ]
        },
        {
            "x": 2,
            "y": 5,
            "z": -2,
            "elements": [
                "advancedrocketry:crystal@0"
            ]
        },
        {
            "x": -3,
            "y": 5,
            "z": -1,
            "elements": [
                "advancedrocketry:crystal@0"
            ]
        },
        {
            "x": 2,
            "y": 4,
            "z": 2,
            "elements": [
                "advancedrocketry:crystal@0"
            ]
        },
        {
            "x": -1,
            "y": 7,
            "z": -2,
            "elements": [
                "advancedrocketry:crystal@0"
            ]
        },
        {
            "x": -1,
            "y": 2,
            "z": -1,
            "elements": [
                "generalized_output_item"
            ]
        },
        {
            "x": -2,
            "y": 3,
            "z": -1,
            "elements": [
                "advancedrocketry:crystal@0"
            ]
        },
        {
            "x": -2,
            "y": 3,
            "z": 1,
            "elements": [
                "advancedrocketry:crystal@0"
            ]
        },
        {
            "x": -4,
            "y": -2,
            "z": 3,
            "elements": [
                "contenttweaker:innerved_sky_stone@0"
            ]
        },
        {
            "x": 2,
            "y": 7,
            "z": 2,
            "elements": [
                "advancedrocketry:crystal@0"
            ]
        },
        {
            "x": 0,
            "y": -2,
            "z": -1,
            "elements": [
                "actuallyadditions:block_crystal_empowered@1"
            ]
        },
        {
            "x": 0,
            "y": -2,
            "z": 1,
            "elements": [
                "actuallyadditions:block_crystal_empowered@1"
            ]
        },
        {
            "x": -1,
            "y": -2,
            "z": 4,
            "elements": [
                "mysticalagradditions:storage@1"
            ]
        },
        {
            "x": 5,
            "y": 1,
            "z": 2,
            "elements": [
                "chisel:glasspanedyedpurple@0"
            ]
        },
        {
            "x": 2,
            "y": -2,
            "z": 5,
            "elements": [
                "contenttweaker:innerved_sky_stone@0"
            ]
        },
        {
            "x": -3,
            "y": -2,
            "z": 2,
            "elements": [
                "mysticalagradditions:storage@1"
            ]
        },
        {
            "x": 2,
            "y": 6,
            "z": -2,
            "elements": [
                "advancedrocketry:crystal@0"
            ]
        },
        {
            "x": -1,
            "y": 2,
            "z": 1,
            "elements": [
                "generalized_output_item"
            ]
        },
        {
            "x": -5,
            "y": -2,
            "z": 0,
            "elements": [
                "contenttweaker:innerved_sky_stone@0"
            ]
        },
        {
            "x": 2,
            "y": -2,
            "z": -4,
            "elements": [
                "mysticalagradditions:storage@1"
            ]
        },
        {
            "x": -3,
            "y": 6,
            "z": -1,
            "elements": [
                "advancedrocketry:crystal@0"
            ]
        },
        {
            "x": -3,
            "y": 6,
            "z": 1,
            "elements": [
                "advancedrocketry:crystal@0"
            ]
        },
        {
            "x": -4,
            "y": 4,
            "z": 4,
            "elements": [
                "chisel:glasspanedyedpurple@0"
            ]
        },
        {
            "x": -5,
            "y": -1,
            "z": 0,
            "elements": [
                "botania:pylon@2"
            ]
        },
        {
            "x": 2,
            "y": 7,
            "z": -2,
            "elements": [
                "advancedrocketry:crystal@0"
            ]
        },
        {
            "x": 0,
            "y": 2,
            "z": -1,
            "elements": [
                "environmentaltech:ionite_tile_stairs@6"
            ]
        },
        {
            "x": 4,
            "y": -1,
            "z": -3,
            "elements": [
                "botania:pylon@1"
            ]
        },
        {
            "x": 2,
            "y": 5,
            "z": 2,
            "elements": [
                "advancedrocketry:crystal@0"
            ]
        },
        {
            "x": 3,
            "y": -2,
            "z": 3,
            "elements": [
                "mysticalagradditions:storage@1"
            ]
        },
        {
            "x": 1,
            "y": -2,
            "z": -1,
            "elements": [
                "mysticalagradditions:storage@1"
            ]
        },
        {
            "x": -1,
            "y": 5,
            "z": -3,
            "elements": [
                "advancedrocketry:crystal@0"
            ]
        },
        {
            "x": 1,
            "y": -2,
            "z": 1,
            "elements": [
                "mysticalagradditions:storage@1"
            ]
        },
        {
            "x": 2,
            "y": -2,
            "z": -3,
            "elements": [
                "mysticalagradditions:storage@1"
            ]
        },
        {
            "x": -4,
            "y": -2,
            "z": 0,
            "elements": [
                "actuallyadditions:block_crystal_empowered@1"
            ]
        },
        {
            "x": 3,
            "y": 5,
            "z": 1,
            "elements": [
                "advancedrocketry:crystal@0"
            ]
        },
        {
            "x": 3,
            "y": 4,
            "z": 1,
            "elements": [
                "advancedrocketry:crystal@0"
            ]
        },
        {
            "x": 0,
            "y": 8,
            "z": 0,
            "elements": [
                "advancedrocketry:crystal@0"
            ]
        },
        {
            "x": -1,
            "y": 6,
            "z": -3,
            "elements": [
                "advancedrocketry:crystal@0"
            ]
        },
        {
            "x": -2,
            "y": 7,
            "z": -1,
            "elements": [
                "advancedrocketry:crystal@0"
            ]
        },
        {
            "x": -2,
            "y": -2,
            "z": -5,
            "elements": [
                "contenttweaker:innerved_sky_stone@0"
            ]
        },
        {
            "x": 2,
            "y": -2,
            "z": 3,
            "elements": [
                "mysticalagradditions:storage@1"
            ]
        },
        {
            "x": -1,
            "y": -2,
            "z": -3,
            "elements": [
                "mysticalagradditions:storage@1"
            ]
        },
        {
            "x": -3,
            "y": -2,
            "z": 4,
            "elements": [
                "contenttweaker:innerved_sky_stone@0"
            ]
        },
        {
            "x": -2,
            "y": -2,
            "z": 1,
            "elements": [
                "mysticalagradditions:storage@1"
            ]
        },
        {
            "x": 0,
            "y": -2,
            "z": 5,
            "elements": [
                "contenttweaker:innerved_sky_stone@0"
            ]
        },
        {
            "x": 1,
            "y": 2,
            "z": -1,
            "elements": [
                "generalized_output_item"
            ]
        },
        {
            "x": -4,
            "y": -1,
            "z": 3,
            "elements": [
                "botania:pylon@1"
            ]
        },
        {
            "x": 3,
            "y": 4,
            "z": 0,
            "elements": [
                "advancedrocketry:crystal@0"
            ]
        },
        {
            "x": 3,
            "y": -2,
            "z": -1,
            "elements": [
                "mysticalagradditions:storage@1"
            ]
        },
        {
            "x": 1,
            "y": 8,
            "z": 0,
            "elements": [
                "advancedrocketry:crystal@0"
            ]
        },
        {
            "x": -3,
            "y": -2,
            "z": 3,
            "elements": [
                "mysticalagradditions:storage@1"
            ]
        },
        {
            "x": -4,
            "y": 7,
            "z": 4,
            "elements": [
                "chisel:glasspanedyedred@0"
            ]
        },
        {
            "x": 3,
            "y": 6,
            "z": 1,
            "elements": [
                "advancedrocketry:crystal@0"
            ]
        },
        {
            "x": -5,
            "y": -2,
            "z": 1,
            "elements": [
                "contenttweaker:innerved_sky_stone@0"
            ]
        },
        {
            "x": 0,
            "y": -1,
            "z": 5,
            "elements": [
                "botania:pylon@2"
            ]
        },
        {
            "x": 0,
            "y": 8,
            "z": 1,
            "elements": [
                "advancedrocketry:crystal@0"
            ]
        },
        {
            "x": 0,
            "y": 5,
            "z": 0,
            "elements": [
                "ebwizardry:crystal_block@0"
            ]
        },
        {
            "x": 2,
            "y": -2,
            "z": 0,
            "elements": [
                "actuallyadditions:block_crystal_empowered@1"
            ]
        },
        {
            "x": 0,
            "y": -2,
            "z": -3,
            "elements": [
                "actuallyadditions:block_crystal_empowered@1"
            ]
        },
        {
            "x": 2,
            "y": 3,
            "z": 1,
            "elements": [
                "advancedrocketry:crystal@0"
            ]
        },
        {
            "x": -5,
            "y": -2,
            "z": -2,
            "elements": [
                "contenttweaker:innerved_sky_stone@0"
            ]
        },
        {
            "x": -3,
            "y": -2,
            "z": -4,
            "elements": [
                "contenttweaker:innerved_sky_stone@0"
            ]
        },
        {
            "x": 5,
            "y": -1,
            "z": 0,
            "elements": [
                "botania:pylon@2"
            ]
        },
        {
            "x": 0,
            "y": 4,
            "z": -3,
            "elements": [
                "advancedrocketry:crystal@0"
            ]
        },
        {
            "x": -1,
            "y": 8,
            "z": -1,
            "elements": [
                "advancedrocketry:crystal@0"
            ]
        },
        {
            "x": 3,
            "y": -2,
            "z": 4,
            "elements": [
                "contenttweaker:innerved_sky_stone@0"
            ]
        },
        {
            "x": -4,
            "y": -2,
            "z": -1,
            "elements": [
                "mysticalagradditions:storage@1"
            ]
        },
        {
            "x": 0,
            "y": -2,
            "z": 3,
            "elements": [
                "actuallyadditions:block_crystal_empowered@1"
            ]
        },
        {
            "x": 5,
            "y": -2,
            "z": 0,
            "elements": [
                "contenttweaker:innerved_sky_stone@0"
            ]
        },
        {
            "x": 4,
            "y": -2,
            "z": 1,
            "elements": [
                "mysticalagradditions:storage@1"
            ]
        },
        {
            "x": 0,
            "y": 2,
            "z": 0,
            "elements": [
                "contenttweaker:hypergrowth_component@0"
            ]
        },
        {
            "x": -1,
            "y": -2,
            "z": 0,
            "elements": [
                "actuallyadditions:block_crystal_empowered@1"
            ]
        },
        {
            "x": 1,
            "y": -2,
            "z": -3,
            "elements": [
                "mysticalagradditions:storage@1"
            ]
        },
        {
            "x": -3,
            "y": 4,
            "z": 0,
            "elements": [
                "advancedrocketry:crystal@0"
            ]
        },
        {
            "x": -2,
            "y": -2,
            "z": -4,
            "elements": [
                "mysticalagradditions:storage@1"
            ]
        },
        {
            "x": 0,
            "y": 1,
            "z": 0,
            "elements": [
                "generalized_input_item"
            ]
        },
        {
            "x": -1,
            "y": 4,
            "z": -3,
            "elements": [
                "advancedrocketry:crystal@0"
            ]
        },
        {
            "x": -1,
            "y": -2,
            "z": 3,
            "elements": [
                "mysticalagradditions:storage@1"
            ]
        },
        {
            "x": -3,
            "y": -2,
            "z": -1,
            "elements": [
                "mysticalagradditions:storage@1"
            ]
        },
        {
            "x": -3,
            "y": -1,
            "z": -4,
            "elements": [
                "botania:pylon@1"
            ]
        },
        {
            "x": 1,
            "y": 7,
            "z": 2,
            "elements": [
                "advancedrocketry:crystal@0"
            ]
        }
    ]
}