{
    "registryname": "meatballium_crucible",
    "localizedname": "§a肉丸素反应堆",
    "requires-blueprint": false,
    "color": "414141",
    "parts": [
        {
            "x": 1,
            "y": 3,
            "z": 4,
            "elements": [
                "contenttweaker:arc_reactor_coil@0"
            ]
        },
        {
            "x": -3,
            "y": 0,
            "z": 1,
            "elements": [
                "chisel:blockaluminum@0"
            ]
        },
        {
            "x": -1,
            "y": 2,
            "z": 0,
            "elements": [
                "contenttweaker:arc_reactor_coil@0"
            ]
        },
        {
            "x": -2,
            "y": 4,
            "z": 0,
            "elements": [
                "contenttweaker:charged_draconium_block@0"
            ]
        },
        {
            "x": -4,
            "y": 0,
            "z": 4,
            "elements": [
                "chisel:blockaluminum@0"
            ]
        },
        {
            "x": -6,
            "y": 0,
            "z": 2,
            "elements": [
                "chisel:blockaluminum@0"
            ]
        },
        {
            "x": 2,
            "y": 1,
            "z": 2,
            "elements": [
                "contenttweaker:draconium_electromagnet@0"
            ]
        },
        {
            "x": -5,
            "y": 3,
            "z": 2,
            "elements": [
                "contenttweaker:arc_reactor_coil@0"
            ]
        },
        {
            "x": -1,
            "y": 1,
            "z": 0,
            "elements": [
                "contenttweaker:draconium_electromagnet@0"
            ]
        },
        {
            "x": -6,
            "y": 1,
            "z": 2,
            "elements": [
                "contenttweaker:radiant_meatballium_reinforced_casing@0"
            ]
        },
        {
            "x": 1,
            "y": 4,
            "z": 4,
            "elements": [
                "contenttweaker:arc_reactor_coil@0"
            ]
        },
        {
            "x": -1,
            "y": 0,
            "z": 4,
            "elements": [
                "chisel:blockaluminum@0"
            ]
        },
        {
            "x": -7,
            "y": 0,
            "z": 0,
            "elements": [
                "chisel:blockaluminum@0"
            ]
        },
        {
            "x": -4,
            "y": 0,
            "z": 3,
            "elements": [
                "chisel:blockaluminum@0"
            ]
        },
        {
            "x": -5,
            "y": 2,
            "z": 2,
            "elements": [
                "contenttweaker:arc_reactor_coil@0"
            ]
        },
        {
            "x": 1,
            "y": 0,
            "z": 0,
            "elements": [
                "chisel:blockaluminum@0"
            ]
        },
        {
            "x": -5,
            "y": 3,
            "z": 3,
            "elements": [
                "contenttweaker:radiant_meatballium_reinforced_casing@0"
            ]
        },
        {
            "x": 2,
            "y": 0,
            "z": 2,
            "elements": [
                "chisel:blockaluminum@0"
            ]
        },
        {
            "x": -5,
            "y": 0,
            "z": 2,
            "elements": [
                "chisel:blockaluminum@0"
            ]
        },
        {
            "x": -7,
            "y": 0,
            "z": 4,
            "elements": [
                "chisel:blockaluminum@0"
            ]
        },
        {
            "x": -4,
            "y": 1,
            "z": 3,
            "elements": [
                "contenttweaker:radiant_meatballium_reinforced_casing@0"
            ]
        },
        {
            "x": 2,
            "y": 3,
            "z": 2,
            "elements": [
                "contenttweaker:arc_reactor_coil@0"
            ]
        },
        {
            "x": -1,
            "y": 1,
            "z": 4,
            "elements": [
                "contenttweaker:draconium_electromagnet@0"
            ]
        },
        {
            "x": -1,
            "y": 4,
            "z": 0,
            "elements": [
                "contenttweaker:arc_reactor_coil@0"
            ]
        },
        {
            "x": 0,
            "y": 0,
            "z": 1,
            "elements": [
                "generalized_input_fluid"
            ]
        },
        {
            "x": -6,
            "y": 3,
            "z": 2,
            "elements": [
                "contenttweaker:radiant_meatballium_reinforced_casing@0"
            ]
        },
        {
            "x": -2,
            "y": 4,
            "z": 3,
            "elements": [
                "contenttweaker:arc_reactor_coil@0"
            ]
        },
        {
            "x": 2,
            "y": 4,
            "z": 1,
            "elements": [
                "contenttweaker:arc_reactor_coil@0"
            ]
        },
        {
            "x": -2,
            "y": 4,
            "z": 4,
            "elements": [
                "contenttweaker:charged_draconium_block@0"
            ]
        },
        {
            "x": -5,
            "y": 1,
            "z": 2,
            "elements": [
                "contenttweaker:arc_reactor_coil@0"
            ]
        },
        {
            "x": 2,
            "y": 2,
            "z": 2,
            "elements": [
                "contenttweaker:arc_reactor_coil@0"
            ]
        },
        {
            "x": 1,
            "y": 0,
            "z": 3,
            "elements": [
                "contenttweaker:arc_reactor_coil@0"
            ]
        },
        {
            "x": -1,
            "y": 3,
            "z": 0,
            "elements": [
                "contenttweaker:arc_reactor_coil@0"
            ]
        },
        {
            "x": -6,
            "y": 0,
            "z": 0,
            "elements": [
                "chisel:blockaluminum@0"
            ]
        },
        {
            "x": -1,
            "y": 2,
            "z": 4,
            "elements": [
                "contenttweaker:arc_reactor_coil@0"
            ]
        },
        {
            "x": -2,
            "y": 3,
            "z": 3,
            "elements": [
                "contenttweaker:arc_reactor_coil@0"
            ]
        },
        {
            "x": -6,
            "y": 2,
            "z": 2,
            "elements": [
                "contenttweaker:radiant_meatballium_reinforced_casing@0"
            ]
        },
        {
            "x": -7,
            "y": 0,
            "z": 3,
            "elements": [
                "chisel:blockaluminum@0"
            ]
        },
        {
            "x": 2,
            "y": 0,
            "z": 0,
            "elements": [
                "chisel:blockaluminum@0"
            ]
        },
        {
            "x": -1,
            "y": 0,
            "z": 1,
            "elements": [
                "contenttweaker:arc_reactor_coil@0"
            ]
        },
        {
            "x": 1,
            "y": 2,
            "z": 0,
            "elements": [
                "contenttweaker:arc_reactor_coil@0"
            ]
        },
        {
            "x": -2,
            "y": 2,
            "z": 1,
            "elements": [
                "contenttweaker:arc_reactor_coil@0"
            ]
        },
        {
            "x": -5,
            "y": 1,
            "z": 3,
            "elements": [
                "contenttweaker:radiant_meatballium_reinforced_casing@0"
            ]
        },
        {
            "x": 2,
            "y": 2,
            "z": 3,
            "elements": [
                "contenttweaker:arc_reactor_coil@0"
            ]
        },
        {
            "x": 1,
            "y": 1,
            "z": 0,
            "elements": [
                "contenttweaker:draconium_electromagnet@0"
            ]
        },
        {
            "x": 2,
            "y": 4,
            "z": 2,
            "elements": [
                "contenttweaker:arc_reactor_coil@0"
            ]
        },
        {
            "x": 2,
            "y": 0,
            "z": 3,
            "elements": [
                "chisel:blockaluminum@0"
            ]
        },
        {
            "x": -5,
            "y": 2,
            "z": 3,
            "elements": [
                "contenttweaker:radiant_meatballium_reinforced_casing@0"
            ]
        },
        {
            "x": -2,
            "y": 3,
            "z": 1,
            "elements": [
                "contenttweaker:arc_reactor_coil@0"
            ]
        },
        {
            "x": 0,
            "y": 0,
            "z": 2,
            "elements": [
                "mysticalagradditions:special@4"
            ]
        },
        {
            "x": -1,
            "y": 0,
            "z": 0,
            "elements": [
                "chisel:blockaluminum@0"
            ]
        },
        {
            "x": -3,
            "y": 2,
            "z": 2,
            "elements": [
                "contenttweaker:mythic_machine_case@0"
            ]
        },
        {
            "x": -6,
            "y": 0,
            "z": 3,
            "elements": [
                "chisel:blockaluminum@0"
            ]
        },
        {
            "x": -2,
            "y": 0,
            "z": 1,
            "elements": [
                "chisel:blockaluminum@0"
            ]
        },
        {
            "x": -3,
            "y": 0,
            "z": 2,
            "elements": [
                "chisel:blockaluminum@0"
            ]
        },
        {
            "x": 2,
            "y": 1,
            "z": 3,
            "elements": [
                "contenttweaker:draconium_electromagnet@0"
            ]
        },
        {
            "x": -6,
            "y": 1,
            "z": 3,
            "elements": [
                "contenttweaker:radiant_meatballium_reinforced_casing@0"
            ]
        },
        {
            "x": 1,
            "y": 4,
            "z": 0,
            "elements": [
                "contenttweaker:arc_reactor_coil@0"
            ]
        },
        {
            "x": -2,
            "y": 0,
            "z": 4,
            "elements": [
                "chisel:blockaluminum@0"
            ]
        },
        {
            "x": -5,
            "y": 0,
            "z": 3,
            "elements": [
                "chisel:blockaluminum@0"
            ]
        },
        {
            "x": 1,
            "y": 3,
            "z": 0,
            "elements": [
                "contenttweaker:arc_reactor_coil@0"
            ]
        },
        {
            "x": -4,
            "y": 0,
            "z": 0,
            "elements": [
                "chisel:blockaluminum@0"
            ]
        },
        {
            "x": -2,
            "y": 1,
            "z": 1,
            "elements": [
                "contenttweaker:draconium_electromagnet@0"
            ]
        },
        {
            "x": -2,
            "y": 0,
            "z": 2,
            "elements": [
                "chisel:blockaluminum@0"
            ]
        },
        {
            "x": -7,
            "y": 0,
            "z": 1,
            "elements": [
                "chisel:blockaluminum@0"
            ]
        },
        {
            "x": -2,
            "y": 1,
            "z": 2,
            "elements": [
                "contenttweaker:draconium_electromagnet@0"
            ]
        },
        {
            "x": 2,
            "y": 4,
            "z": 0,
            "elements": [
                "contenttweaker:charged_draconium_block@0"
            ]
        },
        {
            "x": 1,
            "y": 0,
            "z": 1,
            "elements": [
                "contenttweaker:arc_reactor_coil@0"
            ]
        },
        {
            "x": 0,
            "y": 1,
            "z": 4,
            "elements": [
                "contenttweaker:draconium_electromagnet@0"
            ]
        },
        {
            "x": 0,
            "y": 0,
            "z": 3,
            "elements": [
                "generalized_output_fluid"
            ]
        },
        {
            "x": 0,
            "y": 2,
            "z": 4,
            "elements": [
                "contenttweaker:arc_reactor_coil@0"
            ]
        },
        {
            "x": -3,
            "y": 0,
            "z": 0,
            "elements": [
                "chisel:blockaluminum@0"
            ]
        },
        {
            "x": -4,
            "y": 0,
            "z": 1,
            "elements": [
                "chisel:blockaluminum@0"
            ]
        },
        {
            "x": -3,
            "y": 0,
            "z": 4,
            "elements": [
                "chisel:blockaluminum@0"
            ]
        },
        {
            "x": -2,
            "y": 3,
            "z": 2,
            "elements": [
                "contenttweaker:arc_reactor_coil@0"
            ]
        },
        {
            "x": 2,
            "y": 4,
            "z": 3,
            "elements": [
                "contenttweaker:arc_reactor_coil@0"
            ]
        },
        {
            "x": -4,
            "y": 1,
            "z": 1,
            "elements": [
                "contenttweaker:radiant_meatballium_reinforced_casing@0"
            ]
        },
        {
            "x": -2,
            "y": 4,
            "z": 1,
            "elements": [
                "contenttweaker:arc_reactor_coil@0"
            ]
        },
        {
            "x": 2,
            "y": 4,
            "z": 4,
            "elements": [
                "contenttweaker:charged_draconium_block@0"
            ]
        },
        {
            "x": -2,
            "y": 2,
            "z": 2,
            "elements": [
                "contenttweaker:arc_reactor_coil@0"
            ]
        },
        {
            "x": -3,
            "y": 0,
            "z": 3,
            "elements": [
                "chisel:blockaluminum@0"
            ]
        },
        {
            "x": 2,
            "y": 3,
            "z": 3,
            "elements": [
                "contenttweaker:arc_reactor_coil@0"
            ]
        },
        {
            "x": 0,
            "y": 0,
            "z": 4,
            "elements": [
                "chisel:blockaluminum@0"
            ]
        },
        {
            "x": -1,
            "y": 0,
            "z": 2,
            "elements": [
                "generalized_input_item"
            ]
        },
        {
            "x": -2,
            "y": 0,
            "z": 0,
            "elements": [
                "chisel:blockaluminum@0"
            ]
        },
        {
            "x": -4,
            "y": 0,
            "z": 2,
            "elements": [
                "chisel:blockaluminum@0"
            ]
        },
        {
            "x": -1,
            "y": 3,
            "z": 4,
            "elements": [
                "contenttweaker:arc_reactor_coil@0"
            ]
        },
        {
            "x": -6,
            "y": 0,
            "z": 4,
            "elements": [
                "chisel:blockaluminum@0"
            ]
        },
        {
            "x": -5,
            "y": 0,
            "z": 1,
            "elements": [
                "chisel:blockaluminum@0"
            ]
        },
        {
            "x": 2,
            "y": 3,
            "z": 1,
            "elements": [
                "contenttweaker:arc_reactor_coil@0"
            ]
        },
        {
            "x": 0,
            "y": 4,
            "z": 0,
            "elements": [
                "contenttweaker:arc_reactor_coil@0"
            ]
        },
        {
            "x": -5,
            "y": 1,
            "z": 1,
            "elements": [
                "contenttweaker:radiant_meatballium_reinforced_casing@0"
            ]
        },
        {
            "x": -2,
            "y": 4,
            "z": 2,
            "elements": [
                "contenttweaker:arc_reactor_coil@0"
            ]
        },
        {
            "x": -4,
            "y": 1,
            "z": 2,
            "elements": [
                "contenttweaker:radiant_meatballium_reinforced_casing@0"
            ]
        },
        {
            "x": 2,
            "y": 2,
            "z": 1,
            "elements": [
                "contenttweaker:arc_reactor_coil@0"
            ]
        },
        {
            "x": -1,
            "y": 4,
            "z": 4,
            "elements": [
                "contenttweaker:arc_reactor_coil@0"
            ]
        },
        {
            "x": 0,
            "y": 3,
            "z": 0,
            "elements": [
                "contenttweaker:arc_reactor_coil@0"
            ]
        },
        {
            "x": -5,
            "y": 0,
            "z": 0,
            "elements": [
                "chisel:blockaluminum@0"
            ]
        },
        {
            "x": -2,
            "y": 0,
            "z": 3,
            "elements": [
                "chisel:blockaluminum@0"
            ]
        },
        {
            "x": 1,
            "y": 0,
            "z": 4,
            "elements": [
                "chisel:blockaluminum@0"
            ]
        },
        {
            "x": 0,
            "y": 3,
            "z": 4,
            "elements": [
                "contenttweaker:arc_reactor_coil@0"
            ]
        },
        {
            "x": 0,
            "y": 2,
            "z": 0,
            "elements": [
                "contenttweaker:arc_reactor_coil@0"
            ]
        },
        {
            "x": -5,
            "y": 0,
            "z": 4,
            "elements": [
                "chisel:blockaluminum@0"
            ]
        },
        {
            "x": -6,
            "y": 0,
            "z": 1,
            "elements": [
                "chisel:blockaluminum@0"
            ]
        },
        {
            "x": -7,
            "y": 0,
            "z": 2,
            "elements": [
                "chisel:blockaluminum@0"
            ]
        },
        {
            "x": -2,
            "y": 1,
            "z": 3,
            "elements": [
                "contenttweaker:draconium_electromagnet@0"
            ]
        },
        {
            "x": -4,
            "y": 3,
            "z": 2,
            "elements": [
                "contenttweaker:radiant_meatballium_reinforced_casing@0"
            ]
        },
        {
            "x": -5,
            "y": 2,
            "z": 1,
            "elements": [
                "modularmachinery:blockenergyinputhatch"
            ]
        },
        {
            "x": 2,
            "y": 0,
            "z": 1,
            "elements": [
                "chisel:blockaluminum@0"
            ]
        },
        {
            "x": 1,
            "y": 1,
            "z": 4,
            "elements": [
                "contenttweaker:draconium_electromagnet@0"
            ]
        },
        {
            "x": -2,
            "y": 2,
            "z": 3,
            "elements": [
                "contenttweaker:arc_reactor_coil@0"
            ]
        },
        {
            "x": 0,
            "y": 1,
            "z": 0,
            "elements": [
                "modularmachinery:blockcasing@4",
                "modularmachinery:blockparallelcontroller"
            ]
        },
        {
            "x": -6,
            "y": 1,
            "z": 1,
            "elements": [
                "contenttweaker:radiant_meatballium_reinforced_casing@0"
            ]
        },
        {
            "x": 1,
            "y": 2,
            "z": 4,
            "elements": [
                "contenttweaker:arc_reactor_coil@0"
            ]
        },
        {
            "x": -1,
            "y": 0,
            "z": 3,
            "elements": [
                "contenttweaker:arc_reactor_coil@0"
            ]
        },
        {
            "x": 0,
            "y": 4,
            "z": 4,
            "elements": [
                "contenttweaker:arc_reactor_coil@0"
            ]
        },
        {
            "x": -5,
            "y": 3,
            "z": 1,
            "elements": [
                "contenttweaker:radiant_meatballium_reinforced_casing@0"
            ]
        },
        {
            "x": 2,
            "y": 1,
            "z": 1,
            "elements": [
                "contenttweaker:draconium_electromagnet@0"
            ]
        },
        {
            "x": 2,
            "y": 0,
            "z": 4,
            "elements": [
                "chisel:blockaluminum@0"
            ]
        },
        {
            "x": -5,
            "y": 4,
            "z": 2,
            "elements": [
                "contenttweaker:sentient_meatball@0"
            ]
        },
        {
            "x": 1,
            "y": 0,
            "z": 2,
            "elements": [
                "generalized_input_item"
            ]
        },
        {
            "x": -4,
            "y": 2,
            "z": 2,
            "elements": [
                "contenttweaker:mythic_machine_case@0"
            ]
        }
    ]
}