{
    "registryname": "mythical_generator_second_order",
    "localizedname": "§c二阶神话资源坩埚",
    "requires-blueprint": false,
    "color": "C84400",
    "modifiers": [
        {
            "elements": "contenttweaker:defined_block@0",
            "x": 0,
            "y": 1,
            "z": 0,
            "description": "速度x100",
            "modifier": {
                "io": "input",
                "target": "modularmachinery:duration",
                "operation": 1,
                "multiplier": 0.01
            }
        }
    ],
    "parts": [
        {
            "x": -3,
            "y": -2,
            "z": 5,
            "elements": [
                "chisel:factory@10"
            ]
        },
        {
            "x": -1,
            "y": 2,
            "z": 0,
            "elements": [
                "divinerpg:eden_block"
            ]
        },
        {
            "x": 0,
            "y": -2,
            "z": 0,
            "elements": [
                "chisel:factory@10"
            ]
        },
        {
            "x": 6,
            "y": 4,
            "z": 7,
            "elements": [
                "contenttweaker:ragnarok_sigil@0"
            ]
        },
        {
            "x": -3,
            "y": 6,
            "z": 7,
            "elements": [
                "techreborn:machine_casing@1"
            ]
        },
        {
            "x": -2,
            "y": 4,
            "z": 0,
            "elements": [
                "nuclearcraft:salt_fission_wall@0"
            ]
        },
        {
            "x": -3,
            "y": 12,
            "z": 3,
            "elements": [
                "techreborn:machine_casing@1"
            ]
        },
        {
            "x": 7,
            "y": 4,
            "z": 2,
            "elements": [
                "nuclearcraft:salt_fission_wall@0"
            ]
        },
        {
            "x": 5,
            "y": -2,
            "z": 1,
            "elements": [
                "chisel:factory@10"
            ]
        },
        {
            "x": -3,
            "y": 6,
            "z": 0,
            "elements": [
                "techreborn:machine_casing@1"
            ]
        },
        {
            "x": 6,
            "y": 5,
            "z": 7,
            "elements": [
                "minecraft:beacon@0"
            ]
        },
        {
            "x": -3,
            "y": 7,
            "z": 7,
            "elements": [
                "techreborn:machine_casing@1"
            ]
        },
        {
            "x": -2,
            "y": 11,
            "z": 9,
            "elements": [
                "techreborn:machine_casing@1"
            ]
        },
        {
            "x": -3,
            "y": 11,
            "z": 4,
            "elements": [
                "techreborn:machine_casing@1"
            ]
        },
        {
            "x": 6,
            "y": 5,
            "z": 4,
            "elements": [
                "contenttweaker:cursed_meatballium_reinforced_casing@0"
            ]
        },
        {
            "x": 7,
            "y": 5,
            "z": 2,
            "elements": [
                "contenttweaker:mythic_coil_t3@0"
            ]
        },
        {
            "x": 5,
            "y": -1,
            "z": 1,
            "elements": [
                "chisel:blockgold@4"
            ]
        },
        {
            "x": 1,
            "y": 0,
            "z": 0,
            "elements": [
                "nuclearcraft:salt_fission_glass@0"
            ]
        },
        {
            "x": -3,
            "y": 8,
            "z": 7,
            "elements": [
                "techreborn:machine_casing@1"
            ]
        },
        {
            "x": 7,
            "y": 6,
            "z": 2,
            "elements": [
                "contenttweaker:mythic_coil_t3@0"
            ]
        },
        {
            "x": 1,
            "y": -2,
            "z": 0,
            "elements": [
                "chisel:factory@10"
            ]
        },
        {
            "x": 6,
            "y": 4,
            "z": 3,
            "elements": [
                "nuclearcraft:salt_fission_vessel@0"
            ]
        },
        {
            "x": -1,
            "y": 4,
            "z": 0,
            "elements": [
                "contenttweaker:ragnarok_sigil@0"
            ]
        },
        {
            "x": -3,
            "y": 9,
            "z": 7,
            "elements": [
                "techreborn:machine_casing@1"
            ]
        },
        {
            "x": 6,
            "y": 2,
            "z": 7,
            "elements": [
                "divinerpg:eden_block"
            ]
        },
        {
            "x": 1,
            "y": 5,
            "z": 9,
            "elements": [
                "appliedenergistics2:fluix_stairs@7"
            ]
        },
        {
            "x": -3,
            "y": 8,
            "z": 0,
            "elements": [
                "techreborn:machine_casing@1"
            ]
        },
        {
            "x": 6,
            "y": 3,
            "z": 7,
            "elements": [
                "divinerpg:eden_block"
            ]
        },
        {
            "x": 8,
            "y": -2,
            "z": 7,
            "elements": [
                "chisel:factory@10"
            ]
        },
        {
            "x": 6,
            "y": 3,
            "z": 4,
            "elements": [
                "divinerpg:eden_block"
            ]
        },
        {
            "x": 3,
            "y": -1,
            "z": 9,
            "elements": [
                "modularmachinery:blockenergyinputhatch"
            ]
        },
        {
            "x": 6,
            "y": 1,
            "z": 4,
            "elements": [
                "generalized_output_fluid"
            ]
        },
        {
            "x": -2,
            "y": 9,
            "z": 9,
            "elements": [
                "techreborn:machine_casing@1"
            ]
        },
        {
            "x": 6,
            "y": 3,
            "z": 1,
            "elements": [
                "divinerpg:eden_block"
            ]
        },
        {
            "x": 2,
            "y": 0,
            "z": 0,
            "elements": [
                "nuclearcraft:salt_fission_glass@0"
            ]
        },
        {
            "x": -3,
            "y": 8,
            "z": 3,
            "elements": [
                "techreborn:machine_casing@1"
            ]
        },
        {
            "x": 1,
            "y": 2,
            "z": 0,
            "elements": [
                "nuclearcraft:salt_fission_glass@0"
            ]
        },
        {
            "x": -3,
            "y": 6,
            "z": 5,
            "elements": [
                "techreborn:machine_casing@1"
            ]
        },
        {
            "x": -2,
            "y": -2,
            "z": 0,
            "elements": [
                "chisel:factory@10"
            ]
        },
        {
            "x": 3,
            "y": 3,
            "z": 4,
            "elements": [
                "enderio:block_fluid_cloud_seed_concentrated@0"
            ]
        },
        {
            "x": -1,
            "y": -2,
            "z": 5,
            "elements": [
                "chisel:factory@10"
            ]
        },
        {
            "x": -3,
            "y": 11,
            "z": 7,
            "elements": [
                "techreborn:machine_casing@1"
            ]
        },
        {
            "x": 6,
            "y": 2,
            "z": 1,
            "elements": [
                "divinerpg:eden_block"
            ]
        },
        {
            "x": 8,
            "y": -2,
            "z": -1,
            "elements": [
                "chisel:factory@10"
            ]
        },
        {
            "x": -3,
            "y": 10,
            "z": 0,
            "elements": [
                "techreborn:machine_casing@1"
            ]
        },
        {
            "x": -3,
            "y": 10,
            "z": 7,
            "elements": [
                "techreborn:machine_casing@1"
            ]
        },
        {
            "x": -1,
            "y": 0,
            "z": 0,
            "elements": [
                "divinerpg:eden_block"
            ]
        },
        {
            "x": 3,
            "y": -2,
            "z": 0,
            "elements": [
                "chisel:factory@10"
            ]
        },
        {
            "x": 6,
            "y": 1,
            "z": 1,
            "elements": [
                "divinerpg:eden_block"
            ]
        },
        {
            "x": 0,
            "y": 0,
            "z": 5,
            "elements": [
                "contenttweaker:crystevia_cap@0"
            ]
        },
        {
            "x": 6,
            "y": 0,
            "z": 1,
            "elements": [
                "divinerpg:eden_block"
            ]
        },
        {
            "x": 0,
            "y": 2,
            "z": 5,
            "elements": [
                "enderio:block_fluid_cloud_seed_concentrated@0"
            ]
        },
        {
            "x": 8,
            "y": -2,
            "z": 1,
            "elements": [
                "chisel:factory@10"
            ]
        },
        {
            "x": 1,
            "y": 4,
            "z": 0,
            "elements": [
                "nuclearcraft:salt_fission_vessel@0"
            ]
        },
        {
            "x": 5,
            "y": -1,
            "z": 4,
            "elements": [
                "chisel:blockgold@4"
            ]
        },
        {
            "x": -2,
            "y": 6,
            "z": 0,
            "elements": [
                "contenttweaker:mythic_coil_t3@0"
            ]
        },
        {
            "x": 3,
            "y": 0,
            "z": 3,
            "elements": [
                "contenttweaker:candyland_cap@0"
            ]
        },
        {
            "x": -3,
            "y": 12,
            "z": 7,
            "elements": [
                "techreborn:machine_casing@1"
            ]
        },
        {
            "x": -3,
            "y": 12,
            "z": 0,
            "elements": [
                "techreborn:machine_casing@1"
            ]
        },
        {
            "x": -3,
            "y": 10,
            "z": 3,
            "elements": [
                "techreborn:machine_casing@1"
            ]
        },
        {
            "x": -3,
            "y": 9,
            "z": -1,
            "elements": [
                "techreborn:machine_casing@1"
            ]
        },
        {
            "x": 4,
            "y": -2,
            "z": 0,
            "elements": [
                "chisel:factory@10"
            ]
        },
        {
            "x": -3,
            "y": 8,
            "z": -1,
            "elements": [
                "techreborn:machine_casing@1"
            ]
        },
        {
            "x": -3,
            "y": 11,
            "z": 6,
            "elements": [
                "techreborn:machine_casing@1"
            ]
        },
        {
            "x": 4,
            "y": 0,
            "z": 0,
            "elements": [
                "nuclearcraft:salt_fission_glass@0"
            ]
        },
        {
            "x": 5,
            "y": -2,
            "z": 7,
            "elements": [
                "chisel:factory@10"
            ]
        },
        {
            "x": 1,
            "y": -2,
            "z": 5,
            "elements": [
                "chisel:factory@10"
            ]
        },
        {
            "x": 5,
            "y": -1,
            "z": 7,
            "elements": [
                "chisel:netherbrick@8"
            ]
        },
        {
            "x": 6,
            "y": 2,
            "z": 6,
            "elements": [
                "divinerpg:eden_block"
            ]
        },
        {
            "x": 4,
            "y": 7,
            "z": 9,
            "elements": [
                "techreborn:machine_casing@1"
            ]
        },
        {
            "x": 2,
            "y": -1,
            "z": 4,
            "elements": [
                "chisel:blockgold@4"
            ]
        },
        {
            "x": 4,
            "y": 5,
            "z": 9,
            "elements": [
                "appliedenergistics2:fluix_stairs@7"
            ]
        },
        {
            "x": 6,
            "y": 6,
            "z": 8,
            "elements": [
                "contenttweaker:mythic_coil_t3@0"
            ]
        },
        {
            "x": 2,
            "y": 4,
            "z": 0,
            "elements": [
                "nuclearcraft:salt_fission_vessel@0"
            ]
        },
        {
            "x": 3,
            "y": 2,
            "z": 7,
            "elements": [
                "divinerpg:eden_block"
            ]
        },
        {
            "x": 3,
            "y": 4,
            "z": -1,
            "elements": [
                "nuclearcraft:salt_fission_wall@0"
            ]
        },
        {
            "x": 0,
            "y": 1,
            "z": 4,
            "elements": [
                "divinerpg:divine_rock@0"
            ]
        },
        {
            "x": -3,
            "y": 10,
            "z": 6,
            "elements": [
                "techreborn:machine_casing@1"
            ]
        },
        {
            "x": -1,
            "y": -1,
            "z": 4,
            "elements": [
                "chisel:netherbrick@8"
            ]
        },
        {
            "x": 6,
            "y": 6,
            "z": -1,
            "elements": [
                "contenttweaker:mythic_coil_t3@0"
            ]
        },
        {
            "x": 1,
            "y": 9,
            "z": 9,
            "elements": [
                "techreborn:machine_casing@1"
            ]
        },
        {
            "x": 3,
            "y": 3,
            "z": 7,
            "elements": [
                "divinerpg:eden_block"
            ]
        },
        {
            "x": 0,
            "y": -1,
            "z": 9,
            "elements": [
                "chisel:futura@0"
            ]
        },
        {
            "x": 3,
            "y": 5,
            "z": -1,
            "elements": [
                "contenttweaker:mythic_coil_t3@0"
            ]
        },
        {
            "x": 6,
            "y": 5,
            "z": 8,
            "elements": [
                "contenttweaker:mythic_coil_t3@0"
            ]
        },
        {
            "x": 3,
            "y": 4,
            "z": 7,
            "elements": [
                "nuclearcraft:salt_fission_vessel@0"
            ]
        },
        {
            "x": -3,
            "y": 8,
            "z": 5,
            "elements": [
                "techreborn:machine_casing@1"
            ]
        },
        {
            "x": -3,
            "y": 11,
            "z": -1,
            "elements": [
                "techreborn:machine_casing@1"
            ]
        },
        {
            "x": 5,
            "y": 0,
            "z": 0,
            "elements": [
                "divinerpg:eden_block"
            ]
        },
        {
            "x": 2,
            "y": 2,
            "z": 0,
            "elements": [
                "nuclearcraft:salt_fission_glass@0"
            ]
        },
        {
            "x": -3,
            "y": 5,
            "z": 4,
            "elements": [
                "appliedenergistics2:fluix_stairs@4"
            ]
        },
        {
            "x": -3,
            "y": -2,
            "z": 0,
            "elements": [
                "chisel:factory@10"
            ]
        },
        {
            "x": 3,
            "y": 6,
            "z": -1,
            "elements": [
                "contenttweaker:mythic_coil_t3@0"
            ]
        },
        {
            "x": -1,
            "y": 4,
            "z": 5,
            "elements": [
                "nuclearcraft:salt_fission_vessel@0"
            ]
        },
        {
            "x": 2,
            "y": 0,
            "z": 5,
            "elements": [
                "contenttweaker:celeve_cap@0"
            ]
        },
        {
            "x": 2,
            "y": 2,
            "z": 5,
            "elements": [
                "enderio:block_fluid_cloud_seed_concentrated@0"
            ]
        },
        {
            "x": 3,
            "y": 1,
            "z": 4,
            "elements": [
                "contenttweaker:candyland_cap@0"
            ]
        },
        {
            "x": 6,
            "y": 4,
            "z": -1,
            "elements": [
                "nuclearcraft:salt_fission_wall@0"
            ]
        },
        {
            "x": -3,
            "y": 12,
            "z": 6,
            "elements": [
                "techreborn:machine_casing@1"
            ]
        },
        {
            "x": 3,
            "y": 2,
            "z": 3,
            "elements": [
                "enderio:block_fluid_cloud_seed_concentrated@0"
            ]
        },
        {
            "x": 5,
            "y": -2,
            "z": 3,
            "elements": [
                "chisel:factory@10"
            ]
        },
        {
            "x": 3,
            "y": 5,
            "z": 7,
            "elements": [
                "contenttweaker:cursed_meatballium_reinforced_casing@0"
            ]
        },
        {
            "x": 1,
            "y": 11,
            "z": 9,
            "elements": [
                "techreborn:machine_casing@1"
            ]
        },
        {
            "x": -3,
            "y": 10,
            "z": -1,
            "elements": [
                "techreborn:machine_casing@1"
            ]
        },
        {
            "x": 6,
            "y": 5,
            "z": -1,
            "elements": [
                "contenttweaker:mythic_coil_t3@0"
            ]
        },
        {
            "x": -3,
            "y": 10,
            "z": 5,
            "elements": [
                "techreborn:machine_casing@1"
            ]
        },
        {
            "x": 4,
            "y": 1,
            "z": 9,
            "elements": [
                "chisel:futura@0"
            ]
        },
        {
            "x": -1,
            "y": 0,
            "z": 5,
            "elements": [
                "divinerpg:eden_block"
            ]
        },
        {
            "x": 6,
            "y": 2,
            "z": 3,
            "elements": [
                "divinerpg:eden_block"
            ]
        },
        {
            "x": 6,
            "y": 0,
            "z": 7,
            "elements": [
                "divinerpg:eden_block"
            ]
        },
        {
            "x": 5,
            "y": 2,
            "z": 0,
            "elements": [
                "divinerpg:eden_block"
            ]
        },
        {
            "x": 5,
            "y": -2,
            "z": 6,
            "elements": [
                "chisel:factory@10"
            ]
        },
        {
            "x": -2,
            "y": 5,
            "z": 9,
            "elements": [
                "appliedenergistics2:fluix_stairs@7"
            ]
        },
        {
            "x": 0,
            "y": 6,
            "z": -1,
            "elements": [
                "contenttweaker:mythic_coil_t3@0"
            ]
        },
        {
            "x": 0,
            "y": 4,
            "z": 7,
            "elements": [
                "nuclearcraft:salt_fission_vessel@0"
            ]
        },
        {
            "x": -1,
            "y": 2,
            "z": 5,
            "elements": [
                "divinerpg:eden_block"
            ]
        },
        {
            "x": 3,
            "y": 0,
            "z": 7,
            "elements": [
                "divinerpg:eden_block"
            ]
        },
        {
            "x": 6,
            "y": 0,
            "z": 3,
            "elements": [
                "divinerpg:eden_block"
            ]
        },
        {
            "x": 8,
            "y": -2,
            "z": 3,
            "elements": [
                "chisel:factory@10"
            ]
        },
        {
            "x": -3,
            "y": 7,
            "z": 4,
            "elements": [
                "techreborn:machine_casing@1"
            ]
        },
        {
            "x": 0,
            "y": 5,
            "z": 7,
            "elements": [
                "contenttweaker:cursed_meatballium_reinforced_casing@0"
            ]
        },
        {
            "x": -3,
            "y": 12,
            "z": 5,
            "elements": [
                "techreborn:machine_casing@1"
            ]
        },
        {
            "x": 6,
            "y": 1,
            "z": 7,
            "elements": [
                "divinerpg:eden_block"
            ]
        },
        {
            "x": -3,
            "y": 12,
            "z": -1,
            "elements": [
                "techreborn:machine_casing@1"
            ]
        },
        {
            "x": 2,
            "y": -1,
            "z": 7,
            "elements": [
                "chisel:netherbrick@8"
            ]
        },
        {
            "x": 5,
            "y": -1,
            "z": 6,
            "elements": [
                "chisel:blockgold@4"
            ]
        },
        {
            "x": 6,
            "y": 0,
            "z": 6,
            "elements": [
                "generalized_output_fluid"
            ]
        },
        {
            "x": -2,
            "y": -2,
            "z": 5,
            "elements": [
                "chisel:factory@10"
            ]
        },
        {
            "x": 0,
            "y": 3,
            "z": 4,
            "elements": [
                "enderio:block_fluid_cloud_seed_concentrated@0"
            ]
        },
        {
            "x": 3,
            "y": 2,
            "z": 6,
            "elements": [
                "enderio:block_fluid_cloud_seed_concentrated@0"
            ]
        },
        {
            "x": 0,
            "y": 4,
            "z": -1,
            "elements": [
                "nuclearcraft:salt_fission_wall@0"
            ]
        },
        {
            "x": 1,
            "y": 1,
            "z": 9,
            "elements": [
                "chisel:futura@0"
            ]
        },
        {
            "x": 0,
            "y": 2,
            "z": 7,
            "elements": [
                "divinerpg:eden_block"
            ]
        },
        {
            "x": -2,
            "y": 7,
            "z": 9,
            "elements": [
                "techreborn:machine_casing@1"
            ]
        },
        {
            "x": 6,
            "y": 1,
            "z": 6,
            "elements": [
                "generalized_output_fluid"
            ]
        },
        {
            "x": 5,
            "y": 4,
            "z": 0,
            "elements": [
                "nuclearcraft:salt_fission_vessel@0"
            ]
        },
        {
            "x": 5,
            "y": -2,
            "z": -1,
            "elements": [
                "chisel:factory@10"
            ]
        },
        {
            "x": 2,
            "y": -2,
            "z": 7,
            "elements": [
                "chisel:factory@10"
            ]
        },
        {
            "x": 1,
            "y": 7,
            "z": 9,
            "elements": [
                "techreborn:machine_casing@1"
            ]
        },
        {
            "x": 3,
            "y": 3,
            "z": 6,
            "elements": [
                "enderio:block_fluid_cloud_seed_concentrated@0"
            ]
        },
        {
            "x": 3,
            "y": 1,
            "z": 7,
            "elements": [
                "divinerpg:eden_block"
            ]
        },
        {
            "x": -3,
            "y": 9,
            "z": 4,
            "elements": [
                "techreborn:machine_casing@1"
            ]
        },
        {
            "x": 0,
            "y": 3,
            "z": 7,
            "elements": [
                "divinerpg:eden_block"
            ]
        },
        {
            "x": 0,
            "y": 5,
            "z": -1,
            "elements": [
                "contenttweaker:mythic_coil_t3@0"
            ]
        },
        {
            "x": 0,
            "y": 1,
            "z": 8,
            "elements": [
                "chisel:futura@0"
            ]
        },
        {
            "x": -2,
            "y": 5,
            "z": 4,
            "elements": [
                "contenttweaker:mythic_coil_t3@0"
            ]
        },
        {
            "x": 2,
            "y": -1,
            "z": 8,
            "elements": [
                "chisel:futura@0"
            ]
        },
        {
            "x": -2,
            "y": 6,
            "z": 3,
            "elements": [
                "contenttweaker:mythic_coil_t3@0"
            ]
        },
        {
            "x": 6,
            "y": 10,
            "z": -2,
            "elements": [
                "techreborn:machine_casing@1"
            ]
        },
        {
            "x": 5,
            "y": 2,
            "z": 5,
            "elements": [
                "enderio:block_fluid_cloud_seed_concentrated@0"
            ]
        },
        {
            "x": 5,
            "y": -2,
            "z": 5,
            "elements": [
                "chisel:factory@10"
            ]
        },
        {
            "x": 6,
            "y": 8,
            "z": -2,
            "elements": [
                "techreborn:machine_casing@1"
            ]
        },
        {
            "x": 5,
            "y": 0,
            "z": 5,
            "elements": [
                "contenttweaker:crystevia_cap@0"
            ]
        },
        {
            "x": 4,
            "y": 2,
            "z": 3,
            "elements": [
                "enderio:block_fluid_cloud_seed_concentrated@0"
            ]
        },
        {
            "x": 6,
            "y": -2,
            "z": 3,
            "elements": [
                "chisel:factory@10"
            ]
        },
        {
            "x": 4,
            "y": 0,
            "z": 3,
            "elements": [
                "contenttweaker:iromine_cap@0"
            ]
        },
        {
            "x": 5,
            "y": -2,
            "z": 8,
            "elements": [
                "chisel:factory@10"
            ]
        },
        {
            "x": 3,
            "y": 0,
            "z": 8,
            "elements": [
                "contenttweaker:vibranium_servo@0"
            ]
        },
        {
            "x": 6,
            "y": 9,
            "z": -2,
            "elements": [
                "techreborn:machine_casing@1"
            ]
        },
        {
            "x": 7,
            "y": -2,
            "z": 0,
            "elements": [
                "chisel:factory@10"
            ]
        },
        {
            "x": 0,
            "y": 2,
            "z": 8,
            "elements": [
                "chisel:futura@0"
            ]
        },
        {
            "x": 6,
            "y": 12,
            "z": -2,
            "elements": [
                "techreborn:machine_casing@1"
            ]
        },
        {
            "x": 5,
            "y": -1,
            "z": 8,
            "elements": [
                "chisel:futura@0"
            ]
        },
        {
            "x": -1,
            "y": 1,
            "z": 4,
            "elements": [
                "divinerpg:eden_block"
            ]
        },
        {
            "x": 4,
            "y": -2,
            "z": 5,
            "elements": [
                "chisel:factory@10"
            ]
        },
        {
            "x": 6,
            "y": 2,
            "z": 5,
            "elements": [
                "divinerpg:eden_block"
            ]
        },
        {
            "x": -1,
            "y": -2,
            "z": 8,
            "elements": [
                "chisel:factory@10"
            ]
        },
        {
            "x": -2,
            "y": 4,
            "z": 3,
            "elements": [
                "nuclearcraft:salt_fission_wall@0"
            ]
        },
        {
            "x": 2,
            "y": -2,
            "z": 8,
            "elements": [
                "chisel:factory@10"
            ]
        },
        {
            "x": 6,
            "y": 0,
            "z": 5,
            "elements": [
                "generalized_output_fluid"
            ]
        },
        {
            "x": 7,
            "y": 4,
            "z": 0,
            "elements": [
                "nuclearcraft:salt_fission_wall@0"
            ]
        },
        {
            "x": 1,
            "y": 0,
            "z": 3,
            "elements": [
                "contenttweaker:iromine_cap@0"
            ]
        },
        {
            "x": 0,
            "y": 4,
            "z": 8,
            "elements": [
                "nuclearcraft:salt_fission_wall@0"
            ]
        },
        {
            "x": 6,
            "y": 11,
            "z": -2,
            "elements": [
                "techreborn:machine_casing@1"
            ]
        },
        {
            "x": -3,
            "y": 8,
            "z": 8,
            "elements": [
                "techreborn:machine_casing@1"
            ]
        },
        {
            "x": 6,
            "y": 5,
            "z": 6,
            "elements": [
                "contenttweaker:cursed_meatballium_reinforced_casing@0"
            ]
        },
        {
            "x": 7,
            "y": -2,
            "z": 5,
            "elements": [
                "chisel:factory@10"
            ]
        },
        {
            "x": 3,
            "y": 2,
            "z": 5,
            "elements": [
                "enderio:block_fluid_cloud_seed_concentrated@0"
            ]
        },
        {
            "x": 4,
            "y": 4,
            "z": 0,
            "elements": [
                "nuclearcraft:salt_fission_vessel@0"
            ]
        },
        {
            "x": 3,
            "y": 0,
            "z": 5,
            "elements": [
                "contenttweaker:celeve_cap@0"
            ]
        },
        {
            "x": -3,
            "y": 7,
            "z": 8,
            "elements": [
                "techreborn:machine_casing@1"
            ]
        },
        {
            "x": 6,
            "y": 4,
            "z": 6,
            "elements": [
                "nuclearcraft:salt_fission_vessel@0"
            ]
        },
        {
            "x": 6,
            "y": 4,
            "z": 8,
            "elements": [
                "nuclearcraft:salt_fission_wall@0"
            ]
        },
        {
            "x": -3,
            "y": 6,
            "z": 8,
            "elements": [
                "techreborn:machine_casing@1"
            ]
        },
        {
            "x": 2,
            "y": -2,
            "z": 5,
            "elements": [
                "chisel:factory@10"
            ]
        },
        {
            "x": 6,
            "y": 3,
            "z": 6,
            "elements": [
                "divinerpg:eden_block"
            ]
        },
        {
            "x": -3,
            "y": 5,
            "z": 8,
            "elements": [
                "appliedenergistics2:fluix_stairs@4"
            ]
        },
        {
            "x": 4,
            "y": 2,
            "z": 0,
            "elements": [
                "nuclearcraft:salt_fission_glass@0"
            ]
        },
        {
            "x": 1,
            "y": 2,
            "z": 3,
            "elements": [
                "enderio:block_fluid_cloud_seed_concentrated@0"
            ]
        },
        {
            "x": 8,
            "y": -2,
            "z": 6,
            "elements": [
                "chisel:factory@10"
            ]
        },
        {
            "x": 0,
            "y": 0,
            "z": 8,
            "elements": [
                "chisel:futura@0"
            ]
        },
        {
            "x": 8,
            "y": -2,
            "z": 8,
            "elements": [
                "chisel:factory@10"
            ]
        },
        {
            "x": 3,
            "y": -2,
            "z": 3,
            "elements": [
                "chisel:factory@10"
            ]
        },
        {
            "x": 6,
            "y": -2,
            "z": 0,
            "elements": [
                "chisel:factory@10"
            ]
        },
        {
            "x": -3,
            "y": 7,
            "z": 9,
            "elements": [
                "techreborn:machine_casing@1"
            ]
        },
        {
            "x": 3,
            "y": 12,
            "z": -2,
            "elements": [
                "techreborn:machine_casing@1"
            ]
        },
        {
            "x": 0,
            "y": 0,
            "z": 3,
            "elements": [
                "divinerpg:divine_rock@0"
            ]
        },
        {
            "x": 2,
            "y": -2,
            "z": 3,
            "elements": [
                "chisel:factory@10"
            ]
        },
        {
            "x": 3,
            "y": 11,
            "z": -2,
            "elements": [
                "techreborn:machine_casing@1"
            ]
        },
        {
            "x": 3,
            "y": 9,
            "z": -2,
            "elements": [
                "techreborn:machine_casing@1"
            ]
        },
        {
            "x": -3,
            "y": 5,
            "z": 9,
            "elements": [
                "appliedenergistics2:fluix_stairs@4"
            ]
        },
        {
            "x": 3,
            "y": 8,
            "z": -2,
            "elements": [
                "techreborn:machine_casing@1"
            ]
        },
        {
            "x": -3,
            "y": 10,
            "z": 8,
            "elements": [
                "techreborn:machine_casing@1"
            ]
        },
        {
            "x": 2,
            "y": 3,
            "z": 4,
            "elements": [
                "enderio:block_fluid_cloud_seed_concentrated@0"
            ]
        },
        {
            "x": 6,
            "y": 5,
            "z": 1,
            "elements": [
                "contenttweaker:cursed_meatballium_reinforced_casing@0"
            ]
        },
        {
            "x": -3,
            "y": 6,
            "z": 3,
            "elements": [
                "techreborn:machine_casing@1"
            ]
        },
        {
            "x": 3,
            "y": 10,
            "z": -2,
            "elements": [
                "techreborn:machine_casing@1"
            ]
        },
        {
            "x": 3,
            "y": 6,
            "z": 8,
            "elements": [
                "contenttweaker:mythic_coil_t3@0"
            ]
        },
        {
            "x": 0,
            "y": 2,
            "z": 3,
            "elements": [
                "enderio:block_fluid_cloud_seed_concentrated@0"
            ]
        },
        {
            "x": 3,
            "y": 5,
            "z": 8,
            "elements": [
                "contenttweaker:mythic_coil_t3@0"
            ]
        },
        {
            "x": 8,
            "y": -2,
            "z": -2,
            "elements": [
                "chisel:factory@10"
            ]
        },
        {
            "x": -3,
            "y": -2,
            "z": 3,
            "elements": [
                "chisel:factory@10"
            ]
        },
        {
            "x": 6,
            "y": 4,
            "z": 1,
            "elements": [
                "nuclearcraft:salt_fission_vessel@0"
            ]
        },
        {
            "x": -3,
            "y": 9,
            "z": 8,
            "elements": [
                "techreborn:machine_casing@1"
            ]
        },
        {
            "x": -1,
            "y": 3,
            "z": 4,
            "elements": [
                "divinerpg:eden_block"
            ]
        },
        {
            "x": 0,
            "y": 6,
            "z": 8,
            "elements": [
                "contenttweaker:mythic_coil_t3@0"
            ]
        },
        {
            "x": 3,
            "y": 4,
            "z": 8,
            "elements": [
                "nuclearcraft:salt_fission_wall@0"
            ]
        },
        {
            "x": 0,
            "y": 9,
            "z": -2,
            "elements": [
                "techreborn:machine_casing@1"
            ]
        },
        {
            "x": 3,
            "y": 6,
            "z": -2,
            "elements": [
                "techreborn:machine_casing@1"
            ]
        },
        {
            "x": 0,
            "y": -1,
            "z": 4,
            "elements": [
                "chisel:blockgold@4"
            ]
        },
        {
            "x": 0,
            "y": 8,
            "z": -2,
            "elements": [
                "techreborn:machine_casing@1"
            ]
        },
        {
            "x": 2,
            "y": 1,
            "z": 4,
            "elements": [
                "contenttweaker:candyland_cap@0"
            ]
        },
        {
            "x": -1,
            "y": 2,
            "z": 3,
            "elements": [
                "divinerpg:eden_block"
            ]
        },
        {
            "x": 0,
            "y": 10,
            "z": -2,
            "elements": [
                "techreborn:machine_casing@1"
            ]
        },
        {
            "x": 0,
            "y": 5,
            "z": 8,
            "elements": [
                "contenttweaker:mythic_coil_t3@0"
            ]
        },
        {
            "x": 6,
            "y": 5,
            "z": -2,
            "elements": [
                "appliedenergistics2:fluix_stairs@6"
            ]
        },
        {
            "x": 7,
            "y": 6,
            "z": 0,
            "elements": [
                "contenttweaker:mythic_coil_t3@0"
            ]
        },
        {
            "x": 3,
            "y": 7,
            "z": -2,
            "elements": [
                "techreborn:machine_casing@1"
            ]
        },
        {
            "x": 0,
            "y": -2,
            "z": 3,
            "elements": [
                "chisel:factory@10"
            ]
        },
        {
            "x": -3,
            "y": 11,
            "z": 8,
            "elements": [
                "techreborn:machine_casing@1"
            ]
        },
        {
            "x": -1,
            "y": 5,
            "z": 4,
            "elements": [
                "contenttweaker:cursed_meatballium_reinforced_casing@0"
            ]
        },
        {
            "x": 1,
            "y": -1,
            "z": 4,
            "elements": [
                "chisel:blockgold@4"
            ]
        },
        {
            "x": 6,
            "y": 6,
            "z": -2,
            "elements": [
                "techreborn:machine_casing@1"
            ]
        },
        {
            "x": 1,
            "y": 1,
            "z": 4,
            "elements": [
                "contenttweaker:iromine_cap@0"
            ]
        },
        {
            "x": 3,
            "y": 1,
            "z": 8,
            "elements": [
                "contenttweaker:vibranium_servo@0"
            ]
        },
        {
            "x": 0,
            "y": 12,
            "z": -2,
            "elements": [
                "techreborn:machine_casing@1"
            ]
        },
        {
            "x": 3,
            "y": 5,
            "z": -2,
            "elements": [
                "appliedenergistics2:fluix_stairs@6"
            ]
        },
        {
            "x": -1,
            "y": 0,
            "z": 3,
            "elements": [
                "divinerpg:eden_block"
            ]
        },
        {
            "x": -3,
            "y": 12,
            "z": 8,
            "elements": [
                "techreborn:machine_casing@1"
            ]
        },
        {
            "x": -1,
            "y": -2,
            "z": 3,
            "elements": [
                "chisel:factory@10"
            ]
        },
        {
            "x": 6,
            "y": 7,
            "z": -2,
            "elements": [
                "techreborn:machine_casing@1"
            ]
        },
        {
            "x": 1,
            "y": 3,
            "z": 4,
            "elements": [
                "enderio:block_fluid_cloud_seed_concentrated@0"
            ]
        },
        {
            "x": 3,
            "y": 2,
            "z": 8,
            "elements": [
                "chisel:futura@0"
            ]
        },
        {
            "x": 0,
            "y": 11,
            "z": -2,
            "elements": [
                "techreborn:machine_casing@1"
            ]
        },
        {
            "x": 1,
            "y": -1,
            "z": 9,
            "elements": [
                "chisel:futura@0"
            ]
        },
        {
            "x": 8,
            "y": 11,
            "z": 5,
            "elements": [
                "techreborn:machine_casing@1"
            ]
        },
        {
            "x": 1,
            "y": -1,
            "z": 7,
            "elements": [
                "chisel:netherbrick@8"
            ]
        },
        {
            "x": 1,
            "y": 6,
            "z": -2,
            "elements": [
                "techreborn:machine_casing@1"
            ]
        },
        {
            "x": 3,
            "y": 3,
            "z": 2,
            "elements": [
                "enderio:block_fluid_cloud_seed_concentrated@0"
            ]
        },
        {
            "x": 4,
            "y": 1,
            "z": 4,
            "elements": [
                "contenttweaker:iromine_cap@0"
            ]
        },
        {
            "x": 2,
            "y": 2,
            "z": 6,
            "elements": [
                "enderio:block_fluid_cloud_seed_concentrated@0"
            ]
        },
        {
            "x": -2,
            "y": 8,
            "z": -2,
            "elements": [
                "techreborn:machine_casing@1"
            ]
        },
        {
            "x": 0,
            "y": 8,
            "z": 9,
            "elements": [
                "techreborn:machine_casing@1"
            ]
        },
        {
            "x": 7,
            "y": -2,
            "z": 6,
            "elements": [
                "chisel:factory@10"
            ]
        },
        {
            "x": 6,
            "y": -1,
            "z": 4,
            "elements": [
                "chisel:netherbrick@8"
            ]
        },
        {
            "x": -3,
            "y": 10,
            "z": 9,
            "elements": [
                "techreborn:machine_casing@1"
            ]
        },
        {
            "x": 0,
            "y": 5,
            "z": 9,
            "elements": [
                "appliedenergistics2:fluix_stairs@7"
            ]
        },
        {
            "x": 5,
            "y": -2,
            "z": -2,
            "elements": [
                "chisel:factory@10"
            ]
        },
        {
            "x": 4,
            "y": 2,
            "z": 4,
            "elements": [
                "enderio:block_fluid_cloud_seed_concentrated@0"
            ]
        },
        {
            "x": -2,
            "y": 10,
            "z": -2,
            "elements": [
                "techreborn:machine_casing@1"
            ]
        },
        {
            "x": 0,
            "y": 7,
            "z": 9,
            "elements": [
                "techreborn:machine_casing@1"
            ]
        },
        {
            "x": 0,
            "y": 6,
            "z": 9,
            "elements": [
                "techreborn:machine_casing@1"
            ]
        },
        {
            "x": -3,
            "y": 9,
            "z": 9,
            "elements": [
                "techreborn:machine_casing@1"
            ]
        },
        {
            "x": 7,
            "y": 5,
            "z": -1,
            "elements": [
                "contenttweaker:mythic_coil_t3@0"
            ]
        },
        {
            "x": -1,
            "y": 3,
            "z": 7,
            "elements": [
                "divinerpg:eden_block"
            ]
        },
        {
            "x": -3,
            "y": 9,
            "z": 2,
            "elements": [
                "techreborn:machine_casing@1"
            ]
        },
        {
            "x": 7,
            "y": 4,
            "z": 1,
            "elements": [
                "nuclearcraft:salt_fission_wall@0"
            ]
        },
        {
            "x": 0,
            "y": 6,
            "z": -2,
            "elements": [
                "techreborn:machine_casing@1"
            ]
        },
        {
            "x": -3,
            "y": 12,
            "z": 9,
            "elements": [
                "techreborn:machine_casing@1"
            ]
        },
        {
            "x": -1,
            "y": 6,
            "z": 8,
            "elements": [
                "contenttweaker:mythic_coil_t3@0"
            ]
        },
        {
            "x": 5,
            "y": 2,
            "z": 6,
            "elements": [
                "enderio:block_fluid_cloud_seed_concentrated@0"
            ]
        },
        {
            "x": 3,
            "y": 1,
            "z": 9,
            "elements": [
                "contenttweaker:vibranium_servo@0"
            ]
        },
        {
            "x": 3,
            "y": -1,
            "z": 4,
            "elements": [
                "chisel:blockgold@4"
            ]
        },
        {
            "x": 3,
            "y": 1,
            "z": 2,
            "elements": [
                "contenttweaker:celeve_cap@0"
            ]
        },
        {
            "x": -2,
            "y": 12,
            "z": -2,
            "elements": [
                "techreborn:machine_casing@1"
            ]
        },
        {
            "x": 3,
            "y": 2,
            "z": 9,
            "elements": [
                "chisel:futura@0"
            ]
        },
        {
            "x": -3,
            "y": 11,
            "z": 9,
            "elements": [
                "techreborn:machine_casing@1"
            ]
        },
        {
            "x": -3,
            "y": 11,
            "z": 2,
            "elements": [
                "techreborn:machine_casing@1"
            ]
        },
        {
            "x": -1,
            "y": 5,
            "z": 7,
            "elements": [
                "minecraft:beacon@0"
            ]
        },
        {
            "x": 2,
            "y": 5,
            "z": -1,
            "elements": [
                "contenttweaker:mythic_coil_t3@0"
            ]
        },
        {
            "x": 4,
            "y": 0,
            "z": 4,
            "elements": [
                "contenttweaker:iromine_cap@0"
            ]
        },
        {
            "x": -1,
            "y": 1,
            "z": 7,
            "elements": [
                "divinerpg:eden_block"
            ]
        },
        {
            "x": 8,
            "y": 10,
            "z": 0,
            "elements": [
                "techreborn:machine_casing@1"
            ]
        },
        {
            "x": -1,
            "y": 4,
            "z": 6,
            "elements": [
                "nuclearcraft:salt_fission_vessel@0"
            ]
        },
        {
            "x": 1,
            "y": 12,
            "z": -2,
            "elements": [
                "techreborn:machine_casing@1"
            ]
        },
        {
            "x": 3,
            "y": 0,
            "z": 9,
            "elements": [
                "contenttweaker:vibranium_servo@0"
            ]
        },
        {
            "x": 5,
            "y": -2,
            "z": 9,
            "elements": [
                "chisel:factory@10"
            ]
        },
        {
            "x": -1,
            "y": -2,
            "z": -2,
            "elements": [
                "chisel:factory@10"
            ]
        },
        {
            "x": 2,
            "y": -1,
            "z": 2,
            "elements": [
                "chisel:blockgold@4"
            ]
        },
        {
            "x": 0,
            "y": 1,
            "z": 2,
            "elements": [
                "contenttweaker:crystevia_cap@0"
            ]
        },
        {
            "x": 0,
            "y": -2,
            "z": 8,
            "elements": [
                "chisel:factory@10"
            ]
        },
        {
            "x": 8,
            "y": 9,
            "z": 0,
            "elements": [
                "techreborn:machine_casing@1"
            ]
        },
        {
            "x": -1,
            "y": 4,
            "z": 8,
            "elements": [
                "nuclearcraft:salt_fission_wall@0"
            ]
        },
        {
            "x": 1,
            "y": 0,
            "z": 8,
            "elements": [
                "chisel:futura@0"
            ]
        },
        {
            "x": 0,
            "y": 2,
            "z": 9,
            "elements": [
                "chisel:futura@0"
            ]
        },
        {
            "x": 1,
            "y": -2,
            "z": 6,
            "elements": [
                "chisel:factory@10"
            ]
        },
        {
            "x": 2,
            "y": 1,
            "z": 7,
            "elements": [
                "divinerpg:eden_block"
            ]
        },
        {
            "x": 0,
            "y": 1,
            "z": 9,
            "elements": [
                "chisel:futura@0"
            ]
        },
        {
            "x": 2,
            "y": -1,
            "z": 9,
            "elements": [
                "modularmachinery:blockenergyinputhatch"
            ]
        },
        {
            "x": 5,
            "y": 5,
            "z": -1,
            "elements": [
                "contenttweaker:mythic_coil_t3@0"
            ]
        },
        {
            "x": 0,
            "y": 3,
            "z": 2,
            "elements": [
                "enderio:block_fluid_cloud_seed_concentrated@0"
            ]
        },
        {
            "x": 4,
            "y": 3,
            "z": 4,
            "elements": [
                "enderio:block_fluid_cloud_seed_concentrated@0"
            ]
        },
        {
            "x": 2,
            "y": -2,
            "z": 9,
            "elements": [
                "chisel:factory@10"
            ]
        },
        {
            "x": 5,
            "y": -1,
            "z": 2,
            "elements": [
                "chisel:blockgold@4"
            ]
        },
        {
            "x": 1,
            "y": 8,
            "z": -2,
            "elements": [
                "techreborn:machine_casing@1"
            ]
        },
        {
            "x": 8,
            "y": 12,
            "z": 0,
            "elements": [
                "techreborn:machine_casing@1"
            ]
        },
        {
            "x": -3,
            "y": 8,
            "z": 9,
            "elements": [
                "techreborn:machine_casing@1"
            ]
        },
        {
            "x": 2,
            "y": -2,
            "z": -2,
            "elements": [
                "chisel:factory@10"
            ]
        },
        {
            "x": 2,
            "y": 0,
            "z": 6,
            "elements": [
                "contenttweaker:gardencia_cap@0"
            ]
        },
        {
            "x": -1,
            "y": 2,
            "z": 6,
            "elements": [
                "divinerpg:eden_block"
            ]
        },
        {
            "x": 1,
            "y": 10,
            "z": -2,
            "elements": [
                "techreborn:machine_casing@1"
            ]
        },
        {
            "x": 8,
            "y": 11,
            "z": 0,
            "elements": [
                "techreborn:machine_casing@1"
            ]
        },
        {
            "x": 4,
            "y": 5,
            "z": -1,
            "elements": [
                "contenttweaker:mythic_coil_t3@0"
            ]
        },
        {
            "x": -3,
            "y": 7,
            "z": 2,
            "elements": [
                "techreborn:machine_casing@1"
            ]
        },
        {
            "x": 5,
            "y": -1,
            "z": 9,
            "elements": [
                "chisel:futura@0"
            ]
        },
        {
            "x": 6,
            "y": -2,
            "z": 4,
            "elements": [
                "chisel:factory@10"
            ]
        },
        {
            "x": -2,
            "y": 4,
            "z": 8,
            "elements": [
                "nuclearcraft:salt_fission_wall@0"
            ]
        },
        {
            "x": -1,
            "y": -2,
            "z": 9,
            "elements": [
                "chisel:factory@10"
            ]
        },
        {
            "x": -1,
            "y": 3,
            "z": 2,
            "elements": [
                "divinerpg:eden_block"
            ]
        },
        {
            "x": 8,
            "y": 7,
            "z": 0,
            "elements": [
                "techreborn:machine_casing@1"
            ]
        },
        {
            "x": -2,
            "y": -2,
            "z": 8,
            "elements": [
                "chisel:factory@10"
            ]
        },
        {
            "x": 1,
            "y": -2,
            "z": -2,
            "elements": [
                "chisel:factory@10"
            ]
        },
        {
            "x": 1,
            "y": 0,
            "z": 1,
            "elements": [
                "contenttweaker:haven_cap@0"
            ]
        },
        {
            "x": -2,
            "y": 6,
            "z": 1,
            "elements": [
                "contenttweaker:mythic_coil_t3@0"
            ]
        },
        {
            "x": 0,
            "y": -1,
            "z": 2,
            "elements": [
                "chisel:blockgold@4"
            ]
        },
        {
            "x": 2,
            "y": 5,
            "z": 7,
            "elements": [
                "contenttweaker:cursed_meatballium_reinforced_casing@0"
            ]
        },
        {
            "x": 4,
            "y": 2,
            "z": 1,
            "elements": [
                "enderio:block_fluid_cloud_seed_concentrated@0"
            ]
        },
        {
            "x": 8,
            "y": 8,
            "z": 0,
            "elements": [
                "techreborn:machine_casing@1"
            ]
        },
        {
            "x": 4,
            "y": -1,
            "z": 7,
            "elements": [
                "chisel:netherbrick@8"
            ]
        },
        {
            "x": -3,
            "y": 5,
            "z": 2,
            "elements": [
                "appliedenergistics2:fluix_stairs@4"
            ]
        },
        {
            "x": 8,
            "y": 5,
            "z": 0,
            "elements": [
                "appliedenergistics2:fluix_stairs@5"
            ]
        },
        {
            "x": 0,
            "y": 0,
            "z": 9,
            "elements": [
                "chisel:futura@0"
            ]
        },
        {
            "x": 1,
            "y": 2,
            "z": 1,
            "elements": [
                "enderio:block_fluid_cloud_seed_concentrated@0"
            ]
        },
        {
            "x": 4,
            "y": 0,
            "z": 1,
            "elements": [
                "contenttweaker:haven_cap@0"
            ]
        },
        {
            "x": 0,
            "y": -2,
            "z": -2,
            "elements": [
                "chisel:factory@10"
            ]
        },
        {
            "x": 6,
            "y": -2,
            "z": 1,
            "elements": [
                "chisel:factory@10"
            ]
        },
        {
            "x": -1,
            "y": 1,
            "z": 2,
            "elements": [
                "generalized_input_item"
            ]
        },
        {
            "x": -1,
            "y": -1,
            "z": 2,
            "elements": [
                "chisel:netherbrick@8"
            ]
        },
        {
            "x": -2,
            "y": 4,
            "z": 1,
            "elements": [
                "nuclearcraft:salt_fission_wall@0"
            ]
        },
        {
            "x": 8,
            "y": 6,
            "z": 0,
            "elements": [
                "techreborn:machine_casing@1"
            ]
        },
        {
            "x": 5,
            "y": 1,
            "z": 7,
            "elements": [
                "divinerpg:eden_block"
            ]
        },
        {
            "x": -3,
            "y": 6,
            "z": -2,
            "elements": [
                "techreborn:machine_casing@1"
            ]
        },
        {
            "x": 2,
            "y": 3,
            "z": 7,
            "elements": [
                "divinerpg:eden_block"
            ]
        },
        {
            "x": 5,
            "y": 0,
            "z": 6,
            "elements": [
                "contenttweaker:voxponds_cap@0"
            ]
        },
        {
            "x": 3,
            "y": -2,
            "z": 1,
            "elements": [
                "chisel:factory@10"
            ]
        },
        {
            "x": 7,
            "y": 6,
            "z": 1,
            "elements": [
                "contenttweaker:mythic_coil_t3@0"
            ]
        },
        {
            "x": 1,
            "y": 3,
            "z": 2,
            "elements": [
                "enderio:block_fluid_cloud_seed_concentrated@0"
            ]
        },
        {
            "x": -2,
            "y": 5,
            "z": 2,
            "elements": [
                "contenttweaker:mythic_coil_t3@0"
            ]
        },
        {
            "x": -3,
            "y": 12,
            "z": -2,
            "elements": [
                "techreborn:machine_casing@1"
            ]
        },
        {
            "x": 7,
            "y": 4,
            "z": 4,
            "elements": [
                "nuclearcraft:salt_fission_wall@0"
            ]
        },
        {
            "x": 5,
            "y": 3,
            "z": 7,
            "elements": [
                "divinerpg:eden_block"
            ]
        },
        {
            "x": 3,
            "y": -2,
            "z": -2,
            "elements": [
                "chisel:factory@10"
            ]
        },
        {
            "x": 6,
            "y": -1,
            "z": 3,
            "elements": [
                "chisel:netherbrick@8"
            ]
        },
        {
            "x": -2,
            "y": 6,
            "z": -2,
            "elements": [
                "techreborn:machine_casing@1"
            ]
        },
        {
            "x": 7,
            "y": 6,
            "z": 4,
            "elements": [
                "contenttweaker:mythic_coil_t3@0"
            ]
        },
        {
            "x": -3,
            "y": 8,
            "z": -2,
            "elements": [
                "techreborn:machine_casing@1"
            ]
        },
        {
            "x": 1,
            "y": 1,
            "z": 2,
            "elements": [
                "contenttweaker:mysterium_cap@0"
            ]
        },
        {
            "x": -2,
            "y": -2,
            "z": -2,
            "elements": [
                "chisel:factory@10"
            ]
        },
        {
            "x": 4,
            "y": -2,
            "z": 6,
            "elements": [
                "chisel:factory@10"
            ]
        },
        {
            "x": 1,
            "y": -1,
            "z": 2,
            "elements": [
                "chisel:blockgold@4"
            ]
        },
        {
            "x": -3,
            "y": -2,
            "z": 8,
            "elements": [
                "chisel:factory@10"
            ]
        },
        {
            "x": 5,
            "y": 5,
            "z": 7,
            "elements": [
                "contenttweaker:cursed_meatballium_reinforced_casing@0"
            ]
        },
        {
            "x": -3,
            "y": 10,
            "z": -2,
            "elements": [
                "techreborn:machine_casing@1"
            ]
        },
        {
            "x": 4,
            "y": 3,
            "z": 3,
            "elements": [
                "enderio:block_fluid_cloud_seed_concentrated@0"
            ]
        },
        {
            "x": 7,
            "y": 5,
            "z": 4,
            "elements": [
                "contenttweaker:mythic_coil_t3@0"
            ]
        },
        {
            "x": 7,
            "y": 6,
            "z": 9,
            "elements": [
                "techreborn:machine_casing@1"
            ]
        },
        {
            "x": 5,
            "y": 5,
            "z": 0,
            "elements": [
                "contenttweaker:cursed_meatballium_reinforced_casing@0"
            ]
        },
        {
            "x": 1,
            "y": 1,
            "z": 7,
            "elements": [
                "divinerpg:eden_block"
            ]
        },
        {
            "x": -3,
            "y": -2,
            "z": 1,
            "elements": [
                "chisel:factory@10"
            ]
        },
        {
            "x": 6,
            "y": 11,
            "z": 9,
            "elements": [
                "techreborn:machine_casing@1"
            ]
        },
        {
            "x": 0,
            "y": 2,
            "z": 1,
            "elements": [
                "enderio:block_fluid_cloud_seed_concentrated@0"
            ]
        },
        {
            "x": 3,
            "y": 0,
            "z": 6,
            "elements": [
                "contenttweaker:gardencia_cap@0"
            ]
        },
        {
            "x": -1,
            "y": 12,
            "z": -2,
            "elements": [
                "techreborn:machine_casing@1"
            ]
        },
        {
            "x": -1,
            "y": 5,
            "z": -1,
            "elements": [
                "contenttweaker:mythic_coil_t3@0"
            ]
        },
        {
            "x": 7,
            "y": 5,
            "z": 9,
            "elements": [
                "appliedenergistics2:fluix_stairs@7"
            ]
        },
        {
            "x": -1,
            "y": -2,
            "z": 6,
            "elements": [
                "chisel:factory@10"
            ]
        },
        {
            "x": -1,
            "y": 4,
            "z": 1,
            "elements": [
                "nuclearcraft:salt_fission_vessel@0"
            ]
        },
        {
            "x": -2,
            "y": 5,
            "z": 7,
            "elements": [
                "contenttweaker:mythic_coil_t3@0"
            ]
        },
        {
            "x": 4,
            "y": 3,
            "z": 5,
            "elements": [
                "enderio:block_fluid_cloud_seed_concentrated@0"
            ]
        },
        {
            "x": 6,
            "y": 12,
            "z": 9,
            "elements": [
                "techreborn:machine_casing@1"
            ]
        },
        {
            "x": 7,
            "y": 8,
            "z": 9,
            "elements": [
                "techreborn:machine_casing@1"
            ]
        },
        {
            "x": 0,
            "y": -1,
            "z": 7,
            "elements": [
                "chisel:netherbrick@8"
            ]
        },
        {
            "x": 2,
            "y": -2,
            "z": 1,
            "elements": [
                "chisel:factory@10"
            ]
        },
        {
            "x": -1,
            "y": 8,
            "z": -2,
            "elements": [
                "techreborn:machine_casing@1"
            ]
        },
        {
            "x": 6,
            "y": 10,
            "z": 9,
            "elements": [
                "techreborn:machine_casing@1"
            ]
        },
        {
            "x": 2,
            "y": -2,
            "z": 6,
            "elements": [
                "chisel:factory@10"
            ]
        },
        {
            "x": 8,
            "y": 6,
            "z": -2,
            "elements": [
                "techreborn:machine_casing@1"
            ]
        },
        {
            "x": 7,
            "y": 6,
            "z": 8,
            "elements": [
                "contenttweaker:mythic_coil_t3@0"
            ]
        },
        {
            "x": 0,
            "y": 0,
            "z": 6,
            "elements": [
                "contenttweaker:voxponds_cap@0"
            ]
        },
        {
            "x": 0,
            "y": 0,
            "z": 1,
            "elements": [
                "contenttweaker:voxponds_cap@0"
            ]
        },
        {
            "x": 3,
            "y": -1,
            "z": 2,
            "elements": [
                "chisel:blockgold@4"
            ]
        },
        {
            "x": -1,
            "y": 10,
            "z": -2,
            "elements": [
                "techreborn:machine_casing@1"
            ]
        },
        {
            "x": 4,
            "y": -2,
            "z": -2,
            "elements": [
                "chisel:factory@10"
            ]
        },
        {
            "x": 7,
            "y": 7,
            "z": 9,
            "elements": [
                "techreborn:machine_casing@1"
            ]
        },
        {
            "x": 6,
            "y": 9,
            "z": 9,
            "elements": [
                "techreborn:machine_casing@1"
            ]
        },
        {
            "x": 0,
            "y": 2,
            "z": 6,
            "elements": [
                "enderio:block_fluid_cloud_seed_concentrated@0"
            ]
        },
        {
            "x": 7,
            "y": 4,
            "z": 8,
            "elements": [
                "nuclearcraft:salt_fission_wall@0"
            ]
        },
        {
            "x": -1,
            "y": 0,
            "z": 1,
            "elements": [
                "generalized_input_fluid"
            ]
        },
        {
            "x": 7,
            "y": 10,
            "z": 9,
            "elements": [
                "techreborn:machine_casing@1"
            ]
        },
        {
            "x": -1,
            "y": 6,
            "z": -2,
            "elements": [
                "techreborn:machine_casing@1"
            ]
        },
        {
            "x": 3,
            "y": -1,
            "z": 7,
            "elements": [
                "chisel:netherbrick@8"
            ]
        },
        {
            "x": -1,
            "y": -2,
            "z": 1,
            "elements": [
                "chisel:factory@10"
            ]
        },
        {
            "x": 7,
            "y": 4,
            "z": 3,
            "elements": [
                "nuclearcraft:salt_fission_wall@0"
            ]
        },
        {
            "x": 4,
            "y": 6,
            "z": 8,
            "elements": [
                "contenttweaker:mythic_coil_t3@0"
            ]
        },
        {
            "x": 7,
            "y": -2,
            "z": -2,
            "elements": [
                "chisel:factory@10"
            ]
        },
        {
            "x": -3,
            "y": 5,
            "z": -1,
            "elements": [
                "appliedenergistics2:fluix_stairs@4"
            ]
        },
        {
            "x": 4,
            "y": 11,
            "z": 9,
            "elements": [
                "techreborn:machine_casing@1"
            ]
        },
        {
            "x": 7,
            "y": 9,
            "z": 9,
            "elements": [
                "techreborn:machine_casing@1"
            ]
        },
        {
            "x": 4,
            "y": 12,
            "z": 9,
            "elements": [
                "techreborn:machine_casing@1"
            ]
        },
        {
            "x": -3,
            "y": 6,
            "z": 6,
            "elements": [
                "techreborn:machine_casing@1"
            ]
        },
        {
            "x": 1,
            "y": 3,
            "z": 7,
            "elements": [
                "divinerpg:eden_block"
            ]
        },
        {
            "x": 0,
            "y": -2,
            "z": 1,
            "elements": [
                "chisel:factory@10"
            ]
        },
        {
            "x": 4,
            "y": 10,
            "z": 9,
            "elements": [
                "techreborn:machine_casing@1"
            ]
        },
        {
            "x": 2,
            "y": 6,
            "z": -2,
            "elements": [
                "techreborn:machine_casing@1"
            ]
        },
        {
            "x": -1,
            "y": 2,
            "z": 1,
            "elements": [
                "divinerpg:eden_block"
            ]
        },
        {
            "x": 7,
            "y": 11,
            "z": 9,
            "elements": [
                "techreborn:machine_casing@1"
            ]
        },
        {
            "x": 7,
            "y": 5,
            "z": 3,
            "elements": [
                "contenttweaker:mythic_coil_t3@0"
            ]
        },
        {
            "x": 4,
            "y": 9,
            "z": 9,
            "elements": [
                "techreborn:machine_casing@1"
            ]
        },
        {
            "x": -3,
            "y": 6,
            "z": 1,
            "elements": [
                "techreborn:machine_casing@1"
            ]
        },
        {
            "x": 1,
            "y": 5,
            "z": 7,
            "elements": [
                "contenttweaker:cursed_meatballium_reinforced_casing@0"
            ]
        },
        {
            "x": -3,
            "y": 7,
            "z": -1,
            "elements": [
                "techreborn:machine_casing@1"
            ]
        },
        {
            "x": -3,
            "y": 8,
            "z": 6,
            "elements": [
                "techreborn:machine_casing@1"
            ]
        },
        {
            "x": 7,
            "y": 12,
            "z": 9,
            "elements": [
                "techreborn:machine_casing@1"
            ]
        },
        {
            "x": 7,
            "y": 6,
            "z": 3,
            "elements": [
                "contenttweaker:mythic_coil_t3@0"
            ]
        },
        {
            "x": 6,
            "y": 1,
            "z": 2,
            "elements": [
                "divinerpg:eden_block"
            ]
        },
        {
            "x": 5,
            "y": 6,
            "z": -2,
            "elements": [
                "techreborn:machine_casing@1"
            ]
        },
        {
            "x": 1,
            "y": -2,
            "z": 1,
            "elements": [
                "chisel:factory@10"
            ]
        },
        {
            "x": 3,
            "y": 6,
            "z": 9,
            "elements": [
                "techreborn:machine_casing@1"
            ]
        },
        {
            "x": -2,
            "y": 6,
            "z": 8,
            "elements": [
                "contenttweaker:mythic_coil_t3@0"
            ]
        },
        {
            "x": 1,
            "y": 4,
            "z": 8,
            "elements": [
                "nuclearcraft:salt_fission_wall@0"
            ]
        },
        {
            "x": 2,
            "y": 8,
            "z": -2,
            "elements": [
                "techreborn:machine_casing@1"
            ]
        },
        {
            "x": 1,
            "y": 0,
            "z": 5,
            "elements": [
                "contenttweaker:mysterium_cap@0"
            ]
        },
        {
            "x": -1,
            "y": 0,
            "z": 6,
            "elements": [
                "divinerpg:eden_block"
            ]
        },
        {
            "x": 1,
            "y": 2,
            "z": 5,
            "elements": [
                "enderio:block_fluid_cloud_seed_concentrated@0"
            ]
        },
        {
            "x": 2,
            "y": 10,
            "z": -2,
            "elements": [
                "techreborn:machine_casing@1"
            ]
        },
        {
            "x": 1,
            "y": -2,
            "z": 8,
            "elements": [
                "chisel:factory@10"
            ]
        },
        {
            "x": 7,
            "y": 5,
            "z": 5,
            "elements": [
                "contenttweaker:mythic_coil_t3@0"
            ]
        },
        {
            "x": 4,
            "y": 2,
            "z": 8,
            "elements": [
                "chisel:futura@0"
            ]
        },
        {
            "x": 1,
            "y": 1,
            "z": 5,
            "elements": [
                "contenttweaker:mysterium_cap@0"
            ]
        },
        {
            "x": -3,
            "y": 8,
            "z": 1,
            "elements": [
                "techreborn:machine_casing@1"
            ]
        },
        {
            "x": 7,
            "y": 4,
            "z": 5,
            "elements": [
                "nuclearcraft:salt_fission_wall@0"
            ]
        },
        {
            "x": 6,
            "y": 3,
            "z": 2,
            "elements": [
                "divinerpg:eden_block"
            ]
        },
        {
            "x": -2,
            "y": -2,
            "z": 1,
            "elements": [
                "chisel:factory@10"
            ]
        },
        {
            "x": -2,
            "y": 4,
            "z": 6,
            "elements": [
                "nuclearcraft:salt_fission_wall@0"
            ]
        },
        {
            "x": -3,
            "y": 12,
            "z": 1,
            "elements": [
                "techreborn:machine_casing@1"
            ]
        },
        {
            "x": 4,
            "y": 4,
            "z": 8,
            "elements": [
                "nuclearcraft:salt_fission_wall@0"
            ]
        },
        {
            "x": 0,
            "y": -2,
            "z": 5,
            "elements": [
                "chisel:factory@10"
            ]
        },
        {
            "x": 8,
            "y": -2,
            "z": 9,
            "elements": [
                "chisel:factory@10"
            ]
        },
        {
            "x": 2,
            "y": 12,
            "z": -2,
            "elements": [
                "techreborn:machine_casing@1"
            ]
        },
        {
            "x": 3,
            "y": 8,
            "z": 9,
            "elements": [
                "techreborn:machine_casing@1"
            ]
        },
        {
            "x": -2,
            "y": 5,
            "z": -1,
            "elements": [
                "contenttweaker:mythic_coil_t3@0"
            ]
        },
        {
            "x": -2,
            "y": -2,
            "z": 6,
            "elements": [
                "chisel:factory@10"
            ]
        },
        {
            "x": 6,
            "y": -2,
            "z": 8,
            "elements": [
                "chisel:factory@10"
            ]
        },
        {
            "x": 2,
            "y": 0,
            "z": 8,
            "elements": [
                "contenttweaker:vibranium_servo@0"
            ]
        },
        {
            "x": 3,
            "y": 7,
            "z": 9,
            "elements": [
                "techreborn:machine_casing@1"
            ]
        },
        {
            "x": 0,
            "y": -1,
            "z": 5,
            "elements": [
                "chisel:blockgold@4"
            ]
        },
        {
            "x": 1,
            "y": 2,
            "z": 8,
            "elements": [
                "chisel:futura@0"
            ]
        },
        {
            "x": 7,
            "y": 6,
            "z": 5,
            "elements": [
                "contenttweaker:mythic_coil_t3@0"
            ]
        },
        {
            "x": -1,
            "y": -1,
            "z": 7,
            "elements": [
                "chisel:netherbrick@8"
            ]
        },
        {
            "x": 6,
            "y": 8,
            "z": 9,
            "elements": [
                "techreborn:machine_casing@1"
            ]
        },
        {
            "x": -3,
            "y": 10,
            "z": 1,
            "elements": [
                "techreborn:machine_casing@1"
            ]
        },
        {
            "x": 0,
            "y": 12,
            "z": 9,
            "elements": [
                "techreborn:machine_casing@1"
            ]
        },
        {
            "x": 5,
            "y": 12,
            "z": -2,
            "elements": [
                "techreborn:machine_casing@1"
            ]
        },
        {
            "x": 3,
            "y": 10,
            "z": 9,
            "elements": [
                "techreborn:machine_casing@1"
            ]
        },
        {
            "x": 6,
            "y": -1,
            "z": 2,
            "elements": [
                "chisel:netherbrick@8"
            ]
        },
        {
            "x": -2,
            "y": 4,
            "z": 5,
            "elements": [
                "nuclearcraft:salt_fission_wall@0"
            ]
        },
        {
            "x": 4,
            "y": 1,
            "z": 2,
            "elements": [
                "contenttweaker:mysterium_cap@0"
            ]
        },
        {
            "x": 3,
            "y": -2,
            "z": 5,
            "elements": [
                "chisel:factory@10"
            ]
        },
        {
            "x": 3,
            "y": 0,
            "z": 1,
            "elements": [
                "contenttweaker:gardencia_cap@0"
            ]
        },
        {
            "x": 0,
            "y": 11,
            "z": 9,
            "elements": [
                "techreborn:machine_casing@1"
            ]
        },
        {
            "x": 6,
            "y": 7,
            "z": 9,
            "elements": [
                "techreborn:machine_casing@1"
            ]
        },
        {
            "x": 3,
            "y": -2,
            "z": 8,
            "elements": [
                "chisel:factory@10"
            ]
        },
        {
            "x": 3,
            "y": 9,
            "z": 9,
            "elements": [
                "techreborn:machine_casing@1"
            ]
        },
        {
            "x": -3,
            "y": -2,
            "z": 6,
            "elements": [
                "chisel:factory@10"
            ]
        },
        {
            "x": 2,
            "y": 2,
            "z": 1,
            "elements": [
                "enderio:block_fluid_cloud_seed_concentrated@0"
            ]
        },
        {
            "x": 5,
            "y": 0,
            "z": 8,
            "elements": [
                "chisel:futura@0"
            ]
        },
        {
            "x": 3,
            "y": -1,
            "z": 5,
            "elements": [
                "chisel:blockgold@4"
            ]
        },
        {
            "x": 2,
            "y": 2,
            "z": 8,
            "elements": [
                "chisel:futura@0"
            ]
        },
        {
            "x": 1,
            "y": 5,
            "z": -1,
            "elements": [
                "contenttweaker:mythic_coil_t3@0"
            ]
        },
        {
            "x": 1,
            "y": 6,
            "z": 8,
            "elements": [
                "contenttweaker:mythic_coil_t3@0"
            ]
        },
        {
            "x": 4,
            "y": 3,
            "z": 2,
            "elements": [
                "enderio:block_fluid_cloud_seed_concentrated@0"
            ]
        },
        {
            "x": 4,
            "y": -2,
            "z": 1,
            "elements": [
                "chisel:factory@10"
            ]
        },
        {
            "x": 0,
            "y": 10,
            "z": 9,
            "elements": [
                "techreborn:machine_casing@1"
            ]
        },
        {
            "x": 2,
            "y": 4,
            "z": 8,
            "elements": [
                "nuclearcraft:salt_fission_wall@0"
            ]
        },
        {
            "x": 4,
            "y": 1,
            "z": 5,
            "elements": [
                "contenttweaker:mysterium_cap@0"
            ]
        },
        {
            "x": 3,
            "y": 5,
            "z": 9,
            "elements": [
                "appliedenergistics2:fluix_stairs@7"
            ]
        },
        {
            "x": -2,
            "y": 6,
            "z": 5,
            "elements": [
                "contenttweaker:mythic_coil_t3@0"
            ]
        },
        {
            "x": 0,
            "y": 1,
            "z": 7,
            "elements": [
                "divinerpg:eden_block"
            ]
        },
        {
            "x": 6,
            "y": 6,
            "z": 9,
            "elements": [
                "techreborn:machine_casing@1"
            ]
        },
        {
            "x": 6,
            "y": -2,
            "z": 5,
            "elements": [
                "chisel:factory@10"
            ]
        },
        {
            "x": 4,
            "y": 2,
            "z": 5,
            "elements": [
                "enderio:block_fluid_cloud_seed_concentrated@0"
            ]
        },
        {
            "x": 2,
            "y": 0,
            "z": 1,
            "elements": [
                "contenttweaker:gardencia_cap@0"
            ]
        },
        {
            "x": 4,
            "y": 0,
            "z": 5,
            "elements": [
                "contenttweaker:mysterium_cap@0"
            ]
        },
        {
            "x": 5,
            "y": 10,
            "z": -2,
            "elements": [
                "techreborn:machine_casing@1"
            ]
        },
        {
            "x": 5,
            "y": 8,
            "z": -2,
            "elements": [
                "techreborn:machine_casing@1"
            ]
        },
        {
            "x": 6,
            "y": 5,
            "z": 9,
            "elements": [
                "appliedenergistics2:fluix_stairs@7"
            ]
        },
        {
            "x": 4,
            "y": -2,
            "z": 8,
            "elements": [
                "chisel:factory@10"
            ]
        },
        {
            "x": 3,
            "y": 2,
            "z": 1,
            "elements": [
                "enderio:block_fluid_cloud_seed_concentrated@0"
            ]
        },
        {
            "x": 3,
            "y": 11,
            "z": 9,
            "elements": [
                "techreborn:machine_casing@1"
            ]
        },
        {
            "x": -3,
            "y": 5,
            "z": 7,
            "elements": [
                "appliedenergistics2:fluix_stairs@4"
            ]
        },
        {
            "x": 4,
            "y": 0,
            "z": 8,
            "elements": [
                "chisel:futura@0"
            ]
        },
        {
            "x": 1,
            "y": 3,
            "z": 5,
            "elements": [
                "enderio:block_fluid_cloud_seed_concentrated@0"
            ]
        },
        {
            "x": -2,
            "y": 5,
            "z": 5,
            "elements": [
                "contenttweaker:mythic_coil_t3@0"
            ]
        },
        {
            "x": 3,
            "y": 12,
            "z": 9,
            "elements": [
                "techreborn:machine_casing@1"
            ]
        },
        {
            "x": 6,
            "y": -1,
            "z": 5,
            "elements": [
                "chisel:netherbrick@8"
            ]
        },
        {
            "x": 0,
            "y": 9,
            "z": 9,
            "elements": [
                "techreborn:machine_casing@1"
            ]
        },
        {
            "x": 6,
            "y": 5,
            "z": 2,
            "elements": [
                "contenttweaker:cursed_meatballium_reinforced_casing@0"
            ]
        },
        {
            "x": 2,
            "y": 6,
            "z": 8,
            "elements": [
                "contenttweaker:mythic_coil_t3@0"
            ]
        },
        {
            "x": 5,
            "y": 4,
            "z": 8,
            "elements": [
                "nuclearcraft:salt_fission_wall@0"
            ]
        },
        {
            "x": -2,
            "y": 12,
            "z": 9,
            "elements": [
                "techreborn:machine_casing@1"
            ]
        },
        {
            "x": 5,
            "y": 1,
            "z": 1,
            "elements": [
                "contenttweaker:voxponds_cap@0"
            ]
        },
        {
            "x": 7,
            "y": 12,
            "z": -2,
            "elements": [
                "techreborn:machine_casing@1"
            ]
        },
        {
            "x": 5,
            "y": 0,
            "z": 1,
            "elements": [
                "contenttweaker:voxponds_cap@0"
            ]
        },
        {
            "x": 3,
            "y": -2,
            "z": 9,
            "elements": [
                "chisel:factory@10"
            ]
        },
        {
            "x": -1,
            "y": 1,
            "z": 0,
            "elements": [
                "divinerpg:eden_block"
            ]
        },
        {
            "x": 0,
            "y": -1,
            "z": 0,
            "elements": [
                "chisel:netherbrick@8"
            ]
        },
        {
            "x": 2,
            "y": 5,
            "z": 8,
            "elements": [
                "contenttweaker:mythic_coil_t3@0"
            ]
        },
        {
            "x": 6,
            "y": 5,
            "z": 3,
            "elements": [
                "contenttweaker:cursed_meatballium_reinforced_casing@0"
            ]
        },
        {
            "x": -3,
            "y": 5,
            "z": 0,
            "elements": [
                "appliedenergistics2:fluix_stairs@4"
            ]
        },
        {
            "x": 7,
            "y": 11,
            "z": -2,
            "elements": [
                "techreborn:machine_casing@1"
            ]
        },
        {
            "x": 5,
            "y": 3,
            "z": 1,
            "elements": [
                "enderio:block_fluid_cloud_seed_concentrated@0"
            ]
        },
        {
            "x": -3,
            "y": 7,
            "z": 0,
            "elements": [
                "techreborn:machine_casing@1"
            ]
        },
        {
            "x": 7,
            "y": 10,
            "z": -2,
            "elements": [
                "techreborn:machine_casing@1"
            ]
        },
        {
            "x": 6,
            "y": 4,
            "z": 4,
            "elements": [
                "nuclearcraft:salt_fission_vessel@0"
            ]
        },
        {
            "x": -2,
            "y": 10,
            "z": 9,
            "elements": [
                "techreborn:machine_casing@1"
            ]
        },
        {
            "x": 5,
            "y": 1,
            "z": 8,
            "elements": [
                "chisel:futura@0"
            ]
        },
        {
            "x": 7,
            "y": 8,
            "z": -2,
            "elements": [
                "techreborn:machine_casing@1"
            ]
        },
        {
            "x": 1,
            "y": -1,
            "z": 0,
            "elements": [
                "modularmachinery:blockparallelcontroller",
                "chisel:netherbrick@8"
            ]
        },
        {
            "x": 5,
            "y": 2,
            "z": 1,
            "elements": [
                "enderio:block_fluid_cloud_seed_concentrated@0"
            ]
        },
        {
            "x": -3,
            "y": 12,
            "z": 4,
            "elements": [
                "techreborn:machine_casing@1"
            ]
        },
        {
            "x": 4,
            "y": 0,
            "z": 9,
            "elements": [
                "chisel:futura@0"
            ]
        },
        {
            "x": -1,
            "y": 3,
            "z": 0,
            "elements": [
                "divinerpg:eden_block"
            ]
        },
        {
            "x": 6,
            "y": 3,
            "z": 3,
            "elements": [
                "divinerpg:eden_block"
            ]
        },
        {
            "x": 5,
            "y": 2,
            "z": 8,
            "elements": [
                "chisel:futura@0"
            ]
        },
        {
            "x": 1,
            "y": 6,
            "z": 9,
            "elements": [
                "techreborn:machine_casing@1"
            ]
        },
        {
            "x": 7,
            "y": 9,
            "z": -2,
            "elements": [
                "techreborn:machine_casing@1"
            ]
        },
        {
            "x": 4,
            "y": 9,
            "z": -2,
            "elements": [
                "techreborn:machine_casing@1"
            ]
        },
        {
            "x": 3,
            "y": 1,
            "z": 3,
            "elements": [
                "contenttweaker:candyland_cap@0"
            ]
        },
        {
            "x": -3,
            "y": 9,
            "z": 0,
            "elements": [
                "techreborn:machine_casing@1"
            ]
        },
        {
            "x": 7,
            "y": 6,
            "z": -2,
            "elements": [
                "techreborn:machine_casing@1"
            ]
        },
        {
            "x": 1,
            "y": 0,
            "z": 6,
            "elements": [
                "contenttweaker:haven_cap@0"
            ]
        },
        {
            "x": 7,
            "y": -2,
            "z": 1,
            "elements": [
                "chisel:factory@10"
            ]
        },
        {
            "x": 4,
            "y": 8,
            "z": -2,
            "elements": [
                "techreborn:machine_casing@1"
            ]
        },
        {
            "x": 4,
            "y": 10,
            "z": -2,
            "elements": [
                "techreborn:machine_casing@1"
            ]
        },
        {
            "x": 1,
            "y": 1,
            "z": 0,
            "elements": [
                "nuclearcraft:salt_fission_glass@0"
            ]
        },
        {
            "x": 6,
            "y": 2,
            "z": 4,
            "elements": [
                "divinerpg:eden_block"
            ]
        },
        {
            "x": -3,
            "y": 7,
            "z": 3,
            "elements": [
                "techreborn:machine_casing@1"
            ]
        },
        {
            "x": -1,
            "y": -1,
            "z": 5,
            "elements": [
                "chisel:netherbrick@8"
            ]
        },
        {
            "x": 7,
            "y": -2,
            "z": 8,
            "elements": [
                "chisel:factory@10"
            ]
        },
        {
            "x": -3,
            "y": 5,
            "z": 5,
            "elements": [
                "appliedenergistics2:fluix_stairs@4"
            ]
        },
        {
            "x": 7,
            "y": 7,
            "z": -2,
            "elements": [
                "techreborn:machine_casing@1"
            ]
        },
        {
            "x": 1,
            "y": 1,
            "z": 6,
            "elements": [
                "contenttweaker:haven_cap@0"
            ]
        },
        {
            "x": 2,
            "y": -1,
            "z": 3,
            "elements": [
                "chisel:blockgold@4"
            ]
        },
        {
            "x": 4,
            "y": 12,
            "z": -2,
            "elements": [
                "techreborn:machine_casing@1"
            ]
        },
        {
            "x": 5,
            "y": 6,
            "z": 8,
            "elements": [
                "contenttweaker:mythic_coil_t3@0"
            ]
        },
        {
            "x": -3,
            "y": 9,
            "z": 3,
            "elements": [
                "techreborn:machine_casing@1"
            ]
        },
        {
            "x": -3,
            "y": 11,
            "z": 0,
            "elements": [
                "techreborn:machine_casing@1"
            ]
        },
        {
            "x": 5,
            "y": 5,
            "z": 8,
            "elements": [
                "contenttweaker:mythic_coil_t3@0"
            ]
        },
        {
            "x": 7,
            "y": 5,
            "z": -2,
            "elements": [
                "appliedenergistics2:fluix_stairs@6"
            ]
        },
        {
            "x": -3,
            "y": 11,
            "z": 3,
            "elements": [
                "techreborn:machine_casing@1"
            ]
        },
        {
            "x": 0,
            "y": -2,
            "z": 6,
            "elements": [
                "chisel:factory@10"
            ]
        },
        {
            "x": 4,
            "y": 11,
            "z": -2,
            "elements": [
                "techreborn:machine_casing@1"
            ]
        },
        {
            "x": 1,
            "y": 3,
            "z": 0,
            "elements": [
                "divinerpg:eden_block"
            ]
        },
        {
            "x": 0,
            "y": -1,
            "z": 6,
            "elements": [
                "chisel:blockgold@4"
            ]
        },
        {
            "x": 0,
            "y": 3,
            "z": 3,
            "elements": [
                "enderio:block_fluid_cloud_seed_concentrated@0"
            ]
        },
        {
            "x": -2,
            "y": 5,
            "z": 0,
            "elements": [
                "contenttweaker:mythic_coil_t3@0"
            ]
        },
        {
            "x": 6,
            "y": 0,
            "z": 4,
            "elements": [
                "generalized_output_fluid"
            ]
        },
        {
            "x": 0,
            "y": 1,
            "z": 5,
            "elements": [
                "contenttweaker:crystevia_cap@0"
            ]
        },
        {
            "x": 1,
            "y": 10,
            "z": 9,
            "elements": [
                "techreborn:machine_casing@1"
            ]
        },
        {
            "x": 8,
            "y": 8,
            "z": 1,
            "elements": [
                "techreborn:machine_casing@1"
            ]
        },
        {
            "x": 2,
            "y": -2,
            "z": 4,
            "elements": [
                "chisel:factory@10"
            ]
        },
        {
            "x": 3,
            "y": -2,
            "z": 6,
            "elements": [
                "chisel:factory@10"
            ]
        },
        {
            "x": 1,
            "y": 0,
            "z": 9,
            "elements": [
                "chisel:futura@0"
            ]
        },
        {
            "x": 4,
            "y": 8,
            "z": 9,
            "elements": [
                "techreborn:machine_casing@1"
            ]
        },
        {
            "x": 3,
            "y": -1,
            "z": 0,
            "elements": [
                "contenttweaker:mythic_excavation_engine@0"
            ]
        },
        {
            "x": 8,
            "y": 11,
            "z": 8,
            "elements": [
                "techreborn:machine_casing@1"
            ]
        },
        {
            "x": 1,
            "y": -1,
            "z": 5,
            "elements": [
                "chisel:blockgold@4"
            ]
        },
        {
            "x": 0,
            "y": 2,
            "z": 4,
            "elements": [
                "enderio:block_fluid_cloud_seed_concentrated@0"
            ]
        },
        {
            "x": 8,
            "y": 12,
            "z": 8,
            "elements": [
                "techreborn:machine_casing@1"
            ]
        },
        {
            "x": 2,
            "y": 3,
            "z": 0,
            "elements": [
                "divinerpg:eden_block"
            ]
        },
        {
            "x": 5,
            "y": -2,
            "z": 4,
            "elements": [
                "chisel:factory@10"
            ]
        },
        {
            "x": 8,
            "y": 9,
            "z": 1,
            "elements": [
                "techreborn:machine_casing@1"
            ]
        },
        {
            "x": 4,
            "y": 1,
            "z": 7,
            "elements": [
                "divinerpg:eden_block"
            ]
        },
        {
            "x": -1,
            "y": 5,
            "z": 5,
            "elements": [
                "contenttweaker:cursed_meatballium_reinforced_casing@0"
            ]
        },
        {
            "x": 3,
            "y": -1,
            "z": 6,
            "elements": [
                "chisel:blockgold@4"
            ]
        },
        {
            "x": 3,
            "y": 0,
            "z": 4,
            "elements": [
                "contenttweaker:candyland_cap@0"
            ]
        },
        {
            "x": 0,
            "y": 3,
            "z": 5,
            "elements": [
                "enderio:block_fluid_cloud_seed_concentrated@0"
            ]
        },
        {
            "x": 8,
            "y": 9,
            "z": 8,
            "elements": [
                "techreborn:machine_casing@1"
            ]
        },
        {
            "x": 1,
            "y": 2,
            "z": 6,
            "elements": [
                "enderio:block_fluid_cloud_seed_concentrated@0"
            ]
        },
        {
            "x": 1,
            "y": 12,
            "z": 9,
            "elements": [
                "techreborn:machine_casing@1"
            ]
        },
        {
            "x": 4,
            "y": 6,
            "z": 9,
            "elements": [
                "techreborn:machine_casing@1"
            ]
        },
        {
            "x": 0,
            "y": -2,
            "z": 9,
            "elements": [
                "chisel:factory@10"
            ]
        },
        {
            "x": -3,
            "y": 6,
            "z": 4,
            "elements": [
                "techreborn:machine_casing@1"
            ]
